Workbook

Sheet Materiais
B2: Materiais
B4: Materiais | C4: Unidade | D4: QTD por Embalagem | E4: Total | F4: Unitario
B5: Açucar cristal | C5: g | D5: 1000 | E5: 3.58 | F5: 0.00358
B6: Amendoim moído | C6: g | D6: 1000 | E6: 1.94 | F6: 0.00194
B7: Amendoim picado | C7: g | D7: 211 | E7: 1.79 | F7: 0.0084834123
B8: Barra chocolate amargo SICAO | C8: g | D8: 1050 | E8: 24.7 | F8: 0.02352381
B9: Barra chocolate branco SICAO | C9: g | D9: 1050 | E9: 29.45 | F9: 0.028047619
B10: Cacau em pó | C10: g | D10: 500 | E10: 19.6 | F10: 0.0392
B11: Café soluvel | C11: g | D11: 1000 | E11: 12 | F11: 0.012
B12: Canela | C12: g | D12: 50 | E12: 3.9 | F12: 0.078
B13: Chocolate em pó | C13: g | D13: 300 | E13: 6.9 | F13: 0.023
B14: Côco ralado fino | C14: g | D14: 1000 | E14: 17.5 | F14: 0.0175
B15: Côco ralado grosso | C15: g | D15: 1000 | E15: 31.5 | F15: 0.0315
B16: Creme de leite | C16: g | D16: 200 | E16: 2.9 | F16: 0.0145
... B23: Nozes pedaço | C23: g | D23: 1000 | E23: 59.9 | F23: 0.0599

Sheet Produtos
B2: Produtos
B4: Produto | C4: Rendimento (g) | D4: Ingrediente_1 | E4: Quantidade_1 | F4: Quantidade_utilizada_1 | G4: Medida_1 | H4: Ingrediente_2 | I4: Quantidade_2 | J4: Quantidade_utilizada_2 | K4: Medida_2 | L4: Ingrediente_3 | M4: Quantidade_3 | N4: Quantidade_utilizada_3 | O4: Medida_3 | P4: Ingrediente_4 | Q4: Quantidade_4 | R4: Quantidade_utilizada_4 | S4: Medida_4 | T4: Ingrediente_5 | U4: Quantidade_5 | V4: Quantidade_utilizada_5 | W4: Medida_5 | X4: Ingrediente_6 | Y4: Quantidade_6 | Z4: Quantidade_utilizada_6 | AA4: Medida_6 | AB4: Ingrediente_7 | AC4: Quantidade_7 | AD4: Quantidade_utilizada_7 | AE4: Medida_7
B5: Brigadeiro Chocolate | C5: 600 | D5: Leite Condensado | E5: 395 | F5: =SUMIFS(Produção!AT:AT,Produção!B:B,Tabela5[[#This Row],[Produto]])*Tabela5[[#This Row],[Quantidade_1]]/Tabela5[[#This Row],[Rendimento (g)]] -> 1316.6667 | G5: =IFERROR(VLOOKUP(Tabela5[[#This Row],[Ingrediente_1]],Tabela2[[Materiais]:[Unidade]],2,0),"") -> g | H5: Manteiga sem sal | I5: 15 | J5: =SUMIFS(Produção!AT:AT,Produção!B:B,Tabela5[[#This Row],[Produto]])*Tabela5[[#This Row],[Quantidade_2]]/Tabela5[[#This Row],[Rendimento (g)]] -> 50 | K5: =IFERROR(VLOOKUP(Tabela5[[#This Row],[Ingrediente_2]],Tabela2[[Materiais]:[Unidade]],2,0),"") -> g | L5: Cacau em pó | M5: 6 | N5: =SUMIFS(Produção!AT:AT,Produção!B:B,Tabela5[[#This Row],[Produto]])*Tabela5[[#This Row],[Quantidade_3]]/Tabela5[[#This Row],[Rendimento (g)]] -> 20 | O5: =IFERROR(VLOOKUP(Tabela5[[#This Row],[Ingrediente_3]],Tabela2[[Materiais]:[Unidade]],2,0),"") -> g | P5: Creme de leite | Q5: 50 | R5: =SUMIFS(Produção!AT:AT,Produção!B:B,Tabela5[[#This Row],[Produto]])*Tabela5[[#This Row],[Quantidade_4]]/Tabela5[[#This Row],[Rendimento (g)]] -> 166.66667 | S5: =IFERROR(VLOOKUP(Tabela5[[#This Row],[Ingrediente_4]],Tabela2[[Materiais]:[Unidade]],2,0),"") -> g | T5: Farinha de trigo | U5: 9 | V5: =SUMIFS(Produção!AT:AT,Produção!B:B,Tabela5[[#This Row],[Produto]])*Tabela5[[#This Row],[Quantidade_5]]/Tabela5[[#This Row],[Rendimento (g)]] -> 30 | W5: =IFERROR(VLOOKUP(Tabela5[[#This Row],[Ingrediente_5]],Tabela2[[Materiais]:[Unidade]],2,0),"") -> g | X5: Barra chocolate amargo SICAO | Y5: 200 | Z5: =SUMIFS(Produção!AT:AT,Produção!B:B,Tabela5[[#This Row],[Produto]])*Tabela5[[#This Row],[Quantidade_6]]/Tabela5[[#This Row],[Rendimento (g)]] -> 666.66667 | AA5: =IFERROR(VLOOKUP(Tabela5[[#This Row],[Ingrediente_6]],Tabela2[[Materiais]:[Unidade]],2,0),"") -> g | AD5: =SUMIFS(Produção!AT:AT,Produção!B:B,Tabela5[[#This Row],[Produto]])*Tabela5[[#This Row],[Quantidade_7]]/Tabela5[[#This Row],[Rendimento (g)]] -> 0 | AE5: =IFERROR(VLOOKUP(Tabela5[[#This Row],[Ingrediente_7]],Tabela2[[Materiais]:[Unidade]],2,0),"")
B6: Brigadeiro Coco | C6: 550 | D6: Leite Condensado | E6: 395 | F6: =SUMIFS(Produção!AT:AT,Produção!B:B,Tabela5[[#This Row],[Produto]])*Tabela5[[#This Row],[Quantidade_1]]/Tabela5[[#This Row],[Rendimento (g)]] -> 718.18182 | G6: =IFERROR(VLOOKUP(Tabela5[[#This Row],[Ingrediente_1]],Tabela2[[Materiais]:[Unidade]],2,0),"") -> g | H6: Manteiga sem sal | I6: 15 | J6: =SUMIFS(Produção!AT:AT,Produção!B:B,Tabela5[[#This Row],[Produto]])*Tabela5[[#This Row],[Quantidade_2]]/Tabela5[[#This Row],[Rendimento (g)]] -> 27.272727 | K6: =IFERROR(VLOOKUP(Tabela5[[#This Row],[Ingrediente_2]],Tabela2[[Materiais]:[Unidade]],2,0),"") -> g | L6: Barra chocolate branco SICAO | M6: 40 | N6: =SUMIFS(Produção!AT:AT,Produção!B:B,Tabela5[[#This Row],[Produto]])*Tabela5[[#This Row],[Quantidade_3]]/Tabela5[[#This Row],[Rendimento (g)]] -> 72.727273 | O6: =IFERROR(VLOOKUP(Tabela5[[#This Row],[Ingrediente_3]],Tabela2[[Materiais]:[Unidade]],2,0),"") -> g | P6: Côco ralado fino | Q6: 50 | R6: =SUMIFS(Produção!AT:AT,Produção!B:B,Tabela5[[#This Row],[Produto]])*Tabela5[[#This Row],[Quantidade_4]]/Tabela5[[#This Row],[Rendimento (g)]] -> 90.909091 | S6: =IFERROR(VLOOKUP(Tabela5[[#This Row],[Ingrediente_4]],Tabela2[[Materiais]:[Unidade]],2,0),"") -> g | T6: Côco ralado grosso | U6: 60 | V6: =SUMIFS(Produção!AT:AT,Produção!B:B,Tabela5[[#This Row],[Produto]])*Tabela5[[#This Row],[Quantidade_5]]/Tabela5[[#This Row],[Rendimento (g)]] -> 109.09091 | W6: =IFERROR(VLOOKUP(Tabela5[[#This Row],[Ingrediente_5]],Tabela2[[Materiais]:[Unidade]],2,0),"") -> g | Z6: =SUMIFS(Produção!AT:AT,Produção!B:B,Tabela5[[#This Row],[Produto]])*Tabela5[[#This Row],[Quantidade_6]]/Tabela5[[#This Row],[Rendimento (g)]] -> 0 | AA6: =IFERROR(VLOOKUP(Tabela5[[#This Row],[Ingrediente_6]],Tabela2[[Materiais]:[Unidade]],2,0),"") | AD6: =SUMIFS(Produção!AT:AT,Produção!B:B,Tabela5[[#This Row],[Produto]])*Tabela5[[#This Row],[Quantidade_7]]/Tabela5[[#This Row],[Rendimento (g)]] -> 0 | AE6: =IFERROR(VLOOKUP(Tabela5[[#This Row],[Ingrediente_7]],Tabela2[[Materiais]:[Unidade]],2,0),"")
B7: Brigadeiro Café | C7: 500 | D7: Leite Condensado | E7: 395 | F7: =SUMIFS(Produção!AT:AT,Produção!B:B,Tabela5[[#This Row],[Produto]])*Tabela5[[#This Row],[Quantidade_1]]/Tabela5[[#This Row],[Rendimento (g)]] -> 790 | G7: =IFERROR(VLOOKUP(Tabela5[[#This Row],[Ingrediente_1]],Tabela2[[Materiais]:[Unidade]],2,0),"") -> g | H7: Manteiga sem sal | I7: 15 | J7: =SUMIFS(Produção!AT:AT,Produção!B:B,Tabela5[[#This Row],[Produto]])*Tabela5[[#This Row],[Quantidade_2]]/Tabela5[[#This Row],[Rendimento (g)]] -> 30 | K7: =IFERROR(VLOOKUP(Tabela5[[#This Row],[Ingrediente_2]],Tabela2[[Materiais]:[Unidade]],2,0),"") -> g | L7: Nozes pedaço | M7: 27 | N7: =SUMIFS(Produção!AT:AT,Produção!B:B,Tabela5[[#This Row],[Produto]])*Tabela5[[#This Row],[Quantidade_3]]/Tabela5[[#This Row],[Rendimento (g)]] -> 54 | O7: =IFERROR(VLOOKUP(Tabela5[[#This Row],[Ingrediente_3]],Tabela2[[Materiais]:[Unidade]],2,0),"") -> g | P7: Nozes moída | Q7: 50 | R7: =SUMIFS(Produção!AT:AT,Produção!B:B,Tabela5[[#This Row],[Produto]])*Tabela5[[#This Row],[Quantidade_4]]/Tabela5[[#This Row],[Rendimento (g)]] -> 100 | S7: =IFERROR(VLOOKUP(Tabela5[[#This Row],[Ingrediente_4]],Tabela2[[Materiais]:[Unidade]],2,0),"") -> g | T7: Açucar cristal | U7: 40 | V7: =SUMIFS(Produção!AT:AT,Produção!B:B,Tabela5[[#This Row],[Produto]])*Tabela5[[#This Row],[Quantidade_5]]/Tabela5[[#This Row],[Rendimento (g)]] -> 80 | W7: =IFERROR(VLOOKUP(Tabela5[[#This Row],[Ingrediente_5]],Tabela2[[Materiais]:[Unidade]],2,0),"") -> g | Z7: =SUMIFS(Produção!AT:AT,Produção!B:B,Tabela5[[#This Row],[Produto]])*Tabela5[[#This Row],[Quantidade_6]]/Tabela5[[#This Row],[Rendimento (g)]] -> 0 | AA7: =IFERROR(VLOOKUP(Tabela5[[#This Row],[Ingrediente_6]],Tabela2[[Materiais]:[Unidade]],2,0),"") | AD7: =SUMIFS(Produção!AT:AT,Produção!B:B,Tabela5[[#This Row],[Produto]])*Tabela5[[#This Row],[Quantidade_7]]/Tabela5[[#This Row],[Rendimento (g)]] -> 0 | AE7: =IFERROR(VLOOKUP(Tabela5[[#This Row],[Ingrediente_7]],Tabela2[[Materiais]:[Unidade]],2,0),"")
B8: Brigadeiro Nozes | C8: 500 | D8: Leite Condensado | E8: 395 | F8: =SUMIFS(Produção!AT:AT,Produção!B:B,Tabela5[[#This Row],[Produto]])*Tabela5[[#This Row],[Quantidade_1]]/Tabela5[[#This Row],[Rendimento (g)]] -> 790 | G8: =IFERROR(VLOOKUP(Tabela5[[#This Row],[Ingrediente_1]],Tabela2[[Materiais]:[Unidade]],2,0),"") -> g | H8: Manteiga sem sal | I8: 15 | J8: =SUMIFS(Produção!AT:AT,Produção!B:B,Tabela5[[#This Row],[Produto]])*Tabela5[[#This Row],[Quantidade_2]]/Tabela5[[#This Row],[Rendimento (g)]] -> 30 | K8: =IFERROR(VLOOKUP(Tabela5[[#This Row],[Ingrediente_2]],Tabela2[[Materiais]:[Unidade]],2,0),"") -> g | L8: Barra chocolate amargo SICAO | M8: 60 | N8: =SUMIFS(Produção!AT:AT,Produção!B:B,Tabela5[[#This Row],[Produto]])*Tabela5[[#This Row],[Quantidade_3]]/Tabela5[[#This Row],[Rendimento (g)]] -> 120 | O8: =IFERROR(VLOOKUP(Tabela5[[#This Row],[Ingrediente_3]],Tabela2[[Materiais]:[Unidade]],2,0),"") -> g | P8: Café soluvel | Q8: 5 | R8: =SUMIFS(Produção!AT:AT,Produção!B:B,Tabela5[[#This Row],[Produto]])*Tabela5[[#This Row],[Quantidade_4]]/Tabela5[[#This Row],[Rendimento (g)]] -> 10 | S8: =IFERROR(VLOOKUP(Tabela5[[#This Row],[Ingrediente_4]],Tabela2[[Materiais]:[Unidade]],2,0),"") -> g | T8: Chocolate em pó | U8: 15 | V8: =SUMIFS(Produção!AT:AT,Produção!B:B,Tabela5[[#This Row],[Produto]])*Tabela5[[#This Row],[Quantidade_5]]/Tabela5[[#This Row],[Rendimento (g)]] -> 30 | W8: =IFERROR(VLOOKUP(Tabela5[[#This Row],[Ingrediente_5]],Tabela2[[Materiais]:[Unidade]],2,0),"") -> g | X8: Açucar cristal | Y8: 50 | Z8: =SUMIFS(Produção!AT:AT,Produção!B:B,Tabela5[[#This Row],[Produto]])*Tabela5[[#This Row],[Quantidade_6]]/Tabela5[[#This Row],[Rendimento (g)]] -> 100 | AA8: =IFERROR(VLOOKUP(Tabela5[[#This Row],[Ingrediente_6]],Tabela2[[Materiais]:[Unidade]],2,0),"") -> g | AD8: =SUMIFS(Produção!AT:AT,Produção!B:B,Tabela5[[#This Row],[Produto]])*Tabela5[[#This Row],[Quantidade_7]]/Tabela5[[#This Row],[Rendimento (g)]] -> 0 | AE8: =IFERROR(VLOOKUP(Tabela5[[#This Row],[Ingrediente_7]],Tabela2[[Materiais]:[Unidade]],2,0),"")
B9: Brigadeiro Churros | C9: 500 | D9: Leite Condensado | E9: 395 | F9: =SUMIFS(Produção!AT:AT,Produção!B:B,Tabela5[[#This Row],[Produto]])*Tabela5[[#This Row],[Quantidade_1]]/Tabela5[[#This Row],[Rendimento (g)]] -> 790 | G9: =IFERROR(VLOOKUP(Tabela5[[#This Row],[Ingrediente_1]],Tabela2[[Materiais]:[Unidade]],2,0),"") -> g | H9: Manteiga sem sal | I9: 15 | J9: =SUMIFS(Produção!AT:AT,Produção!B:B,Tabela5[[#This Row],[Produto]])*Tabela5[[#This Row],[Quantidade_2]]/Tabela5[[#This Row],[Rendimento (g)]] -> 30 | K9: =IFERROR(VLOOKUP(Tabela5[[#This Row],[Ingrediente_2]],Tabela2[[Materiais]:[Unidade]],2,0),"") -> g | L9: Creme de leite | M9: 50 | N9: =SUMIFS(Produção!AT:AT,Produção!B:B,Tabela5[[#This Row],[Produto]])*Tabela5[[#This Row],[Quantidade_3]]/Tabela5[[#This Row],[Rendimento (g)]] -> 100 | O9: =IFERROR(VLOOKUP(Tabela5[[#This Row],[Ingrediente_3]],Tabela2[[Materiais]:[Unidade]],2,0),"") -> g | P9: Doce de leite cremoso | Q9: 30 | R9: =SUMIFS(Produção!AT:AT,Produção!B:B,Tabela5[[#This Row],[Produto]])*Tabela5[[#This Row],[Quantidade_4]]/Tabela5[[#This Row],[Rendimento (g)]] -> 60 | S9: =IFERROR(VLOOKUP(Tabela5[[#This Row],[Ingrediente_4]],Tabela2[[Materiais]:[Unidade]],2,0),"") -> g | T9: Canela | U9: 2 | V9: =SUMIFS(Produção!AT:AT,Produção!B:B,Tabela5[[#This Row],[Produto]])*Tabela5[[#This Row],[Quantidade_5]]/Tabela5[[#This Row],[Rendimento (g)]] -> 4 | W9: =IFERROR(VLOOKUP(Tabela5[[#This Row],[Ingrediente_5]],Tabela2[[Materiais]:[Unidade]],2,0),"") -> g | X9: Açucar cristal | Y9: 40 | Z9: =SUMIFS(Produção!AT:AT,Produção!B:B,Tabela5[[#This Row],[Produto]])*Tabela5[[#This Row],[Quantidade_6]]/Tabela5[[#This Row],[Rendimento (g)]] -> 80 | AA9: =IFERROR(VLOOKUP(Tabela5[[#This Row],[Ingrediente_6]],Tabela2[[Materiais]:[Unidade]],2,0),"") -> g | AD9: =SUMIFS(Produção!AT:AT,Produção!B:B,Tabela5[[#This Row],[Produto]])*Tabela5[[#This Row],[Quantidade_7]]/Tabela5[[#This Row],[Rendimento (g)]] -> 0 | AE9: =IFERROR(VLOOKUP(Tabela5[[#This Row],[Ingrediente_7]],Tabela2[[Materiais]:[Unidade]],2,0),"")
B10: Brigadeiro Paçoca | C10: 500 | D10: Leite Condensado | E10: 395 | F10: =SUMIFS(Produção!AT:AT,Produção!B:B,Tabela5[[#This Row],[Produto]])*Tabela5[[#This Row],[Quantidade_1]]/Tabela5[[#This Row],[Rendimento (g)]] -> 790 | G10: =IFERROR(VLOOKUP(Tabela5[[#This Row],[Ingrediente_1]],Tabela2[[Materiais]:[Unidade]],2,0),"") -> g | H10: Manteiga sem sal | I10: 15 | J10: =SUMIFS(Produção!AT:AT,Produção!B:B,Tabela5[[#This Row],[Produto]])*Tabela5[[#This Row],[Quantidade_2]]/Tabela5[[#This Row],[Rendimento (g)]] -> 30 | K10: =IFERROR(VLOOKUP(Tabela5[[#This Row],[Ingrediente_2]],Tabela2[[Materiais]:[Unidade]],2,0),"") -> g | L10: Amendoim moído | M10: 50 | N10: =SUMIFS(Produção!AT:AT,Produção!B:B,Tabela5[[#This Row],[Produto]])*Tabela5[[#This Row],[Quantidade_3]]/Tabela5[[#This Row],[Rendimento (g)]] -> 100 | O10: =IFERROR(VLOOKUP(Tabela5[[#This Row],[Ingrediente_3]],Tabela2[[Materiais]:[Unidade]],2,0),"") -> g | P10: Amendoim picado | Q10: 50 | R10: =SUMIFS(Produção!AT:AT,Produção!B:B,Tabela5[[#This Row],[Produto]])*Tabela5[[#This Row],[Quantidade_4]]/Tabela5[[#This Row],[Rendimento (g)]] -> 100 | S10: =IFERROR(VLOOKUP(Tabela5[[#This Row],[Ingrediente_4]],Tabela2[[Materiais]:[Unidade]],2,0),"") -> g | V10: =SUMIFS(Produção!AT:AT,Produção!B:B,Tabela5[[#This Row],[Produto]])*Tabela5[[#This Row],[Quantidade_5]]/Tabela5[[#This Row],[Rendimento (g)]] -> 0 | W10: =IFERROR(VLOOKUP(Tabela5[[#This Row],[Ingrediente_5]],Tabela2[[Materiais]:[Unidade]],2,0),"") | Z10: =SUMIFS(Produção!AT:AT,Produção!B:B,Tabela5[[#This Row],[Produto]])*Tabela5[[#This Row],[Quantidade_6]]/Tabela5[[#This Row],[Rendimento (g)]] -> 0 | AA10: =IFERROR(VLOOKUP(Tabela5[[#This Row],[Ingrediente_6]],Tabela2[[Materiais]:[Unidade]],2,0),"") | AD10: =SUMIFS(Produção!AT:AT,Produção!B:B,Tabela5[[#This Row],[Produto]])*Tabela5[[#This Row],[Quantidade_7]]/Tabela5[[#This Row],[Rendimento (g)]] -> 0 | AE10: =IFERROR(VLOOKUP(Tabela5[[#This Row],[Ingrediente_7]],Tabela2[[Materiais]:[Unidade]],2,0),"")
B11: Brigadeiro Limão | C11: 550 | D11: Leite Condensado | E11: 395 | F11: =SUMIFS(Produção!AT:AT,Produção!B:B,Tabela5[[#This Row],[Produto]])*Tabela5[[#This Row],[Quantidade_1]]/Tabela5[[#This Row],[Rendimento (g)]] -> 718.18182 | G11: =IFERROR(VLOOKUP(Tabela5[[#This Row],[Ingrediente_1]],Tabela2[[Materiais]:[Unidade]],2,0),"") -> g | H11: Manteiga sem sal | I11: 15 | J11: =SUMIFS(Produção!AT:AT,Produção!B:B,Tabela5[[#This Row],[Produto]])*Tabela5[[#This Row],[Quantidade_2]]/Tabela5[[#This Row],[Rendimento (g)]] -> 27.272727 | K11: =IFERROR(VLOOKUP(Tabela5[[#This Row],[Ingrediente_2]],Tabela2[[Materiais]:[Unidade]],2,0),"") -> g | L11: Barra chocolate branco SICAO | M11: 30 | N11: =SUMIFS(Produção!AT:AT,Produção!B:B,Tabela5[[#This Row],[Produto]])*Tabela5[[#This Row],[Quantidade_3]]/Tabela5[[#This Row],[Rendimento (g)]] -> 54.545455 | O11: =IFERROR(VLOOKUP(Tabela5[[#This Row],[Ingrediente_3]],Tabela2[[Materiais]:[Unidade]],2,0),"") -> g | P11: Creme de leite | Q11: 50 | R11: =SUMIFS(Produção!AT:AT,Produção!B:B,Tabela5[[#This Row],[Produto]])*Tabela5[[#This Row],[Quantidade_4]]/Tabela5[[#This Row],[Rendimento (g)]] -> 90.909091 | S11: =IFERROR(VLOOKUP(Tabela5[[#This Row],[Ingrediente_4]],Tabela2[[Materiais]:[Unidade]],2,0),"") -> g | T11: Limão | U11: 50 | V11: =SUMIFS(Produção!AT:AT,Produção!B:B,Tabela5[[#This Row],[Produto]])*Tabela5[[#This Row],[Quantidade_5]]/Tabela5[[#This Row],[Rendimento (g)]] -> 90.909091 | W11: =IFERROR(VLOOKUP(Tabela5[[#This Row],[Ingrediente_5]],Tabela2[[Materiais]:[Unidade]],2,0),"") -> g | X11: Açucar cristal | Y11: 50 | Z11: =SUMIFS(Produção!AT:AT,Produção!B:B,Tabela5[[#This Row],[Produto]])*Tabela5[[#This Row],[Quantidade_6]]/Tabela5[[#This Row],[Rendimento (g)]] -> 90.909091 | AA11: =IFERROR(VLOOKUP(Tabela5[[#This Row],[Ingrediente_6]],Tabela2[[Materiais]:[Unidade]],2,0),"") -> g | AD11: =SUMIFS(Produção!AT:AT,Produção!B:B,Tabela5[[#This Row],[Produto]])*Tabela5[[#This Row],[Quantidade_7]]/Tabela5[[#This Row],[Rendimento (g)]] -> 0 | AE11: =IFERROR(VLOOKUP(Tabela5[[#This Row],[Ingrediente_7]],Tabela2[[Materiais]:[Unidade]],2,0),"")

Sheet Entradas e Saídas
B2: Registro
B4: Data | C4: Mês | D4: Ano | E4: Departamento | F4: Descrição | G4: Valor | H4: Quantidade | I4: Unidade
B5: =42722+(365*4) -> 44182 | C5: =MONTH(Tabela6[[#This Row],[Data]]) -> 12 | D5: =YEAR(Tabela6[[#This Row],[Data]]) -> 2020 | E5: Ingredientes | F5: Oreo | G5: -1.49 | H5: 10 | I5: =IFERROR(VLOOKUP(Tabela6[[#This Row],[Descrição]],Materiais!B:C,2,0),"")
B6: =42724+(365*4) -> 44184 | C6: =MONTH(Tabela6[[#This Row],[Data]]) -> 12 | D6: =YEAR(Tabela6[[#This Row],[Data]]) -> 2020 | E6: Ingredientes | F6: Açucar cristal | G6: -3.58 | H6: 1000 | I6: =IFERROR(VLOOKUP(Tabela6[[#This Row],[Descrição]],Materiais!B:C,2,0),"") -> g
B7: =42724+(365*4) -> 44184 | C7: =MONTH(Tabela6[[#This Row],[Data]]) -> 12 | D7: =YEAR(Tabela6[[#This Row],[Data]]) -> 2020 | E7: Ingredientes | F7: Canela | G7: -3.79 | H7: 35 | I7: =IFERROR(VLOOKUP(Tabela6[[#This Row],[Descrição]],Materiais!B:C,2,0),"") -> g
B8: =42724+(365*4) -> 44184 | C8: =MONTH(Tabela6[[#This Row],[Data]]) -> 12 | D8: =YEAR(Tabela6[[#This Row],[Data]]) -> 2020 | E8: Ingredientes | F8: Creme de leite | G8: -19.35 | H8: 1000 | I8: =IFERROR(VLOOKUP(Tabela6[[#This Row],[Descrição]],Materiais!B:C,2,0),"") -> g
B9: =42724+(365*4) -> 44184 | C9: =MONTH(Tabela6[[#This Row],[Data]]) -> 12 | D9: =YEAR(Tabela6[[#This Row],[Data]]) -> 2020 | E9: Ingredientes | F9: Farinha de trigo | G9: -2.59 | H9: 1000 | I9: =IFERROR(VLOOKUP(Tabela6[[#This Row],[Descrição]],Materiais!B:C,2,0),"") -> g
B10: =42724+(365*4) -> 44184 | C10: =MONTH(Tabela6[[#This Row],[Data]]) -> 12 | D10: =YEAR(Tabela6[[#This Row],[Data]]) -> 2020 | E10: Ingredientes | F10: Leite condensado | G10: -67.05 | H10: 5925 | I10: =IFERROR(VLOOKUP(Tabela6[[#This Row],[Descrição]],Materiais!B:C,2,0),"") -> g
B11: =42724+(365*4) -> 44184 | C11: =MONTH(Tabela6[[#This Row],[Data]]) -> 12 | D11: =YEAR(Tabela6[[#This Row],[Data]]) -> 2020 | E11: Ingredientes | F11: Manteiga sem sal | G11: -7.85 | H11: 200 | I11: =IFERROR(VLOOKUP(Tabela6[[#This Row],[Descrição]],Materiais!B:C,2,0),"") -> g
B12: =42734+(365*4) -> 44194 | C12: =MONTH(Tabela6[[#This Row],[Data]]) -> 12 | D12: =YEAR(Tabela6[[#This Row],[Data]]) -> 2020 | E12: Ingredientes | F12: Barra chocolate amargo SICAO | G12: -25.2 | H12: 1050 | I12: =IFERROR(VLOOKUP(Tabela6[[#This Row],[Descrição]],Materiais!B:C,2,0),"") -> g
B13: =42734+(365*4) -> 44194 | C13: =MONTH(Tabela6[[#This Row],[Data]]) -> 12 | D13: =YEAR(Tabela6[[#This Row],[Data]]) -> 2020 | E13: Ingredientes | F13: Barra chocolate ao leite SICAO | G13: -25.4 | H13: 1050 | I13: =IFERROR(VLOOKUP(Tabela6[[#This Row],[Descrição]],Materiais!B:C,2,0),"")
B14: =42734+(365*4) -> 44194 | C14: =MONTH(Tabela6[[#This Row],[Data]]) -> 12 | D14: =YEAR(Tabela6[[#This Row],[Data]]) -> 2020 | E14: Ingredientes | F14: Cacau em pó | G14: -19.6 | H14: 500 | I14: =IFERROR(VLOOKUP(Tabela6[[#This Row],[Descrição]],Materiais!B:C,2,0),"") -> g
B15: =42734+(365*4) -> 44194 | C15: =MONTH(Tabela6[[#This Row],[Data]]) -> 12 | D15: =YEAR(Tabela6[[#This Row],[Data]]) -> 2020 | E15: Ingredientes | F15: Chocolate em pó | G15: -6.9 | H15: 300 | I15: =IFERROR(VLOOKUP(Tabela6[[#This Row],[Descrição]],Materiais!B:C,2,0),"") -> g
B16: =42734+(365*4) -> 44194 | C16: =MONTH(Tabela6[[#This Row],[Data]]) -> 12 | D16: =YEAR(Tabela6[[#This Row],[Data]]) -> 2020 | E16: Ingredientes | F16: Doce de leite cremoso | G16: -11.8 | H16: 800 | I16: =IFERROR(VLOOKUP(Tabela6[[#This Row],[Descrição]],Materiais!B:C,2,0),"") -> g
B17: =42734+(365*4) -> 44194 | C17: =MONTH(Tabela6[[#This Row],[Data]]) -> 12 | D17: =YEAR(Tabela6[[#This Row],[Data]]) -> 2020 | E17: Embalagens | F17: Forminha | G17: -4 | H17: 400 | I17: =IFERROR(VLOOKUP(Tabela6[[#This Row],[Descrição]],Materiais!B:C,2,0),"")
B18: =42734+(365*4) -> 44194 | C18: =MONTH(Tabela6[[#This Row],[Data]]) -> 12 | D18: =YEAR(Tabela6[[#This Row],[Data]]) -> 2020 | E18: Ingredientes | F18: Granulado redondo pequeno | G18: -8.6 | H18: 500 | I18: =IFERROR(VLOOKUP(Tabela6[[#This Row],[Descrição]],Materiais!B:C,2,0),"")
B19: =42751+(365*4) -> 44211 | C19: =MONTH(Tabela6[[#This Row],[Data]]) -> 1 | D19: =YEAR(Tabela6[[#This Row],[Data]]) -> 2021 | E19: Vendas | F19: Brigadeiro Chocolate | G19: 10 | H19: 5 | I19: =IFERROR(VLOOKUP(Tabela6[[#This Row],[Descrição]],Materiais!B:C,2,0),"")
B20: =42751+(365*4) -> 44211 | C20: =MONTH(Tabela6[[#This Row],[Data]]) -> 1 | D20: =YEAR(Tabela6[[#This Row],[Data]]) -> 2021 | E20: Vendas | F20: Brigadeiro Churros | G20: 8 | H20: 4 | I20: =IFERROR(VLOOKUP(Tabela6[[#This Row],[Descrição]],Materiais!B:C,2,0),"")
B21: =42752+(365*4) -> 44212 | C21: =MONTH(Tabela6[[#This Row],[Data]]) -> 1 | D21: =YEAR(Tabela6[[#This Row],[Data]]) -> 2021 | E21: Vendas | F21: Brigadeiro Chocolate | G21: 36 | H21: 18 | I21: =IFERROR(VLOOKUP(Tabela6[[#This Row],[Descrição]],Materiais!B:C,2,0),"")
B22: =42752+(365*4) -> 44212 | C22: =MONTH(Tabela6[[#This Row],[Data]]) -> 1 | D22: =YEAR(Tabela6[[#This Row],[Data]]) -> 2021 | E22: Vendas | F22: Brigadeiro Churros | G22: 30 | H22: 15 | I22: =IFERROR(VLOOKUP(Tabela6[[#This Row],[Descrição]],Materiais!B:C,2,0),"")
B23: =42753+(365*4) -> 44213 | C23: =MONTH(Tabela6[[#This Row],[Data]]) -> 1 | D23: =YEAR(Tabela6[[#This Row],[Data]]) -> 2021 | E23: Vendas | F23: Brigadeiro Chocolate | G23: 10 | H23: 5 | I23: =IFERROR(VLOOKUP(Tabela6[[#This Row],[Descrição]],Materiais!B:C,2,0),"")
B24: =42753+(365*4) -> 44213 | C24: =MONTH(Tabela6[[#This Row],[Data]]) -> 1 | D24: =YEAR(Tabela6[[#This Row],[Data]]) -> 2021 | E24: Vendas | F24: Brigadeiro Churros | G24: 8 | H24: 4 | I24: =IFERROR(VLOOKUP(Tabela6[[#This Row],[Descrição]],Materiais!B:C,2,0),"")
B25: =42753+(365*4) -> 44213 | C25: =MONTH(Tabela6[[#This Row],[Data]]) -> 1 | D25: =YEAR(Tabela6[[#This Row],[Data]]) -> 2021 | E25: Vendas | F25: Croc-croc (Oreo) | G25: 6 | H25: 3 | I25: =IFERROR(VLOOKUP(Tabela6[[#This Row],[Descrição]],Materiais!B:C,2,0),"")
B26: =42754+(365*4) -> 44214 | C26: =MONTH(Tabela6[[#This Row],[Data]]) -> 1 | D26: =YEAR(Tabela6[[#This Row],[Data]]) -> 2021 | E26: Vendas | F26: Brigadeiro Chocolate | G26: 26 | H26: 13 | I26: =IFERROR(VLOOKUP(Tabela6[[#This Row],[Descrição]],Materiais!B:C,2,0),"")
B27: =42754+(365*4) -> 44214 | C27: =MONTH(Tabela6[[#This Row],[Data]]) -> 1 | D27: =YEAR(Tabela6[[#This Row],[Data]]) -> 2021 | E27: Vendas | F27: Brigadeiro Churros | G27: 12 | H27: 6 | I27: =IFERROR(VLOOKUP(Tabela6[[#This Row],[Descrição]],Materiais!B:C,2,0),"")
B28: =42754+(365*4) -> 44214 | C28: =MONTH(Tabela6[[#This Row],[Data]]) -> 1 | D28: =YEAR(Tabela6[[#This Row],[Data]]) -> 2021 | E28: Vendas | F28: Croc-croc (Oreo) | G28: 12 | H28: 6 | I28: =IFERROR(VLOOKUP(Tabela6[[#This Row],[Descrição]],Materiais!B:C,2,0),"")
B29: =42755+(365*4) -> 44215 | C29: =MONTH(Tabela6[[#This Row],[Data]]) -> 1 | D29: =YEAR(Tabela6[[#This Row],[Data]]) -> 2021 | E29: Embalagens | F29: Bandeja isopor | G29: -1.7 | H29: 10 | I29: =IFERROR(VLOOKUP(Tabela6[[#This Row],[Descrição]],Materiais!B:C,2,0),"")
B30: =42755+(365*4) -> 44215 | C30: =MONTH(Tabela6[[#This Row],[Data]]) -> 1 | D30: =YEAR(Tabela6[[#This Row],[Data]]) -> 2021 | E30: Vendas | F30: Brigadeiro Chocolate | G30: 6 | H30: 3 | I30: =IFERROR(VLOOKUP(Tabela6[[#This Row],[Descrição]],Materiais!B:C,2,0),"")
B31: =42755+(365*4) -> 44215 | C31: =MONTH(Tabela6[[#This Row],[Data]]) -> 1 | D31: =YEAR(Tabela6[[#This Row],[Data]]) -> 2021 | E31: Ingredientes | F31: Côco ralado fino | G31: -4.3 | H31: 246 | I31: =IFERROR(VLOOKUP(Tabela6[[#This Row],[Descrição]],Materiais!B:C,2,0),"") -> g
B32: =42755+(365*4) -> 44215 | C32: =MONTH(Tabela6[[#This Row],[Data]]) -> 1 | D32: =YEAR(Tabela6[[#This Row],[Data]]) -> 2021 | E32: Ingredientes | F32: Côco ralado grosso | G32: -6.45 | H32: 205 | I32: =IFERROR(VLOOKUP(Tabela6[[#This Row],[Descrição]],Materiais!B:C,2,0),"") -> g
B33: =42755+(365*4) -> 44215 | C33: =MONTH(Tabela6[[#This Row],[Data]]) -> 1 | D33: =YEAR(Tabela6[[#This Row],[Data]]) -> 2021 | E33: Vendas | F33: Croc-croc (Oreo) | G33: 26 | H33: 13 | I33: =IFERROR(VLOOKUP(Tabela6[[#This Row],[Descrição]],Materiais!B:C,2,0),"")
B34: =42755+(365*4) -> 44215 | C34: =MONTH(Tabela6[[#This Row],[Data]]) -> 1 | D34: =YEAR(Tabela6[[#This Row],[Data]]) -> 2021 | E34: Embalagens | F34: Forma quadrada exibição | G34: -2.5 | H34: 2 | I34: =IFERROR(VLOOKUP(Tabela6[[#This Row],[Descrição]],Materiais!B:C,2,0),"")
B35: =42755+(365*4) -> 44215 | C35: =MONTH(Tabela6[[#This Row],[Data]]) -> 1 | D35: =YEAR(Tabela6[[#This Row],[Data]]) -> 2021 | E35: Embalagens | F35: Forminha | G35: -5 | H35: 300 | I35: =IFERROR(VLOOKUP(Tabela6[[#This Row],[Descrição]],Materiais!B:C,2,0),"")
B36: =42755+(365*4) -> 44215 | C36: =MONTH(Tabela6[[#This Row],[Data]]) -> 1 | D36: =YEAR(Tabela6[[#This Row],[Data]]) -> 2021 | E36: Ingredientes | F36: Granulado redondo pequeno | G36: -8.6 | H36: 500 | I36: =IFERROR(VLOOKUP(Tabela6[[#This Row],[Descrição]],Materiais!B:C,2,0),"")
B37: =42755+(365*4) -> 44215 | C37: =MONTH(Tabela6[[#This Row],[Data]]) -> 1 | D37: =YEAR(Tabela6[[#This Row],[Data]]) -> 2021 | E37: Ingredientes | F37: Leite condensado | G37: -85.35 | H37: 5925 | I37: =IFERROR(VLOOKUP(Tabela6[[#This Row],[Descrição]],Materiais!B:C,2,0),"") -> g
B38: =42755+(365*4) -> 44215 | C38: =MONTH(Tabela6[[#This Row],[Data]]) -> 1 | D38: =YEAR(Tabela6[[#This Row],[Data]]) -> 2021 | E38: Ingredientes | F38: Ovomaltine | G38: -7.09 | H38: 300 | I38: =IFERROR(VLOOKUP(Tabela6[[#This Row],[Descrição]],Materiais!B:C,2,0),"")
B39: =42755+(365*4) -> 44215 | C39: =MONTH(Tabela6[[#This Row],[Data]]) -> 1 | D39: =YEAR(Tabela6[[#This Row],[Data]]) -> 2021 | E39: Embalagens | F39: saco plástico 30x45 | G39: -2.3 | H39: 100 | I39: =IFERROR(VLOOKUP(Tabela6[[#This Row],[Descrição]],Materiais!B:C,2,0),"")
B40: =42758+(365*4) -> 44218 | C40: =MONTH(Tabela6[[#This Row],[Data]]) -> 1 | D40: =YEAR(Tabela6[[#This Row],[Data]]) -> 2021 | E40: Vendas | F40: Brigadeiro Chocolate | G40: 16 | H40: 8 | I40: =IFERROR(VLOOKUP(Tabela6[[#This Row],[Descrição]],Materiais!B:C,2,0),"")
B41: =42758+(365*4) -> 44218 | C41: =MONTH(Tabela6[[#This Row],[Data]]) -> 1 | D41: =YEAR(Tabela6[[#This Row],[Data]]) -> 2021 | E41: Vendas | F41: Brigadeiro Churros | G41: 4 | H41: 2 | I41: =IFERROR(VLOOKUP(Tabela6[[#This Row],[Descrição]],Materiais!B:C,2,0),"")
B42: =42759+(365*4) -> 44219 | C42: =MONTH(Tabela6[[#This Row],[Data]]) -> 1 | D42: =YEAR(Tabela6[[#This Row],[Data]]) -> 2021 | E42: Vendas | F42: Brigadeiro Chocolate | G42: 14 | H42: 7 | I42: =IFERROR(VLOOKUP(Tabela6[[#This Row],[Descrição]],Materiais!B:C,2,0),"")
...

Sheet Fluxo de Caixa
B2: Fluxo de Caixa
B4: Fluxo de Caixa
C5: 44166 | D5: 44197 | E5: 44228 | F5: 44256 | G5: 44287 | H5: 44317 | I5: 44348 | J5: 44378 | K5: 44409 | L5: 44440 | M5: 44470 | N5: 44501 | O5: 44531 | P5: 44562 | Q5: 44593 | R5: 44621 | S5: 44652 | T5: 44682 | U5: 44713 | V5: 44743 | W5: 44774 | X5: 44805 | Y5: 44835 | Z5: 44866 | AA5: 44896 | AB5: 44927 | AC5: 44958 | AD5: 44986 | AE5: 45017 | AF5: 45047 | AG5: 45078 | AH5: 45108 | AI5: 45139 | AJ5: 45170 | AK5: 45200 | AL5: 45231 | AM5: 45261 | AN5: 45292 | AO5: 45323 | AP5: 45352 | AQ5: 45383 | AR5: 45413 | AS5: 45444
B6: Investimento | C6: =SUMIFS('Entradas e Saídas'!$G:$G,'Entradas e Saídas'!$E:$E,'Fluxo de Caixa'!$B6,'Entradas e Saídas'!$C:$C,MONTH('Fluxo de Caixa'!C$5),'Entradas e Saídas'!$D:$D,YEAR('Fluxo de Caixa'!C$5)) -> 0 | D6: =SUMIFS('Entradas e Saídas'!$G:$G,'Entradas e Saídas'!$E:$E,'Fluxo de Caixa'!$B6,'Entradas e Saídas'!$C:$C,MONTH('Fluxo de Caixa'!D$5),'Entradas e Saídas'!$D:$D,YEAR('Fluxo de Caixa'!D$5)) -> 0 | E6: =SUMIFS('Entradas e Saídas'!$G:$G,'Entradas e Saídas'!$E:$E,'Fluxo de Caixa'!$B6,'Entradas e Saídas'!$C:$C,MONTH('Fluxo de Caixa'!E$5),'Entradas e Saídas'!$D:$D,YEAR('Fluxo de Caixa'!E$5)) -> 0 | F6: =SUMIFS('Entradas e Saídas'!$G:$G,'Entradas e Saídas'!$E:$E,'Fluxo de Caixa'!$B6,'Entradas e Saídas'!$C:$C,MONTH('Fluxo de Caixa'!F$5),'Entradas e Saídas'!$D:$D,YEAR('Fluxo de Caixa'!F$5)) -> 0 | G6: =SUMIFS('Entradas e Saídas'!$G:$G,'Entradas e Saídas'!$E:$E,'Fluxo de Caixa'!$B6,'Entradas e Saídas'!$C:$C,MONTH('Fluxo de Caixa'!G$5),'Entradas e Saídas'!$D:$D,YEAR('Fluxo de Caixa'!G$5)) -> 0 | H6: =SUMIFS('Entradas e Saídas'!$G:$G,'Entradas e Saídas'!$E:$E,'Fluxo de Caixa'!$B6,'Entradas e Saídas'!$C:$C,MONTH('Fluxo de Caixa'!H$5),'Entradas e Saídas'!$D:$D,YEAR('Fluxo de Caixa'!H$5)) -> 0 | I6: =SUMIFS('Entradas e Saídas'!$G:$G,'Entradas e Saídas'!$E:$E,'Fluxo de Caixa'!$B6,'Entradas e Saídas'!$C:$C,MONTH('Fluxo de Caixa'!I$5),'Entradas e Saídas'!$D:$D,YEAR('Fluxo de Caixa'!I$5)) -> 0 | J6: =SUMIFS('Entradas e Saídas'!$G:$G,'Entradas e Saídas'!$E:$E,'Fluxo de Caixa'!$B6,'Entradas e Saídas'!$C:$C,MONTH('Fluxo de Caixa'!J$5),'Entradas e Saídas'!$D:$D,YEAR('Fluxo de Caixa'!J$5)) -> 0 | ... AS6: =SUMIFS('Entradas e Saídas'!$G:$G,'Entradas e Saídas'!$E:$E,'Fluxo de Caixa'!$B6,'Entradas e Saídas'!$C:$C,MONTH('Fluxo de Caixa'!AS$5),'Entradas e Saídas'!$D:$D,YEAR('Fluxo de Caixa'!AS$5)) -> 0
B7: Operacional | C7: =SUMIFS('Entradas e Saídas'!$G:$G,'Entradas e Saídas'!$E:$E,'Fluxo de Caixa'!$B7,'Entradas e Saídas'!$C:$C,MONTH('Fluxo de Caixa'!C$5),'Entradas e Saídas'!$D:$D,YEAR('Fluxo de Caixa'!C$5)) -> 0 | D7: =SUMIFS('Entradas e Saídas'!$G:$G,'Entradas e Saídas'!$E:$E,'Fluxo de Caixa'!$B7,'Entradas e Saídas'!$C:$C,MONTH('Fluxo de Caixa'!D$5),'Entradas e Saídas'!$D:$D,YEAR('Fluxo de Caixa'!D$5)) -> 0 | E7: =SUMIFS('Entradas e Saídas'!$G:$G,'Entradas e Saídas'!$E:$E,'Fluxo de Caixa'!$B7,'Entradas e Saídas'!$C:$C,MONTH('Fluxo de Caixa'!E$5),'Entradas e Saídas'!$D:$D,YEAR('Fluxo de Caixa'!E$5)) -> 0 | F7: =SUMIFS('Entradas e Saídas'!$G:$G,'Entradas e Saídas'!$E:$E,'Fluxo de Caixa'!$B7,'Entradas e Saídas'!$C:$C,MONTH('Fluxo de Caixa'!F$5),'Entradas e Saídas'!$D:$D,YEAR('Fluxo de Caixa'!F$5)) -> 0 | G7: =SUMIFS('Entradas e Saídas'!$G:$G,'Entradas e Saídas'!$E:$E,'Fluxo de Caixa'!$B7,'Entradas e Saídas'!$C:$C,MONTH('Fluxo de Caixa'!G$5),'Entradas e Saídas'!$D:$D,YEAR('Fluxo de Caixa'!G$5)) -> 0 | H7: =SUMIFS('Entradas e Saídas'!$G:$G,'Entradas e Saídas'!$E:$E,'Fluxo de Caixa'!$B7,'Entradas e Saídas'!$C:$C,MONTH('Fluxo de Caixa'!H$5),'Entradas e Saídas'!$D:$D,YEAR('Fluxo de Caixa'!H$5)) -> 0 | I7: =SUMIFS('Entradas e Saídas'!$G:$G,'Entradas e Saídas'!$E:$E,'Fluxo de Caixa'!$B7,'Entradas e Saídas'!$C:$C,MONTH('Fluxo de Caixa'!I$5),'Entradas e Saídas'!$D:$D,YEAR('Fluxo de Caixa'!I$5)) -> 0 | J7: =SUMIFS('Entradas e Saídas'!$G:$G,'Entradas e Saídas'!$E:$E,'Fluxo de Caixa'!$B7,'Entradas e Saídas'!$C:$C,MONTH('Fluxo de Caixa'!J$5),'Entradas e Saídas'!$D:$D,YEAR('Fluxo de Caixa'!J$5)) -> 0 | ... AS7: =SUMIFS('Entradas e Saídas'!$G:$G,'Entradas e Saídas'!$E:$E,'Fluxo de Caixa'!$B7,'Entradas e Saídas'!$C:$C,MONTH('Fluxo de Caixa'!AS$5),'Entradas e Saídas'!$D:$D,YEAR('Fluxo de Caixa'!AS$5)) -> 0
B8: Marketing | C8: =SUMIFS('Entradas e Saídas'!$G:$G,'Entradas e Saídas'!$E:$E,'Fluxo de Caixa'!$B8,'Entradas e Saídas'!$C:$C,MONTH('Fluxo de Caixa'!C$5),'Entradas e Saídas'!$D:$D,YEAR('Fluxo de Caixa'!C$5)) -> 0 | D8: =SUMIFS('Entradas e Saídas'!$G:$G,'Entradas e Saídas'!$E:$E,'Fluxo de Caixa'!$B8,'Entradas e Saídas'!$C:$C,MONTH('Fluxo de Caixa'!D$5),'Entradas e Saídas'!$D:$D,YEAR('Fluxo de Caixa'!D$5)) -> 0 | E8: =SUMIFS('Entradas e Saídas'!$G:$G,'Entradas e Saídas'!$E:$E,'Fluxo de Caixa'!$B8,'Entradas e Saídas'!$C:$C,MONTH('Fluxo de Caixa'!E$5),'Entradas e Saídas'!$D:$D,YEAR('Fluxo de Caixa'!E$5)) -> 0 | F8: =SUMIFS('Entradas e Saídas'!$G:$G,'Entradas e Saídas'!$E:$E,'Fluxo de Caixa'!$B8,'Entradas e Saídas'!$C:$C,MONTH('Fluxo de Caixa'!F$5),'Entradas e Saídas'!$D:$D,YEAR('Fluxo de Caixa'!F$5)) -> 0 | G8: =SUMIFS('Entradas e Saídas'!$G:$G,'Entradas e Saídas'!$E:$E,'Fluxo de Caixa'!$B8,'Entradas e Saídas'!$C:$C,MONTH('Fluxo de Caixa'!G$5),'Entradas e Saídas'!$D:$D,YEAR('Fluxo de Caixa'!G$5)) -> 0 | H8: =SUMIFS('Entradas e Saídas'!$G:$G,'Entradas e Saídas'!$E:$E,'Fluxo de Caixa'!$B8,'Entradas e Saídas'!$C:$C,MONTH('Fluxo de Caixa'!H$5),'Entradas e Saídas'!$D:$D,YEAR('Fluxo de Caixa'!H$5)) -> 0 | I8: =SUMIFS('Entradas e Saídas'!$G:$G,'Entradas e Saídas'!$E:$E,'Fluxo de Caixa'!$B8,'Entradas e Saídas'!$C:$C,MONTH('Fluxo de Caixa'!I$5),'Entradas e Saídas'!$D:$D,YEAR('Fluxo de Caixa'!I$5)) -> 0 | J8: =SUMIFS('Entradas e Saídas'!$G:$G,'Entradas e Saídas'!$E:$E,'Fluxo de Caixa'!$B8,'Entradas e Saídas'!$C:$C,MONTH('Fluxo de Caixa'!J$5),'Entradas e Saídas'!$D:$D,YEAR('Fluxo de Caixa'!J$5)) -> 0 | ... AS8: =SUMIFS('Entradas e Saídas'!$G:$G,'Entradas e Saídas'!$E:$E,'Fluxo de Caixa'!$B8,'Entradas e Saídas'!$C:$C,MONTH('Fluxo de Caixa'!AS$5),'Entradas e Saídas'!$D:$D,YEAR('Fluxo de Caixa'!AS$5)) -> 0
B9: Embalagens | C9: =SUMIFS('Entradas e Saídas'!$G:$G,'Entradas e Saídas'!$E:$E,'Fluxo de Caixa'!$B9,'Entradas e Saídas'!$C:$C,MONTH('Fluxo de Caixa'!C$5),'Entradas e Saídas'!$D:$D,YEAR('Fluxo de Caixa'!C$5)) -> -4 | D9: =SUMIFS('Entradas e Saídas'!$G:$G,'Entradas e Saídas'!$E:$E,'Fluxo de Caixa'!$B9,'Entradas e Saídas'!$C:$C,MONTH('Fluxo de Caixa'!D$5),'Entradas e Saídas'!$D:$D,YEAR('Fluxo de Caixa'!D$5)) -> -11.5 | E9: =SUMIFS('Entradas e Saídas'!$G:$G,'Entradas e Saídas'!$E:$E,'Fluxo de Caixa'!$B9,'Entradas e Saídas'!$C:$C,MONTH('Fluxo de Caixa'!E$5),'Entradas e Saídas'!$D:$D,YEAR('Fluxo de Caixa'!E$5)) -> -3 | F9: =SUMIFS('Entradas e Saídas'!$G:$G,'Entradas e Saídas'!$E:$E,'Fluxo de Caixa'!$B9,'Entradas e Saídas'!$C:$C,MONTH('Fluxo de Caixa'!F$5),'Entradas e Saídas'!$D:$D,YEAR('Fluxo de Caixa'!F$5)) -> -109.66 | G9: =SUMIFS('Entradas e Saídas'!$G:$G,'Entradas e Saídas'!$E:$E,'Fluxo de Caixa'!$B9,'Entradas e Saídas'!$C:$C,MONTH('Fluxo de Caixa'!G$5),'Entradas e Saídas'!$D:$D,YEAR('Fluxo de Caixa'!G$5)) -> -101.86 | H9: =SUMIFS('Entradas e Saídas'!$G:$G,'Entradas e Saídas'!$E:$E,'Fluxo de Caixa'!$B9,'Entradas e Saídas'!$C:$C,MONTH('Fluxo de Caixa'!H$5),'Entradas e Saídas'!$D:$D,YEAR('Fluxo de Caixa'!H$5)) -> -47.51 | I9: =SUMIFS('Entradas e Saídas'!$G:$G,'Entradas e Saídas'!$E:$E,'Fluxo de Caixa'!$B9,'Entradas e Saídas'!$C:$C,MONTH('Fluxo de Caixa'!I$5),'Entradas e Saídas'!$D:$D,YEAR('Fluxo de Caixa'!I$5)) -> -120.94 | J9: =SUMIFS('Entradas e Saídas'!$G:$G,'Entradas e Saídas'!$E:$E,'Fluxo de Caixa'!$B9,'Entradas e Saídas'!$C:$C,MONTH('Fluxo de Caixa'!J$5),'Entradas e Saídas'!$D:$D,YEAR('Fluxo de Caixa'!J$5)) -> -4.95 | ... AS9: =SUMIFS('Entradas e Saídas'!$G:$G,'Entradas e Saídas'!$E:$E,'Fluxo de Caixa'!$B9,'Entradas e Saídas'!$C:$C,MONTH('Fluxo de Caixa'!AS$5),'Entradas e Saídas'!$D:$D,YEAR('Fluxo de Caixa'!AS$5)) -> 0
B10: Ingredientes | C10: =SUMIFS('Entradas e Saídas'!$G:$G,'Entradas e Saídas'!$E:$E,'Fluxo de Caixa'!$B10,'Entradas e Saídas'!$C:$C,MONTH('Fluxo de Caixa'!C$5),'Entradas e Saídas'!$D:$D,YEAR('Fluxo de Caixa'!C$5)) -> -203.2 | D10: =SUMIFS('Entradas e Saídas'!$G:$G,'Entradas e Saídas'!$E:$E,'Fluxo de Caixa'!$B10,'Entradas e Saídas'!$C:$C,MONTH('Fluxo de Caixa'!D$5),'Entradas e Saídas'!$D:$D,YEAR('Fluxo de Caixa'!D$5)) -> -111.79 | E10: =SUMIFS('Entradas e Saídas'!$G:$G,'Entradas e Saídas'!$E:$E,'Fluxo de Caixa'!$B10,'Entradas e Saídas'!$C:$C,MONTH('Fluxo de Caixa'!E$5),'Entradas e Saídas'!$D:$D,YEAR('Fluxo de Caixa'!E$5)) -> -56.604 | F10: =SUMIFS('Entradas e Saídas'!$G:$G,'Entradas e Saídas'!$E:$E,'Fluxo de Caixa'!$B10,'Entradas e Saídas'!$C:$C,MONTH('Fluxo de Caixa'!F$5),'Entradas e Saídas'!$D:$D,YEAR('Fluxo de Caixa'!F$5)) -> -448.01 | G10: =SUMIFS('Entradas e Saídas'!$G:$G,'Entradas e Saídas'!$E:$E,'Fluxo de Caixa'!$B10,'Entradas e Saídas'!$C:$C,MONTH('Fluxo de Caixa'!G$5),'Entradas e Saídas'!$D:$D,YEAR('Fluxo de Caixa'!G$5)) -> -210.07 | H10: =SUMIFS('Entradas e Saídas'!$G:$G,'Entradas e Saídas'!$E:$E,'Fluxo de Caixa'!$B10,'Entradas e Saídas'!$C:$C,MONTH('Fluxo de Caixa'!H$5),'Entradas e Saídas'!$D:$D,YEAR('Fluxo de Caixa'!H$5)) -> -507.19 | I10: =SUMIFS('Entradas e Saídas'!$G:$G,'Entradas e Saídas'!$E:$E,'Fluxo de Caixa'!$B10,'Entradas e Saídas'!$C:$C,MONTH('Fluxo de Caixa'!I$5),'Entradas e Saídas'!$D:$D,YEAR('Fluxo de Caixa'!I$5)) -> -457.55 | J10: =SUMIFS('Entradas e Saídas'!$G:$G,'Entradas e Saídas'!$E:$E,'Fluxo de Caixa'!$B10,'Entradas e Saídas'!$C:$C,MONTH('Fluxo de Caixa'!J$5),'Entradas e Saídas'!$D:$D,YEAR('Fluxo de Caixa'!J$5)) -> -441.7875 | ... AS10: =SUMIFS('Entradas e Saídas'!$G:$G,'Entradas e Saídas'!$E:$E,'Fluxo de Caixa'!$B10,'Entradas e Saídas'!$C:$C,MONTH('Fluxo de Caixa'!AS$5),'Entradas e Saídas'!$D:$D,YEAR('Fluxo de Caixa'!AS$5)) -> 0
B11: Material | C11: =SUMIFS('Entradas e Saídas'!$G:$G,'Entradas e Saídas'!$E:$E,'Fluxo de Caixa'!$B11,'Entradas e Saídas'!$C:$C,MONTH('Fluxo de Caixa'!C$5),'Entradas e Saídas'!$D:$D,YEAR('Fluxo de Caixa'!C$5)) -> 0 | D11: =SUMIFS('Entradas e Saídas'!$G:$G,'Entradas e Saídas'!$E:$E,'Fluxo de Caixa'!$B11,'Entradas e Saídas'!$C:$C,MONTH('Fluxo de Caixa'!D$5),'Entradas e Saídas'!$D:$D,YEAR('Fluxo de Caixa'!D$5)) -> 0 | E11: =SUMIFS('Entradas e Saídas'!$G:$G,'Entradas e Saídas'!$E:$E,'Fluxo de Caixa'!$B11,'Entradas e Saídas'!$C:$C,MONTH('Fluxo de Caixa'!E$5),'Entradas e Saídas'!$D:$D,YEAR('Fluxo de Caixa'!E$5)) -> 0 | F11: =SUMIFS('Entradas e Saídas'!$G:$G,'Entradas e Saídas'!$E:$E,'Fluxo de Caixa'!$B11,'Entradas e Saídas'!$C:$C,MONTH('Fluxo de Caixa'!F$5),'Entradas e Saídas'!$D:$D,YEAR('Fluxo de Caixa'!F$5)) -> 0 | G11: =SUMIFS('Entradas e Saídas'!$G:$G,'Entradas e Saídas'!$E:$E,'Fluxo de Caixa'!$B11,'Entradas e Saídas'!$C:$C,MONTH('Fluxo de Caixa'!G$5),'Entradas e Saídas'!$D:$D,YEAR('Fluxo de Caixa'!G$5)) -> 0 | H11: =SUMIFS('Entradas e Saídas'!$G:$G,'Entradas e Saídas'!$E:$E,'Fluxo de Caixa'!$B11,'Entradas e Saídas'!$C:$C,MONTH('Fluxo de Caixa'!H$5),'Entradas e Saídas'!$D:$D,YEAR('Fluxo de Caixa'!H$5)) -> 0 | I11: =SUMIFS('Entradas e Saídas'!$G:$G,'Entradas e Saídas'!$E:$E,'Fluxo de Caixa'!$B11,'Entradas e Saídas'!$C:$C,MONTH('Fluxo de Caixa'!I$5),'Entradas e Saídas'!$D:$D,YEAR('Fluxo de Caixa'!I$5)) -> 0 | J11: =SUMIFS('Entradas e Saídas'!$G:$G,'Entradas e Saídas'!$E:$E,'Fluxo de Caixa'!$B11,'Entradas e Saídas'!$C:$C,MONTH('Fluxo de Caixa'!J$5),'Entradas e Saídas'!$D:$D,YEAR('Fluxo de Caixa'!J$5)) -> 0 | ... AS11: =SUMIFS('Entradas e Saídas'!$G:$G,'Entradas e Saídas'!$E:$E,'Fluxo de Caixa'!$B11,'Entradas e Saídas'!$C:$C,MONTH('Fluxo de Caixa'!AS$5),'Entradas e Saídas'!$D:$D,YEAR('Fluxo de Caixa'!AS$5)) -> 0
B12: Vendas | C12: =SUMIFS('Entradas e Saídas'!$G:$G,'Entradas e Saídas'!$E:$E,'Fluxo de Caixa'!$B12,'Entradas e Saídas'!$C:$C,MONTH('Fluxo de Caixa'!C$5),'Entradas e Saídas'!$D:$D,YEAR('Fluxo de Caixa'!C$5)) -> 0 | D12: =SUMIFS('Entradas e Saídas'!$G:$G,'Entradas e Saídas'!$E:$E,'Fluxo de Caixa'!$B12,'Entradas e Saídas'!$C:$C,MONTH('Fluxo de Caixa'!D$5),'Entradas e Saídas'!$D:$D,YEAR('Fluxo de Caixa'!D$5)) -> 418 | E12: =SUMIFS('Entradas e Saídas'!$G:$G,'Entradas e Saídas'!$E:$E,'Fluxo de Caixa'!$B12,'Entradas e Saídas'!$C:$C,MONTH('Fluxo de Caixa'!E$5),'Entradas e Saídas'!$D:$D,YEAR('Fluxo de Caixa'!E$5)) -> 134 | F12: =SUMIFS('Entradas e Saídas'!$G:$G,'Entradas e Saídas'!$E:$E,'Fluxo de Caixa'!$B12,'Entradas e Saídas'!$C:$C,MONTH('Fluxo de Caixa'!F$5),'Entradas e Saídas'!$D:$D,YEAR('Fluxo de Caixa'!F$5)) -> 1062.5 | G12: =SUMIFS('Entradas e Saídas'!$G:$G,'Entradas e Saídas'!$E:$E,'Fluxo de Caixa'!$B12,'Entradas e Saídas'!$C:$C,MONTH('Fluxo de Caixa'!G$5),'Entradas e Saídas'!$D:$D,YEAR('Fluxo de Caixa'!G$5)) -> 509 | H12: =SUMIFS('Entradas e Saídas'!$G:$G,'Entradas e Saídas'!$E:$E,'Fluxo de Caixa'!$B12,'Entradas e Saídas'!$C:$C,MONTH('Fluxo de Caixa'!H$5),'Entradas e Saídas'!$D:$D,YEAR('Fluxo de Caixa'!H$5)) -> 1393.3 | I12: =SUMIFS('Entradas e Saídas'!$G:$G,'Entradas e Saídas'!$E:$E,'Fluxo de Caixa'!$B12,'Entradas e Saídas'!$C:$C,MONTH('Fluxo de Caixa'!I$5),'Entradas e Saídas'!$D:$D,YEAR('Fluxo de Caixa'!I$5)) -> 1605 | J12: =SUMIFS('Entradas e Saídas'!$G:$G,'Entradas e Saídas'!$E:$E,'Fluxo de Caixa'!$B12,'Entradas e Saídas'!$C:$C,MONTH('Fluxo de Caixa'!J$5),'Entradas e Saídas'!$D:$D,YEAR('Fluxo de Caixa'!J$5)) -> 1144 | ... AS12: =SUMIFS('Entradas e Saídas'!$G:$G,'Entradas e Saídas'!$E:$E,'Fluxo de Caixa'!$B12,'Entradas e Saídas'!$C:$C,MONTH('Fluxo de Caixa'!AS$5),'Entradas e Saídas'!$D:$D,YEAR('Fluxo de Caixa'!AS$5)) -> 0
B13: =IF(Produtos!B5="","-",Produtos!B5) -> Brigadeiro Chocolate | C13: =SUMIFS('Entradas e Saídas'!$G:$G,'Entradas e Saídas'!$E:$E,"Vendas",'Entradas e Saídas'!$C:$C,MONTH('Fluxo de Caixa'!C$5),'Entradas e Saídas'!$D:$D,YEAR('Fluxo de Caixa'!C$5),'Entradas e Saídas'!$F:$F,'Fluxo de Caixa'!$B13) -> 0 | D13: =SUMIFS('Entradas e Saídas'!$G:$G,'Entradas e Saídas'!$E:$E,"Vendas",'Entradas e Saídas'!$C:$C,MONTH('Fluxo de Caixa'!D$5),'Entradas e Saídas'!$D:$D,YEAR('Fluxo de Caixa'!D$5),'Entradas e Saídas'!$F:$F,'Fluxo de Caixa'!$B13) -> 186 | E13: =SUMIFS('Entradas e Saídas'!$G:$G,'Entradas e Saídas'!$E:$E,"Vendas",'Entradas e Saídas'!$C:$C,MONTH('Fluxo de Caixa'!E$5),'Entradas e Saídas'!$D:$D,YEAR('Fluxo de Caixa'!E$5),'Entradas e Saídas'!$F:$F,'Fluxo de Caixa'!$B13) -> 64 | F13: =SUMIFS('Entradas e Saídas'!$G:$G,'Entradas e Saídas'!$E:$E,"Vendas",'Entradas e Saídas'!$C:$C,MONTH('Fluxo de Caixa'!F$5),'Entradas e Saídas'!$D:$D,YEAR('Fluxo de Caixa'!F$5),'Entradas e Saídas'!$F:$F,'Fluxo de Caixa'!$B13) -> 482 | G13: =SUMIFS('Entradas e Saídas'!$G:$G,'Entradas e Saídas'!$E:$E,"Vendas",'Entradas e Saídas'!$C:$C,MONTH('Fluxo de Caixa'!G$5),'Entradas e Saídas'!$D:$D,YEAR('Fluxo de Caixa'!G$5),'Entradas e Saídas'!$F:$F,'Fluxo de Caixa'!$B13) -> 98 | H13: =SUMIFS('Entradas e Saídas'!$G:$G,'Entradas e Saídas'!$E:$E,"Vendas",'Entradas e Saídas'!$C:$C,MONTH('Fluxo de Caixa'!H$5),'Entradas e Saídas'!$D:$D,YEAR('Fluxo de Caixa'!H$5),'Entradas e Saídas'!$F:$F,'Fluxo de Caixa'!$B13) -> 320.05 | I13: =SUMIFS('Entradas e Saídas'!$G:$G,'Entradas e Saídas'!$E:$E,"Vendas",'Entradas e Saídas'!$C:$C,MONTH('Fluxo de Caixa'!I$5),'Entradas e Saídas'!$D:$D,YEAR('Fluxo de Caixa'!I$5),'Entradas e Saídas'!$F:$F,'Fluxo de Caixa'!$B13) -> 558.5 | J13: =SUMIFS('Entradas e Saídas'!$G:$G,'Entradas e Saídas'!$E:$E,"Vendas",'Entradas e Saídas'!$C:$C,MONTH('Fluxo de Caixa'!J$5),'Entradas e Saídas'!$D:$D,YEAR('Fluxo de Caixa'!J$5),'Entradas e Saídas'!$F:$F,'Fluxo de Caixa'!$B13) -> 321.5 | ... AS13: =SUMIFS('Entradas e Saídas'!$G:$G,'Entradas e Saídas'!$E:$E,"Vendas",'Entradas e Saídas'!$C:$C,MONTH('Fluxo de Caixa'!AS$5),'Entradas e Saídas'!$D:$D,YEAR('Fluxo de Caixa'!AS$5),'Entradas e Saídas'!$F:$F,'Fluxo de Caixa'!$B13) -> 0
B14: =IF(Produtos!B6="","-",Produtos!B6) -> Brigadeiro Coco | C14: =SUMIFS('Entradas e Saídas'!$G:$G,'Entradas e Saídas'!$E:$E,"Vendas",'Entradas e Saídas'!$C:$C,MONTH('Fluxo de Caixa'!C$5),'Entradas e Saídas'!$D:$D,YEAR('Fluxo de Caixa'!C$5),'Entradas e Saídas'!$F:$F,'Fluxo de Caixa'!$B14) -> 0 | D14: =SUMIFS('Entradas e Saídas'!$G:$G,'Entradas e Saídas'!$E:$E,"Vendas",'Entradas e Saídas'!$C:$C,MONTH('Fluxo de Caixa'!D$5),'Entradas e Saídas'!$D:$D,YEAR('Fluxo de Caixa'!D$5),'Entradas e Saídas'!$F:$F,'Fluxo de Caixa'!$B14) -> 0 | E14: =SUMIFS('Entradas e Saídas'!$G:$G,'Entradas e Saídas'!$E:$E,"Vendas",'Entradas e Saídas'!$C:$C,MONTH('Fluxo de Caixa'!E$5),'Entradas e Saídas'!$D:$D,YEAR('Fluxo de Caixa'!E$5),'Entradas e Saídas'!$F:$F,'Fluxo de Caixa'!$B14) -> 48 | F14: =SUMIFS('Entradas e Saídas'!$G:$G,'Entradas e Saídas'!$E:$E,"Vendas",'Entradas e Saídas'!$C:$C,MONTH('Fluxo de Caixa'!F$5),'Entradas e Saídas'!$D:$D,YEAR('Fluxo de Caixa'!F$5),'Entradas e Saídas'!$F:$F,'Fluxo de Caixa'!$B14) -> 58 | G14: =SUMIFS('Entradas e Saídas'!$G:$G,'Entradas e Saídas'!$E:$E,"Vendas",'Entradas e Saídas'!$C:$C,MONTH('Fluxo de Caixa'!G$5),'Entradas e Saídas'!$D:$D,YEAR('Fluxo de Caixa'!G$5),'Entradas e Saídas'!$F:$F,'Fluxo de Caixa'!$B14) -> 82 | H14: =SUMIFS('Entradas e Saídas'!$G:$G,'Entradas e Saídas'!$E:$E,"Vendas",'Entradas e Saídas'!$C:$C,MONTH('Fluxo de Caixa'!H$5),'Entradas e Saídas'!$D:$D,YEAR('Fluxo de Caixa'!H$5),'Entradas e Saídas'!$F:$F,'Fluxo de Caixa'!$B14) -> 137 | I14: =SUMIFS('Entradas e Saídas'!$G:$G,'Entradas e Saídas'!$E:$E,"Vendas",'Entradas e Saídas'!$C:$C,MONTH('Fluxo de Caixa'!I$5),'Entradas e Saídas'!$D:$D,YEAR('Fluxo de Caixa'!I$5),'Entradas e Saídas'!$F:$F,'Fluxo de Caixa'!$B14) -> 62 | J14: =SUMIFS('Entradas e Saídas'!$G:$G,'Entradas e Saídas'!$E:$E,"Vendas",'Entradas e Saídas'!$C:$C,MONTH('Fluxo de Caixa'!J$5),'Entradas e Saídas'!$D:$D,YEAR('Fluxo de Caixa'!J$5),'Entradas e Saídas'!$F:$F,'Fluxo de Caixa'!$B14) -> 98 | ... AS14: =SUMIFS('Entradas e Saídas'!$G:$G,'Entradas e Saídas'!$E:$E,"Vendas",'Entradas e Saídas'!$C:$C,MONTH('Fluxo de Caixa'!AS$5),'Entradas e Saídas'!$D:$D,YEAR('Fluxo de Caixa'!AS$5),'Entradas e Saídas'!$F:$F,'Fluxo de Caixa'!$B14) -> 0
B15: =IF(Produtos!B7="","-",Produtos!B7) -> Brigadeiro Café | C15: =SUMIFS('Entradas e Saídas'!$G:$G,'Entradas e Saídas'!$E:$E,"Vendas",'Entradas e Saídas'!$C:$C,MONTH('Fluxo de Caixa'!C$5),'Entradas e Saídas'!$D:$D,YEAR('Fluxo de Caixa'!C$5),'Entradas e Saídas'!$F:$F,'Fluxo de Caixa'!$B15) -> 0 | D15: =SUMIFS('Entradas e Saídas'!$G:$G,'Entradas e Saídas'!$E:$E,"Vendas",'Entradas e Saídas'!$C:$C,MONTH('Fluxo de Caixa'!D$5),'Entradas e Saídas'!$D:$D,YEAR('Fluxo de Caixa'!D$5),'Entradas e Saídas'!$F:$F,'Fluxo de Caixa'!$B15) -> 0 | E15: =SUMIFS('Entradas e Saídas'!$G:$G,'Entradas e Saídas'!$E:$E,"Vendas",'Entradas e Saídas'!$C:$C,MONTH('Fluxo de Caixa'!E$5),'Entradas e Saídas'!$D:$D,YEAR('Fluxo de Caixa'!E$5),'Entradas e Saídas'!$F:$F,'Fluxo de Caixa'!$B15) -> 0 | F15: =SUMIFS('Entradas e Saídas'!$G:$G,'Entradas e Saídas'!$E:$E,"Vendas",'Entradas e Saídas'!$C:$C,MONTH('Fluxo de Caixa'!F$5),'Entradas e Saídas'!$D:$D,YEAR('Fluxo de Caixa'!F$5),'Entradas e Saídas'!$F:$F,'Fluxo de Caixa'!$B15) -> 0 | G15: =SUMIFS('Entradas e Saídas'!$G:$G,'Entradas e Saídas'!$E:$E,"Vendas",'Entradas e Saídas'!$C:$C,MONTH('Fluxo de Caixa'!G$5),'Entradas e Saídas'!$D:$D,YEAR('Fluxo de Caixa'!G$5),'Entradas e Saídas'!$F:$F,'Fluxo de Caixa'!$B15) -> 0 | H15: =SUMIFS('Entradas e Saídas'!$G:$G,'Entradas e Saídas'!$E:$E,"Vendas",'Entradas e Saídas'!$C:$C,MONTH('Fluxo de Caixa'!H$5),'Entradas e Saídas'!$D:$D,YEAR('Fluxo de Caixa'!H$5),'Entradas e Saídas'!$F:$F,'Fluxo de Caixa'!$B15) -> 0 | I15: =SUMIFS('Entradas e Saídas'!$G:$G,'Entradas e Saídas'!$E:$E,"Vendas",'Entradas e Saídas'!$C:$C,MONTH('Fluxo de Caixa'!I$5),'Entradas e Saídas'!$D:$D,YEAR('Fluxo de Caixa'!I$5),'Entradas e Saídas'!$F:$F,'Fluxo de Caixa'!$B15) -> 0 | J15: =SUMIFS('Entradas e Saídas'!$G:$G,'Entradas e Saídas'!$E:$E,"Vendas",'Entradas e Saídas'!$C:$C,MONTH('Fluxo de Caixa'!J$5),'Entradas e Saídas'!$D:$D,YEAR('Fluxo de Caixa'!J$5),'Entradas e Saídas'!$F:$F,'Fluxo de Caixa'!$B15) -> 0 | ... AS15: =SUMIFS('Entradas e Saídas'!$G:$G,'Entradas e Saídas'!$E:$E,"Vendas",'Entradas e Saídas'!$C:$C,MONTH('Fluxo de Caixa'!AS$5),'Entradas e Saídas'!$D:$D,YEAR('Fluxo de Caixa'!AS$5),'Entradas e Saídas'!$F:$F,'Fluxo de Caixa'!$B15) -> 0
B16: =IF(Produtos!B8="","-",Produtos!B8) -> Brigadeiro Nozes | C16: =SUMIFS('Entradas e Saídas'!$G:$G,'Entradas e Saídas'!$E:$E,"Vendas",'Entradas e Saídas'!$C:$C,MONTH('Fluxo de Caixa'!C$5),'Entradas e Saídas'!$D:$D,YEAR('Fluxo de Caixa'!C$5),'Entradas e Saídas'!$F:$F,'Fluxo de Caixa'!$B16) -> 0 | D16: =SUMIFS('Entradas e Saídas'!$G:$G,'Entradas e Saídas'!$E:$E,"Vendas",'Entradas e Saídas'!$C:$C,MONTH('Fluxo de Caixa'!D$5),'Entradas e Saídas'!$D:$D,YEAR('Fluxo de Caixa'!D$5),'Entradas e Saídas'!$F:$F,'Fluxo de Caixa'!$B16) -> 0 | E16: =SUMIFS('Entradas e Saídas'!$G:$G,'Entradas e Saídas'!$E:$E,"Vendas",'Entradas e Saídas'!$C:$C,MONTH('Fluxo de Caixa'!E$5),'Entradas e Saídas'!$D:$D,YEAR('Fluxo de Caixa'!E$5),'Entradas e Saídas'!$F:$F,'Fluxo de Caixa'!$B16) -> 0 | F16: =SUMIFS('Entradas e Saídas'!$G:$G,'Entradas e Saídas'!$E:$E,"Vendas",'Entradas e Saídas'!$C:$C,MONTH('Fluxo de Caixa'!F$5),'Entradas e Saídas'!$D:$D,YEAR('Fluxo de Caixa'!F$5),'Entradas e Saídas'!$F:$F,'Fluxo de Caixa'!$B16) -> 0 | G16: =SUMIFS('Entradas e Saídas'!$G:$G,'Entradas e Saídas'!$E:$E,"Vendas",'Entradas e Saídas'!$C:$C,MONTH('Fluxo de Caixa'!G$5),'Entradas e Saídas'!$D:$D,YEAR('Fluxo de Caixa'!G$5),'Entradas e Saídas'!$F:$F,'Fluxo de Caixa'!$B16) -> 0 | H16: =SUMIFS('Entradas e Saídas'!$G:$G,'Entradas e Saídas'!$E:$E,"Vendas",'Entradas e Saídas'!$C:$C,MONTH('Fluxo de Caixa'!H$5),'Entradas e Saídas'!$D:$D,YEAR('Fluxo de Caixa'!H$5),'Entradas e Saídas'!$F:$F,'Fluxo de Caixa'!$B16) -> 0 | I16: =SUMIFS('Entradas e Saídas'!$G:$G,'Entradas e Saídas'!$E:$E,"Vendas",'Entradas e Saídas'!$C:$C,MONTH('Fluxo de Caixa'!I$5),'Entradas e Saídas'!$D:$D,YEAR('Fluxo de Caixa'!I$5),'Entradas e Saídas'!$F:$F,'Fluxo de Caixa'!$B16) -> 0 | J16: =SUMIFS('Entradas e Saídas'!$G:$G,'Entradas e Saídas'!$E:$E,"Vendas",'Entradas e Saídas'!$C:$C,MONTH('Fluxo de Caixa'!J$5),'Entradas e Saídas'!$D:$D,YEAR('Fluxo de Caixa'!J$5),'Entradas e Saídas'!$F:$F,'Fluxo de Caixa'!$B16) -> 0 | ... AS16: =SUMIFS('Entradas e Saídas'!$G:$G,'Entradas e Saídas'!$E:$E,"Vendas",'Entradas e Saídas'!$C:$C,MONTH('Fluxo de Caixa'!AS$5),'Entradas e Saídas'!$D:$D,YEAR('Fluxo de Caixa'!AS$5),'Entradas e Saídas'!$F:$F,'Fluxo de Caixa'!$B16) -> 0
B17: =IF(Produtos!B9="","-",Produtos!B9) -> Brigadeiro Churros | C17: =SUMIFS('Entradas e Saídas'!$G:$G,'Entradas e Saídas'!$E:$E,"Vendas",'Entradas e Saídas'!$C:$C,MONTH('Fluxo de Caixa'!C$5),'Entradas e Saídas'!$D:$D,YEAR('Fluxo de Caixa'!C$5),'Entradas e Saídas'!$F:$F,'Fluxo de Caixa'!$B17) -> 0 | D17: =SUMIFS('Entradas e Saídas'!$G:$G,'Entradas e Saídas'!$E:$E,"Vendas",'Entradas e Saídas'!$C:$C,MONTH('Fluxo de Caixa'!D$5),'Entradas e Saídas'!$D:$D,YEAR('Fluxo de Caixa'!D$5),'Entradas e Saídas'!$F:$F,'Fluxo de Caixa'!$B17) -> 118 | E17: =SUMIFS('Entradas e Saídas'!$G:$G,'Entradas e Saídas'!$E:$E,"Vendas",'Entradas e Saídas'!$C:$C,MONTH('Fluxo de Caixa'!E$5),'Entradas e Saídas'!$D:$D,YEAR('Fluxo de Caixa'!E$5),'Entradas e Saídas'!$F:$F,'Fluxo de Caixa'!$B17) -> 22 | F17: =SUMIFS('Entradas e Saídas'!$G:$G,'Entradas e Saídas'!$E:$E,"Vendas",'Entradas e Saídas'!$C:$C,MONTH('Fluxo de Caixa'!F$5),'Entradas e Saídas'!$D:$D,YEAR('Fluxo de Caixa'!F$5),'Entradas e Saídas'!$F:$F,'Fluxo de Caixa'!$B17) -> 192 | G17: =SUMIFS('Entradas e Saídas'!$G:$G,'Entradas e Saídas'!$E:$E,"Vendas",'Entradas e Saídas'!$C:$C,MONTH('Fluxo de Caixa'!G$5),'Entradas e Saídas'!$D:$D,YEAR('Fluxo de Caixa'!G$5),'Entradas e Saídas'!$F:$F,'Fluxo de Caixa'!$B17) -> 124 | H17: =SUMIFS('Entradas e Saídas'!$G:$G,'Entradas e Saídas'!$E:$E,"Vendas",'Entradas e Saídas'!$C:$C,MONTH('Fluxo de Caixa'!H$5),'Entradas e Saídas'!$D:$D,YEAR('Fluxo de Caixa'!H$5),'Entradas e Saídas'!$F:$F,'Fluxo de Caixa'!$B17) -> 237.25 | I17: =SUMIFS('Entradas e Saídas'!$G:$G,'Entradas e Saídas'!$E:$E,"Vendas",'Entradas e Saídas'!$C:$C,MONTH('Fluxo de Caixa'!I$5),'Entradas e Saídas'!$D:$D,YEAR('Fluxo de Caixa'!I$5),'Entradas e Saídas'!$F:$F,'Fluxo de Caixa'!$B17) -> 95.5 | J17: =SUMIFS('Entradas e Saídas'!$G:$G,'Entradas e Saídas'!$E:$E,"Vendas",'Entradas e Saídas'!$C:$C,MONTH('Fluxo de Caixa'!J$5),'Entradas e Saídas'!$D:$D,YEAR('Fluxo de Caixa'!J$5),'Entradas e Saídas'!$F:$F,'Fluxo de Caixa'!$B17) -> 176 | ... AS17: =SUMIFS('Entradas e Saídas'!$G:$G,'Entradas e Saídas'!$E:$E,"Vendas",'Entradas e Saídas'!$C:$C,MONTH('Fluxo de Caixa'!AS$5),'Entradas e Saídas'!$D:$D,YEAR('Fluxo de Caixa'!AS$5),'Entradas e Saídas'!$F:$F,'Fluxo de Caixa'!$B17) -> 0
B18: =IF(Produtos!B10="","-",Produtos!B10) -> Brigadeiro Paçoca | C18: =SUMIFS('Entradas e Saídas'!$G:$G,'Entradas e Saídas'!$E:$E,"Vendas",'Entradas e Saídas'!$C:$C,MONTH('Fluxo de Caixa'!C$5),'Entradas e Saídas'!$D:$D,YEAR('Fluxo de Caixa'!C$5),'Entradas e Saídas'!$F:$F,'Fluxo de Caixa'!$B18) -> 0 | D18: =SUMIFS('Entradas e Saídas'!$G:$G,'Entradas e Saídas'!$E:$E,"Vendas",'Entradas e Saídas'!$C:$C,MONTH('Fluxo de Caixa'!D$5),'Entradas e Saídas'!$D:$D,YEAR('Fluxo de Caixa'!D$5),'Entradas e Saídas'!$F:$F,'Fluxo de Caixa'!$B18) -> 0 | E18: =SUMIFS('Entradas e Saídas'!$G:$G,'Entradas e Saídas'!$E:$E,"Vendas",'Entradas e Saídas'!$C:$C,MONTH('Fluxo de Caixa'!E$5),'Entradas e Saídas'!$D:$D,YEAR('Fluxo de Caixa'!E$5),'Entradas e Saídas'!$F:$F,'Fluxo de Caixa'!$B18) -> 0 | F18: =SUMIFS('Entradas e Saídas'!$G:$G,'Entradas e Saídas'!$E:$E,"Vendas",'Entradas e Saídas'!$C:$C,MONTH('Fluxo de Caixa'!F$5),'Entradas e Saídas'!$D:$D,YEAR('Fluxo de Caixa'!F$5),'Entradas e Saídas'!$F:$F,'Fluxo de Caixa'!$B18) -> 16 | G18: =SUMIFS('Entradas e Saídas'!$G:$G,'Entradas e Saídas'!$E:$E,"Vendas",'Entradas e Saídas'!$C:$C,MONTH('Fluxo de Caixa'!G$5),'Entradas e Saídas'!$D:$D,YEAR('Fluxo de Caixa'!G$5),'Entradas e Saídas'!$F:$F,'Fluxo de Caixa'!$B18) -> 0 | H18: =SUMIFS('Entradas e Saídas'!$G:$G,'Entradas e Saídas'!$E:$E,"Vendas",'Entradas e Saídas'!$C:$C,MONTH('Fluxo de Caixa'!H$5),'Entradas e Saídas'!$D:$D,YEAR('Fluxo de Caixa'!H$5),'Entradas e Saídas'!$F:$F,'Fluxo de Caixa'!$B18) -> 29.5 | I18: =SUMIFS('Entradas e Saídas'!$G:$G,'Entradas e Saídas'!$E:$E,"Vendas",'Entradas e Saídas'!$C:$C,MONTH('Fluxo de Caixa'!I$5),'Entradas e Saídas'!$D:$D,YEAR('Fluxo de Caixa'!I$5),'Entradas e Saídas'!$F:$F,'Fluxo de Caixa'!$B18) -> 10 | J18: =SUMIFS('Entradas e Saídas'!$G:$G,'Entradas e Saídas'!$E:$E,"Vendas",'Entradas e Saídas'!$C:$C,MONTH('Fluxo de Caixa'!J$5),'Entradas e Saídas'!$D:$D,YEAR('Fluxo de Caixa'!J$5),'Entradas e Saídas'!$F:$F,'Fluxo de Caixa'!$B18) -> 12 | ... AS18: =SUMIFS('Entradas e Saídas'!$G:$G,'Entradas e Saídas'!$E:$E,"Vendas",'Entradas e Saídas'!$C:$C,MONTH('Fluxo de Caixa'!AS$5),'Entradas e Saídas'!$D:$D,YEAR('Fluxo de Caixa'!AS$5),'Entradas e Saídas'!$F:$F,'Fluxo de Caixa'!$B18) -> 0
B19: =IF(Produtos!B11="","-",Produtos!B11) -> Brigadeiro Limão | C19: =SUMIFS('Entradas e Saídas'!$G:$G,'Entradas e Saídas'!$E:$E,"Vendas",'Entradas e Saídas'!$C:$C,MONTH('Fluxo de Caixa'!C$5),'Entradas e Saídas'!$D:$D,YEAR('Fluxo de Caixa'!C$5),'Entradas e Saídas'!$F:$F,'Fluxo de Caixa'!$B19) -> 0 | D19: =SUMIFS('Entradas e Saídas'!$G:$G,'Entradas e Saídas'!$E:$E,"Vendas",'Entradas e Saídas'!$C:$C,MONTH('Fluxo de Caixa'!D$5),'Entradas e Saídas'!$D:$D,YEAR('Fluxo de Caixa'!D$5),'Entradas e Saídas'!$F:$F,'Fluxo de Caixa'!$B19) -> 0 | E19: =SUMIFS('Entradas e Saídas'!$G:$G,'Entradas e Saídas'!$E:$E,"Vendas",'Entradas e Saídas'!$C:$C,MONTH('Fluxo de Caixa'!E$5),'Entradas e Saídas'!$D:$D,YEAR('Fluxo de Caixa'!E$5),'Entradas e Saídas'!$F:$F,'Fluxo de Caixa'!$B19) -> 0 | F19: =SUMIFS('Entradas e Saídas'!$G:$G,'Entradas e Saídas'!$E:$E,"Vendas",'Entradas e Saídas'!$C:$C,MONTH('Fluxo de Caixa'!F$5),'Entradas e Saídas'!$D:$D,YEAR('Fluxo de Caixa'!F$5),'Entradas e Saídas'!$F:$F,'Fluxo de Caixa'!$B19) -> 0 | G19: =SUMIFS('Entradas e Saídas'!$G:$G,'Entradas e Saídas'!$E:$E,"Vendas",'Entradas e Saídas'!$C:$C,MONTH('Fluxo de Caixa'!G$5),'Entradas e Saídas'!$D:$D,YEAR('Fluxo de Caixa'!G$5),'Entradas e Saídas'!$F:$F,'Fluxo de Caixa'!$B19) -> 0 | H19: =SUMIFS('Entradas e Saídas'!$G:$G,'Entradas e Saídas'!$E:$E,"Vendas",'Entradas e Saídas'!$C:$C,MONTH('Fluxo de Caixa'!H$5),'Entradas e Saídas'!$D:$D,YEAR('Fluxo de Caixa'!H$5),'Entradas e Saídas'!$F:$F,'Fluxo de Caixa'!$B19) -> 128 | I19: =SUMIFS('Entradas e Saídas'!$G:$G,'Entradas e Saídas'!$E:$E,"Vendas",'Entradas e Saídas'!$C:$C,MONTH('Fluxo de Caixa'!I$5),'Entradas e Saídas'!$D:$D,YEAR('Fluxo de Caixa'!I$5),'Entradas e Saídas'!$F:$F,'Fluxo de Caixa'!$B19) -> 83.5 | J19: =SUMIFS('Entradas e Saídas'!$G:$G,'Entradas e Saídas'!$E:$E,"Vendas",'Entradas e Saídas'!$C:$C,MONTH('Fluxo de Caixa'!J$5),'Entradas e Saídas'!$D:$D,YEAR('Fluxo de Caixa'!J$5),'Entradas e Saídas'!$F:$F,'Fluxo de Caixa'!$B19) -> 128.5 | ... AS19: =SUMIFS('Entradas e Saídas'!$G:$G,'Entradas e Saídas'!$E:$E,"Vendas",'Entradas e Saídas'!$C:$C,MONTH('Fluxo de Caixa'!AS$5),'Entradas e Saídas'!$D:$D,YEAR('Fluxo de Caixa'!AS$5),'Entradas e Saídas'!$F:$F,'Fluxo de Caixa'!$B19) -> 0
B20: =IF(Produtos!B12="","-",Produtos!B12) -> - | C20: =SUMIFS('Entradas e Saídas'!$G:$G,'Entradas e Saídas'!$E:$E,"Vendas",'Entradas e Saídas'!$C:$C,MONTH('Fluxo de Caixa'!C$5),'Entradas e Saídas'!$D:$D,YEAR('Fluxo de Caixa'!C$5),'Entradas e Saídas'!$F:$F,'Fluxo de Caixa'!$B20) -> 0 | D20: =SUMIFS('Entradas e Saídas'!$G:$G,'Entradas e Saídas'!$E:$E,"Vendas",'Entradas e Saídas'!$C:$C,MONTH('Fluxo de Caixa'!D$5),'Entradas e Saídas'!$D:$D,YEAR('Fluxo de Caixa'!D$5),'Entradas e Saídas'!$F:$F,'Fluxo de Caixa'!$B20) -> 0 | E20: =SUMIFS('Entradas e Saídas'!$G:$G,'Entradas e Saídas'!$E:$E,"Vendas",'Entradas e Saídas'!$C:$C,MONTH('Fluxo de Caixa'!E$5),'Entradas e Saídas'!$D:$D,YEAR('Fluxo de Caixa'!E$5),'Entradas e Saídas'!$F:$F,'Fluxo de Caixa'!$B20) -> 0 | F20: =SUMIFS('Entradas e Saídas'!$G:$G,'Entradas e Saídas'!$E:$E,"Vendas",'Entradas e Saídas'!$C:$C,MONTH('Fluxo de Caixa'!F$5),'Entradas e Saídas'!$D:$D,YEAR('Fluxo de Caixa'!F$5),'Entradas e Saídas'!$F:$F,'Fluxo de Caixa'!$B20) -> 0 | G20: =SUMIFS('Entradas e Saídas'!$G:$G,'Entradas e Saídas'!$E:$E,"Vendas",'Entradas e Saídas'!$C:$C,MONTH('Fluxo de Caixa'!G$5),'Entradas e Saídas'!$D:$D,YEAR('Fluxo de Caixa'!G$5),'Entradas e Saídas'!$F:$F,'Fluxo de Caixa'!$B20) -> 0 | H20: =SUMIFS('Entradas e Saídas'!$G:$G,'Entradas e Saídas'!$E:$E,"Vendas",'Entradas e Saídas'!$C:$C,MONTH('Fluxo de Caixa'!H$5),'Entradas e Saídas'!$D:$D,YEAR('Fluxo de Caixa'!H$5),'Entradas e Saídas'!$F:$F,'Fluxo de Caixa'!$B20) -> 0 | I20: =SUMIFS('Entradas e Saídas'!$G:$G,'Entradas e Saídas'!$E:$E,"Vendas",'Entradas e Saídas'!$C:$C,MONTH('Fluxo de Caixa'!I$5),'Entradas e Saídas'!$D:$D,YEAR('Fluxo de Caixa'!I$5),'Entradas e Saídas'!$F:$F,'Fluxo de Caixa'!$B20) -> 0 | J20: =SUMIFS('Entradas e Saídas'!$G:$G,'Entradas e Saídas'!$E:$E,"Vendas",'Entradas e Saídas'!$C:$C,MONTH('Fluxo de Caixa'!J$5),'Entradas e Saídas'!$D:$D,YEAR('Fluxo de Caixa'!J$5),'Entradas e Saídas'!$F:$F,'Fluxo de Caixa'!$B20) -> 0 | ... AS20: =SUMIFS('Entradas e Saídas'!$G:$G,'Entradas e Saídas'!$E:$E,"Vendas",'Entradas e Saídas'!$C:$C,MONTH('Fluxo de Caixa'!AS$5),'Entradas e Saídas'!$D:$D,YEAR('Fluxo de Caixa'!AS$5),'Entradas e Saídas'!$F:$F,'Fluxo de Caixa'!$B20) -> 0
B21: =IF(Produtos!B13="","-",Produtos!B13) -> - | C21: =SUMIFS('Entradas e Saídas'!$G:$G,'Entradas e Saídas'!$E:$E,"Vendas",'Entradas e Saídas'!$C:$C,MONTH('Fluxo de Caixa'!C$5),'Entradas e Saídas'!$D:$D,YEAR('Fluxo de Caixa'!C$5),'Entradas e Saídas'!$F:$F,'Fluxo de Caixa'!$B21) -> 0 | D21: =SUMIFS('Entradas e Saídas'!$G:$G,'Entradas e Saídas'!$E:$E,"Vendas",'Entradas e Saídas'!$C:$C,MONTH('Fluxo de Caixa'!D$5),'Entradas e Saídas'!$D:$D,YEAR('Fluxo de Caixa'!D$5),'Entradas e Saídas'!$F:$F,'Fluxo de Caixa'!$B21) -> 0 | E21: =SUMIFS('Entradas e Saídas'!$G:$G,'Entradas e Saídas'!$E:$E,"Vendas",'Entradas e Saídas'!$C:$C,MONTH('Fluxo de Caixa'!E$5),'Entradas e Saídas'!$D:$D,YEAR('Fluxo de Caixa'!E$5),'Entradas e Saídas'!$F:$F,'Fluxo de Caixa'!$B21) -> 0 | F21: =SUMIFS('Entradas e Saídas'!$G:$G,'Entradas e Saídas'!$E:$E,"Vendas",'Entradas e Saídas'!$C:$C,MONTH('Fluxo de Caixa'!F$5),'Entradas e Saídas'!$D:$D,YEAR('Fluxo de Caixa'!F$5),'Entradas e Saídas'!$F:$F,'Fluxo de Caixa'!$B21) -> 0 | G21: =SUMIFS('Entradas e Saídas'!$G:$G,'Entradas e Saídas'!$E:$E,"Vendas",'Entradas e Saídas'!$C:$C,MONTH('Fluxo de Caixa'!G$5),'Entradas e Saídas'!$D:$D,YEAR('Fluxo de Caixa'!G$5),'Entradas e Saídas'!$F:$F,'Fluxo de Caixa'!$B21) -> 0 | H21: =SUMIFS('Entradas e Saídas'!$G:$G,'Entradas e Saídas'!$E:$E,"Vendas",'Entradas e Saídas'!$C:$C,MONTH('Fluxo de Caixa'!H$5),'Entradas e Saídas'!$D:$D,YEAR('Fluxo de Caixa'!H$5),'Entradas e Saídas'!$F:$F,'Fluxo de Caixa'!$B21) -> 0 | I21: =SUMIFS('Entradas e Saídas'!$G:$G,'Entradas e Saídas'!$E:$E,"Vendas",'Entradas e Saídas'!$C:$C,MONTH('Fluxo de Caixa'!I$5),'Entradas e Saídas'!$D:$D,YEAR('Fluxo de Caixa'!I$5),'Entradas e Saídas'!$F:$F,'Fluxo de Caixa'!$B21) -> 0 | J21: =SUMIFS('Entradas e Saídas'!$G:$G,'Entradas e Saídas'!$E:$E,"Vendas",'Entradas e Saídas'!$C:$C,MONTH('Fluxo de Caixa'!J$5),'Entradas e Saídas'!$D:$D,YEAR('Fluxo de Caixa'!J$5),'Entradas e Saídas'!$F:$F,'Fluxo de Caixa'!$B21) -> 0 | ... AS21: =SUMIFS('Entradas e Saídas'!$G:$G,'Entradas e Saídas'!$E:$E,"Vendas",'Entradas e Saídas'!$C:$C,MONTH('Fluxo de Caixa'!AS$5),'Entradas e Saídas'!$D:$D,YEAR('Fluxo de Caixa'!AS$5),'Entradas e Saídas'!$F:$F,'Fluxo de Caixa'!$B21) -> 0
