Workbook
Name SegmentaçãodeDados_Mês_Vencimento: #N/A

Sheet Cadastros
A1: Categorias de Contas | D1: Clientes | E1: Telefone | F1: E-mai
A2: Matrícula Ens Fundamental | D2: Adalberto Torres | E2: 11111111111 | F2: torres@email.com
A3: Matrícula Ens Médio | D3: Agostinho Carrara | E3: 22222222222 | F3: carrara@email.com
A4: Material Escolar | D4: Celina Justo | E4: 33333333333 | F4: justo@email.com
A5: Mensalidade Ens Fundamental | D5: Claire Underwood | E5: 44444444444 | F5: underwood@email.com
A6: Mensalidade Ens Médio | D6: Dona Benta | E6: 55555555555 | F6: benta@email.com
A7: Atividades Extra Muros | D7: Dwight Schrute | E7: 66666666666 | F7: schrute@email.com
D8: Felipe Duarte | E8: 77777777777 | F8: duarte@email.com
D9: Marco Santos | E9: 88888888888 | F9: santos@email.com
D10: Mariana Rosa | E10: 99999999999 | F10: rosa@email.com
D11: Michael Scott | E11: 12121212121 | F11: scott@email.com
D12: Samantha Alves | E12: 23232323232 | F12: alves@email.com
D13: Suzane Barbosa | E13: 34343434343 | F13: barbosa@email.com
D14: Walter White | E14: 45454545454 | F14: white@email.com
D15: Zoe Barnes | E15: 56565656565 | F15: barnes@email.com

Sheet Registro
A1: ID | B1: Data Emissão | C1: Data Vencimento | D1: Mês Vencimento | E1: Categoria | F1: Cliente | G1: Valor | H1: Data Pagamento | I1: Forma Pgto | J1: Recebido | K1: Pendente | L1: Status
A2: =ROW()-1 -> 1 | B2: 44933 | C2: =Tabela3[[#This Row],[Data Emissão]]+10 -> 44943 | D2: =TEXT(Tabela3[[#This Row],[Data Vencimento]],"mmm") -> jan | E2: Matrícula Ens Fundamental | F2: Claire Underwood | G2: 349 | H2: 44946 | I2: Cheque | J2: 366 | K2: =IF(Tabela3[[#This Row],[Recebido]]<Tabela3[[#This Row],[Valor]],Tabela3[[#This Row],[Valor]]-Tabela3[[#This Row],[Recebido]],0) -> 0 | L2: =IF(Tabela3[[#This Row],[Data Pagamento]]<>"",IF(Tabela3[[#This Row],[Data Pagamento]]>Tabela3[[#This Row],[Data Vencimento]],"Pago com Atraso","Pago no Prazo"),IF(Tabela3[[#This Row],[Data Vencimento]]<TODAY(),"Atrasado","Pendente")) -> Pago com Atraso
A3: =ROW()-1 -> 2 | B3: 44940 | C3: =Tabela3[[#This Row],[Data Emissão]]+10 -> 44950 | D3: =TEXT(Tabela3[[#This Row],[Data Vencimento]],"mmm") -> jan | E3: Matrícula Ens Fundamental | F3: Adalberto Torres | G3: 342 | H3: 44952 | I3: PIX | J3: 382 | K3: =IF(Tabela3[[#This Row],[Recebido]]<Tabela3[[#This Row],[Valor]],Tabela3[[#This Row],[Valor]]-Tabela3[[#This Row],[Recebido]],0) -> 0 | L3: =IF(Tabela3[[#This Row],[Data Pagamento]]<>"",IF(Tabela3[[#This Row],[Data Pagamento]]>Tabela3[[#This Row],[Data Vencimento]],"Pago com Atraso","Pago no Prazo"),IF(Tabela3[[#This Row],[Data Vencimento]]<TODAY(),"Atrasado","Pendente")) -> Pago com Atraso
A4: =ROW()-1 -> 3 | B4: 44944 | C4: =Tabela3[[#This Row],[Data Emissão]]+10 -> 44954 | D4: =TEXT(Tabela3[[#This Row],[Data Vencimento]],"mmm") -> jan | E4: Atividades Extra Muros | F4: Dwight Schrute | G4: 221 | H4: 44953 | I4: Cheque | J4: 213 | K4: =IF(Tabela3[[#This Row],[Recebido]]<Tabela3[[#This Row],[Valor]],Tabela3[[#This Row],[Valor]]-Tabela3[[#This Row],[Recebido]],0) -> 8 | L4: =IF(Tabela3[[#This Row],[Data Pagamento]]<>"",IF(Tabela3[[#This Row],[Data Pagamento]]>Tabela3[[#This Row],[Data Vencimento]],"Pago com Atraso","Pago no Prazo"),IF(Tabela3[[#This Row],[Data Vencimento]]<TODAY(),"Atrasado","Pendente")) -> Pago no Prazo
A5: =ROW()-1 -> 4 | B5: 44945 | C5: =Tabela3[[#This Row],[Data Emissão]]+10 -> 44955 | D5: =TEXT(Tabela3[[#This Row],[Data Vencimento]],"mmm") -> jan | E5: Mensalidade Ens Médio | F5: Walter White | G5: 110 | H5: 44961 | I5: Dinheiro | J5: 139 | K5: =IF(Tabela3[[#This Row],[Recebido]]<Tabela3[[#This Row],[Valor]],Tabela3[[#This Row],[Valor]]-Tabela3[[#This Row],[Recebido]],0) -> 0 | L5: =IF(Tabela3[[#This Row],[Data Pagamento]]<>"",IF(Tabela3[[#This Row],[Data Pagamento]]>Tabela3[[#This Row],[Data Vencimento]],"Pago com Atraso","Pago no Prazo"),IF(Tabela3[[#This Row],[Data Vencimento]]<TODAY(),"Atrasado","Pendente")) -> Pago com Atraso
A6: =ROW()-1 -> 5 | B6: 44946 | C6: =Tabela3[[#This Row],[Data Emissão]]+10 -> 44956 | D6: =TEXT(Tabela3[[#This Row],[Data Vencimento]],"mmm") -> jan | E6: Matrícula Ens Fundamental | F6: Celina Justo | G6: 285 | H6: 44954 | I6: Dinheiro | J6: 313 | K6: =IF(Tabela3[[#This Row],[Recebido]]<Tabela3[[#This Row],[Valor]],Tabela3[[#This Row],[Valor]]-Tabela3[[#This Row],[Recebido]],0) -> 0 | L6: =IF(Tabela3[[#This Row],[Data Pagamento]]<>"",IF(Tabela3[[#This Row],[Data Pagamento]]>Tabela3[[#This Row],[Data Vencimento]],"Pago com Atraso","Pago no Prazo"),IF(Tabela3[[#This Row],[Data Vencimento]]<TODAY(),"Atrasado","Pendente")) -> Pago no Prazo
A7: =ROW()-1 -> 6 | B7: 44949 | C7: =Tabela3[[#This Row],[Data Emissão]]+10 -> 44959 | D7: =TEXT(Tabela3[[#This Row],[Data Vencimento]],"mmm") -> fev | E7: Matrícula Ens Médio | F7: Claire Underwood | G7: 414 | H7: 44959 | I7: Boleto | J7: 437 | K7: =IF(Tabela3[[#This Row],[Recebido]]<Tabela3[[#This Row],[Valor]],Tabela3[[#This Row],[Valor]]-Tabela3[[#This Row],[Recebido]],0) -> 0 | L7: =IF(Tabela3[[#This Row],[Data Pagamento]]<>"",IF(Tabela3[[#This Row],[Data Pagamento]]>Tabela3[[#This Row],[Data Vencimento]],"Pago com Atraso","Pago no Prazo"),IF(Tabela3[[#This Row],[Data Vencimento]]<TODAY(),"Atrasado","Pendente")) -> Pago no Prazo
A8: =ROW()-1 -> 7 | B8: 44951 | C8: =Tabela3[[#This Row],[Data Emissão]]+10 -> 44961 | D8: =TEXT(Tabela3[[#This Row],[Data Vencimento]],"mmm") -> fev | E8: Matrícula Ens Médio | F8: Agostinho Carrara | G8: 153 | H8: 44967 | I8: Cheque | J8: 115 | K8: =IF(Tabela3[[#This Row],[Recebido]]<Tabela3[[#This Row],[Valor]],Tabela3[[#This Row],[Valor]]-Tabela3[[#This Row],[Recebido]],0) -> 38 | L8: =IF(Tabela3[[#This Row],[Data Pagamento]]<>"",IF(Tabela3[[#This Row],[Data Pagamento]]>Tabela3[[#This Row],[Data Vencimento]],"Pago com Atraso","Pago no Prazo"),IF(Tabela3[[#This Row],[Data Vencimento]]<TODAY(),"Atrasado","Pendente")) -> Pago com Atraso
A9: =ROW()-1 -> 8 | B9: 44952 | C9: =Tabela3[[#This Row],[Data Emissão]]+10 -> 44962 | D9: =TEXT(Tabela3[[#This Row],[Data Vencimento]],"mmm") -> fev | E9: Matrícula Ens Fundamental | F9: Walter White | G9: 200 | H9: 44952 | I9: Dinheiro | J9: 238 | K9: =IF(Tabela3[[#This Row],[Recebido]]<Tabela3[[#This Row],[Valor]],Tabela3[[#This Row],[Valor]]-Tabela3[[#This Row],[Recebido]],0) -> 0 | L9: =IF(Tabela3[[#This Row],[Data Pagamento]]<>"",IF(Tabela3[[#This Row],[Data Pagamento]]>Tabela3[[#This Row],[Data Vencimento]],"Pago com Atraso","Pago no Prazo"),IF(Tabela3[[#This Row],[Data Vencimento]]<TODAY(),"Atrasado","Pendente")) -> Pago no Prazo
A10: =ROW()-1 -> 9 | B10: 44953 | C10: =Tabela3[[#This Row],[Data Emissão]]+10 -> 44963 | D10: =TEXT(Tabela3[[#This Row],[Data Vencimento]],"mmm") -> fev | E10: Matrícula Ens Médio | F10: Marco Santos | G10: 319 | H10: 44969 | I10: Cheque | J10: 302 | K10: =IF(Tabela3[[#This Row],[Recebido]]<Tabela3[[#This Row],[Valor]],Tabela3[[#This Row],[Valor]]-Tabela3[[#This Row],[Recebido]],0) -> 17 | L10: =IF(Tabela3[[#This Row],[Data Pagamento]]<>"",IF(Tabela3[[#This Row],[Data Pagamento]]>Tabela3[[#This Row],[Data Vencimento]],"Pago com Atraso","Pago no Prazo"),IF(Tabela3[[#This Row],[Data Vencimento]]<TODAY(),"Atrasado","Pendente")) -> Pago com Atraso
A11: =ROW()-1 -> 10 | B11: 44954 | C11: =Tabela3[[#This Row],[Data Emissão]]+10 -> 44964 | D11: =TEXT(Tabela3[[#This Row],[Data Vencimento]],"mmm") -> fev | E11: Mensalidade Ens Médio | F11: Felipe Duarte | G11: 392 | H11: 44963 | I11: PIX | J11: 423 | K11: =IF(Tabela3[[#This Row],[Recebido]]<Tabela3[[#This Row],[Valor]],Tabela3[[#This Row],[Valor]]-Tabela3[[#This Row],[Recebido]],0) -> 0 | L11: =IF(Tabela3[[#This Row],[Data Pagamento]]<>"",IF(Tabela3[[#This Row],[Data Pagamento]]>Tabela3[[#This Row],[Data Vencimento]],"Pago com Atraso","Pago no Prazo"),IF(Tabela3[[#This Row],[Data Vencimento]]<TODAY(),"Atrasado","Pendente")) -> Pago no Prazo
A12: =ROW()-1 -> 11 | B12: 44956 | C12: =Tabela3[[#This Row],[Data Emissão]]+10 -> 44966 | D12: =TEXT(Tabela3[[#This Row],[Data Vencimento]],"mmm") -> fev | E12: Mensalidade Ens Fundamental | F12: Zoe Barnes | G12: 111 | H12: 44972 | I12: Boleto | J12: 144 | K12: =IF(Tabela3[[#This Row],[Recebido]]<Tabela3[[#This Row],[Valor]],Tabela3[[#This Row],[Valor]]-Tabela3[[#This Row],[Recebido]],0) -> 0 | L12: =IF(Tabela3[[#This Row],[Data Pagamento]]<>"",IF(Tabela3[[#This Row],[Data Pagamento]]>Tabela3[[#This Row],[Data Vencimento]],"Pago com Atraso","Pago no Prazo"),IF(Tabela3[[#This Row],[Data Vencimento]]<TODAY(),"Atrasado","Pendente")) -> Pago com Atraso
A13: =ROW()-1 -> 12 | B13: 44959 | C13: =Tabela3[[#This Row],[Data Emissão]]+10 -> 44969 | D13: =TEXT(Tabela3[[#This Row],[Data Vencimento]],"mmm") -> fev | E13: Matrícula Ens Médio | F13: Dwight Schrute | G13: 416 | H13: 44969 | I13: Cheque | J13: 395 | K13: =IF(Tabela3[[#This Row],[Recebido]]<Tabela3[[#This Row],[Valor]],Tabela3[[#This Row],[Valor]]-Tabela3[[#This Row],[Recebido]],0) -> 21 | L13: =IF(Tabela3[[#This Row],[Data Pagamento]]<>"",IF(Tabela3[[#This Row],[Data Pagamento]]>Tabela3[[#This Row],[Data Vencimento]],"Pago com Atraso","Pago no Prazo"),IF(Tabela3[[#This Row],[Data Vencimento]]<TODAY(),"Atrasado","Pendente")) -> Pago no Prazo
... A69: =ROW()-1 -> 68 | B69: 45160 | C69: =Tabela3[[#This Row],[Data Emissão]]+10 -> 45170 | D69: =TEXT(Tabela3[[#This Row],[Data Vencimento]],"mmm") -> set | E69: Mensalidade Ens Fundamental | F69: Suzane Barbosa | G69: 486 | H69: 45174 | I69: Boleto | J69: 487 | K69: =IF(Tabela3[[#This Row],[Recebido]]<Tabela3[[#This Row],[Valor]],Tabela3[[#This Row],[Valor]]-Tabela3[[#This Row],[Recebido]],0) -> 0 | L69: =IF(Tabela3[[#This Row],[Data Pagamento]]<>"",IF(Tabela3[[#This Row],[Data Pagamento]]>Tabela3[[#This Row],[Data Vencimento]],"Pago com Atraso","Pago no Prazo"),IF(Tabela3[[#This Row],[Data Vencimento]]<TODAY(),"Atrasado","Pendente")) -> Pago com Atraso
A70: =ROW()-1 -> 69 | B70: 45161 | C70: =Tabela3[[#This Row],[Data Emissão]]+10 -> 45171 | D70: =TEXT(Tabela3[[#This Row],[Data Vencimento]],"mmm") -> set | E70: Material Escolar | F70: Dona Benta | G70: 266 | K70: =IF(Tabela3[[#This Row],[Recebido]]<Tabela3[[#This Row],[Valor]],Tabela3[[#This Row],[Valor]]-Tabela3[[#This Row],[Recebido]],0) -> 266 | L70: =IF(Tabela3[[#This Row],[Data Pagamento]]<>"",IF(Tabela3[[#This Row],[Data Pagamento]]>Tabela3[[#This Row],[Data Vencimento]],"Pago com Atraso","Pago no Prazo"),IF(Tabela3[[#This Row],[Data Vencimento]]<TODAY(),"Atrasado","Pendente")) -> Atrasado
A71: =ROW()-1 -> 70 | B71: 45161 | C71: =Tabela3[[#This Row],[Data Emissão]]+10 -> 45171 | D71: =TEXT(Tabela3[[#This Row],[Data Vencimento]],"mmm") -> set | E71: Material Escolar | F71: Mariana Rosa | G71: 144 | H71: 45171 | I71: PIX | J71: 120 | K71: =IF(Tabela3[[#This Row],[Recebido]]<Tabela3[[#This Row],[Valor]],Tabela3[[#This Row],[Valor]]-Tabela3[[#This Row],[Recebido]],0) -> 24 | L71: =IF(Tabela3[[#This Row],[Data Pagamento]]<>"",IF(Tabela3[[#This Row],[Data Pagamento]]>Tabela3[[#This Row],[Data Vencimento]],"Pago com Atraso","Pago no Prazo"),IF(Tabela3[[#This Row],[Data Vencimento]]<TODAY(),"Atrasado","Pendente")) -> Pago no Prazo
A72: =ROW()-1 -> 71 | B72: 45170 | C72: =Tabela3[[#This Row],[Data Emissão]]+10 -> 45180 | D72: =TEXT(Tabela3[[#This Row],[Data Vencimento]],"mmm") -> set | E72: Mensalidade Ens Fundamental | F72: Michael Scott | G72: 209 | H72: 45185 | I72: Cheque | J72: 202 | K72: =IF(Tabela3[[#This Row],[Recebido]]<Tabela3[[#This Row],[Valor]],Tabela3[[#This Row],[Valor]]-Tabela3[[#This Row],[Recebido]],0) -> 7 | L72: =IF(Tabela3[[#This Row],[Data Pagamento]]<>"",IF(Tabela3[[#This Row],[Data Pagamento]]>Tabela3[[#This Row],[Data Vencimento]],"Pago com Atraso","Pago no Prazo"),IF(Tabela3[[#This Row],[Data Vencimento]]<TODAY(),"Atrasado","Pendente")) -> Pago com Atraso
A73: =ROW()-1 -> 72 | B73: 45170 | C73: =Tabela3[[#This Row],[Data Emissão]]+10 -> 45180 | D73: =TEXT(Tabela3[[#This Row],[Data Vencimento]],"mmm") -> set | E73: Matrícula Ens Fundamental | F73: Samantha Alves | G73: 451 | K73: =IF(Tabela3[[#This Row],[Recebido]]<Tabela3[[#This Row],[Valor]],Tabela3[[#This Row],[Valor]]-Tabela3[[#This Row],[Recebido]],0) -> 451 | L73: =IF(Tabela3[[#This Row],[Data Pagamento]]<>"",IF(Tabela3[[#This Row],[Data Pagamento]]>Tabela3[[#This Row],[Data Vencimento]],"Pago com Atraso","Pago no Prazo"),IF(Tabela3[[#This Row],[Data Vencimento]]<TODAY(),"Atrasado","Pendente")) -> Atrasado
A74: =ROW()-1 -> 73 | B74: 45171 | C74: =Tabela3[[#This Row],[Data Emissão]]+10 -> 45181 | D74: =TEXT(Tabela3[[#This Row],[Data Vencimento]],"mmm") -> set | E74: Matrícula Ens Fundamental | F74: Dona Benta | G74: 142 | H74: 45178 | I74: PIX | J74: 167 | K74: =IF(Tabela3[[#This Row],[Recebido]]<Tabela3[[#This Row],[Valor]],Tabela3[[#This Row],[Valor]]-Tabela3[[#This Row],[Recebido]],0) -> 0 | L74: =IF(Tabela3[[#This Row],[Data Pagamento]]<>"",IF(Tabela3[[#This Row],[Data Pagamento]]>Tabela3[[#This Row],[Data Vencimento]],"Pago com Atraso","Pago no Prazo"),IF(Tabela3[[#This Row],[Data Vencimento]]<TODAY(),"Atrasado","Pendente")) -> Pago no Prazo
A75: =ROW()-1 -> 74 | B75: 45171 | C75: =Tabela3[[#This Row],[Data Emissão]]+10 -> 45181 | D75: =TEXT(Tabela3[[#This Row],[Data Vencimento]],"mmm") -> set | E75: Matrícula Ens Fundamental | F75: Walter White | G75: 217 | H75: 45183 | I75: PIX | J75: 257 | K75: =IF(Tabela3[[#This Row],[Recebido]]<Tabela3[[#This Row],[Valor]],Tabela3[[#This Row],[Valor]]-Tabela3[[#This Row],[Recebido]],0) -> 0 | L75: =IF(Tabela3[[#This Row],[Data Pagamento]]<>"",IF(Tabela3[[#This Row],[Data Pagamento]]>Tabela3[[#This Row],[Data Vencimento]],"Pago com Atraso","Pago no Prazo"),IF(Tabela3[[#This Row],[Data Vencimento]]<TODAY(),"Atrasado","Pendente")) -> Pago com Atraso
A76: =ROW()-1 -> 75 | B76: 45178 | C76: =Tabela3[[#This Row],[Data Emissão]]+10 -> 45188 | D76: =TEXT(Tabela3[[#This Row],[Data Vencimento]],"mmm") -> set | E76: Mensalidade Ens Médio | F76: Dona Benta | G76: 429 | H76: 45187 | I76: PIX | J76: 446 | K76: =IF(Tabela3[[#This Row],[Recebido]]<Tabela3[[#This Row],[Valor]],Tabela3[[#This Row],[Valor]]-Tabela3[[#This Row],[Recebido]],0) -> 0 | L76: =IF(Tabela3[[#This Row],[Data Pagamento]]<>"",IF(Tabela3[[#This Row],[Data Pagamento]]>Tabela3[[#This Row],[Data Vencimento]],"Pago com Atraso","Pago no Prazo"),IF(Tabela3[[#This Row],[Data Vencimento]]<TODAY(),"Atrasado","Pendente")) -> Pago no Prazo
A77: =ROW()-1 -> 76 | B77: 45180 | C77: =Tabela3[[#This Row],[Data Emissão]]+10 -> 45190 | D77: =TEXT(Tabela3[[#This Row],[Data Vencimento]],"mmm") -> set | E77: Matrícula Ens Médio | F77: Marco Santos | G77: 335 | H77: 45187 | I77: Boleto | J77: 372 | K77: =IF(Tabela3[[#This Row],[Recebido]]<Tabela3[[#This Row],[Valor]],Tabela3[[#This Row],[Valor]]-Tabela3[[#This Row],[Recebido]],0) -> 0 | L77: =IF(Tabela3[[#This Row],[Data Pagamento]]<>"",IF(Tabela3[[#This Row],[Data Pagamento]]>Tabela3[[#This Row],[Data Vencimento]],"Pago com Atraso","Pago no Prazo"),IF(Tabela3[[#This Row],[Data Vencimento]]<TODAY(),"Atrasado","Pendente")) -> Pago no Prazo
A78: =ROW()-1 -> 77 | B78: 45182 | C78: =Tabela3[[#This Row],[Data Emissão]]+10 -> 45192 | D78: =TEXT(Tabela3[[#This Row],[Data Vencimento]],"mmm") -> set | E78: Matrícula Ens Fundamental | F78: Felipe Duarte | G78: 344 | H78: 45198 | I78: PIX | J78: 348 | K78: =IF(Tabela3[[#This Row],[Recebido]]<Tabela3[[#This Row],[Valor]],Tabela3[[#This Row],[Valor]]-Tabela3[[#This Row],[Recebido]],0) -> 0 | L78: =IF(Tabela3[[#This Row],[Data Pagamento]]<>"",IF(Tabela3[[#This Row],[Data Pagamento]]>Tabela3[[#This Row],[Data Vencimento]],"Pago com Atraso","Pago no Prazo"),IF(Tabela3[[#This Row],[Data Vencimento]]<TODAY(),"Atrasado","Pendente")) -> Pago com Atraso
A79: =ROW()-1 -> 78 | B79: 45182 | C79: =Tabela3[[#This Row],[Data Emissão]]+10 -> 45192 | D79: =TEXT(Tabela3[[#This Row],[Data Vencimento]],"mmm") -> set | E79: Atividades Extra Muros | F79: Suzane Barbosa | G79: 190 | H79: 45198 | I79: Boleto | J79: 223 | K79: =IF(Tabela3[[#This Row],[Recebido]]<Tabela3[[#This Row],[Valor]],Tabela3[[#This Row],[Valor]]-Tabela3[[#This Row],[Recebido]],0) -> 0 | L79: =IF(Tabela3[[#This Row],[Data Pagamento]]<>"",IF(Tabela3[[#This Row],[Data Pagamento]]>Tabela3[[#This Row],[Data Vencimento]],"Pago com Atraso","Pago no Prazo"),IF(Tabela3[[#This Row],[Data Vencimento]]<TODAY(),"Atrasado","Pendente")) -> Pago com Atraso
A80: =ROW()-1 -> 79 | B80: 45182 | C80: =Tabela3[[#This Row],[Data Emissão]]+10 -> 45192 | D80: =TEXT(Tabela3[[#This Row],[Data Vencimento]],"mmm") -> set | E80: Matrícula Ens Médio | F80: Agostinho Carrara | G80: 243 | K80: =IF(Tabela3[[#This Row],[Recebido]]<Tabela3[[#This Row],[Valor]],Tabela3[[#This Row],[Valor]]-Tabela3[[#This Row],[Recebido]],0) -> 243 | L80: =IF(Tabela3[[#This Row],[Data Pagamento]]<>"",IF(Tabela3[[#This Row],[Data Pagamento]]>Tabela3[[#This Row],[Data Vencimento]],"Pago com Atraso","Pago no Prazo"),IF(Tabela3[[#This Row],[Data Vencimento]]<TODAY(),"Atrasado","Pendente")) -> Atrasado
A81: =ROW()-1 -> 80 | B81: 45182 | C81: =Tabela3[[#This Row],[Data Emissão]]+10 -> 45192 | D81: =TEXT(Tabela3[[#This Row],[Data Vencimento]],"mmm") -> set | E81: Matrícula Ens Fundamental | F81: Felipe Duarte | G81: 492 | H81: 45197 | I81: Dinheiro | J81: 479 | K81: =IF(Tabela3[[#This Row],[Recebido]]<Tabela3[[#This Row],[Valor]],Tabela3[[#This Row],[Valor]]-Tabela3[[#This Row],[Recebido]],0) -> 13 | L81: =IF(Tabela3[[#This Row],[Data Pagamento]]<>"",IF(Tabela3[[#This Row],[Data Pagamento]]>Tabela3[[#This Row],[Data Vencimento]],"Pago com Atraso","Pago no Prazo"),IF(Tabela3[[#This Row],[Data Vencimento]]<TODAY(),"Atrasado","Pendente")) -> Pago com Atraso
A82: =ROW()-1 -> 81 | B82: 45191 | C82: =Tabela3[[#This Row],[Data Emissão]]+10 -> 45201 | D82: =TEXT(Tabela3[[#This Row],[Data Vencimento]],"mmm") -> out | E82: Mensalidade Ens Médio | F82: Celina Justo | G82: 491 | H82: 45199 | I82: Dinheiro | J82: 469 | K82: =IF(Tabela3[[#This Row],[Recebido]]<Tabela3[[#This Row],[Valor]],Tabela3[[#This Row],[Valor]]-Tabela3[[#This Row],[Recebido]],0) -> 22 | L82: =IF(Tabela3[[#This Row],[Data Pagamento]]<>"",IF(Tabela3[[#This Row],[Data Pagamento]]>Tabela3[[#This Row],[Data Vencimento]],"Pago com Atraso","Pago no Prazo"),IF(Tabela3[[#This Row],[Data Vencimento]]<TODAY(),"Atrasado","Pendente")) -> Pago no Prazo
A83: =ROW()-1 -> 82 | B83: 45193 | C83: =Tabela3[[#This Row],[Data Emissão]]+10 -> 45203 | D83: =TEXT(Tabela3[[#This Row],[Data Vencimento]],"mmm") -> out | E83: Material Escolar | F83: Adalberto Torres | G83: 245 | H83: 45205 | I83: Dinheiro | J83: 211 | K83: =IF(Tabela3[[#This Row],[Recebido]]<Tabela3[[#This Row],[Valor]],Tabela3[[#This Row],[Valor]]-Tabela3[[#This Row],[Recebido]],0) -> 34 | L83: =IF(Tabela3[[#This Row],[Data Pagamento]]<>"",IF(Tabela3[[#This Row],[Data Pagamento]]>Tabela3[[#This Row],[Data Vencimento]],"Pago com Atraso","Pago no Prazo"),IF(Tabela3[[#This Row],[Data Vencimento]]<TODAY(),"Atrasado","Pendente")) -> Pago com Atraso
A84: =ROW()-1 -> 83 | B84: 45194 | C84: =Tabela3[[#This Row],[Data Emissão]]+10 -> 45204 | D84: =TEXT(Tabela3[[#This Row],[Data Vencimento]],"mmm") -> out | E84: Matrícula Ens Fundamental | F84: Mariana Rosa | G84: 116 | K84: =IF(Tabela3[[#This Row],[Recebido]]<Tabela3[[#This Row],[Valor]],Tabela3[[#This Row],[Valor]]-Tabela3[[#This Row],[Recebido]],0) -> 116 | L84: =IF(Tabela3[[#This Row],[Data Pagamento]]<>"",IF(Tabela3[[#This Row],[Data Pagamento]]>Tabela3[[#This Row],[Data Vencimento]],"Pago com Atraso","Pago no Prazo"),IF(Tabela3[[#This Row],[Data Vencimento]]<TODAY(),"Atrasado","Pendente")) -> Atrasado
A85: =ROW()-1 -> 84 | B85: 45195 | C85: =Tabela3[[#This Row],[Data Emissão]]+10 -> 45205 | D85: =TEXT(Tabela3[[#This Row],[Data Vencimento]],"mmm") -> out | E85: Matrícula Ens Médio | F85: Zoe Barnes | G85: 203 | H85: 45203 | I85: Boleto | J85: 228 | K85: =IF(Tabela3[[#This Row],[Recebido]]<Tabela3[[#This Row],[Valor]],Tabela3[[#This Row],[Valor]]-Tabela3[[#This Row],[Recebido]],0) -> 0 | L85: =IF(Tabela3[[#This Row],[Data Pagamento]]<>"",IF(Tabela3[[#This Row],[Data Pagamento]]>Tabela3[[#This Row],[Data Vencimento]],"Pago com Atraso","Pago no Prazo"),IF(Tabela3[[#This Row],[Data Vencimento]]<TODAY(),"Atrasado","Pendente")) -> Pago no Prazo
A86: =ROW()-1 -> 85 | B86: 45213 | C86: =Tabela3[[#This Row],[Data Emissão]]+10 -> 45223 | D86: =TEXT(Tabela3[[#This Row],[Data Vencimento]],"mmm") -> out | E86: Matrícula Ens Fundamental | F86: Adalberto Torres | G86: 490 | H86: 45254 | I86: PIX | J86: 499 | K86: =IF(Tabela3[[#This Row],[Recebido]]<Tabela3[[#This Row],[Valor]],Tabela3[[#This Row],[Valor]]-Tabela3[[#This Row],[Recebido]],0) -> 0 | L86: =IF(Tabela3[[#This Row],[Data Pagamento]]<>"",IF(Tabela3[[#This Row],[Data Pagamento]]>Tabela3[[#This Row],[Data Vencimento]],"Pago com Atraso","Pago no Prazo"),IF(Tabela3[[#This Row],[Data Vencimento]]<TODAY(),"Atrasado","Pendente")) -> Pago com Atraso
A87: =ROW()-1 -> 86 | B87: 45214 | C87: =Tabela3[[#This Row],[Data Emissão]]+10 -> 45224 | D87: =TEXT(Tabela3[[#This Row],[Data Vencimento]],"mmm") -> out | E87: Matrícula Ens Médio | F87: Agostinho Carrara | G87: 113 | K87: =IF(Tabela3[[#This Row],[Recebido]]<Tabela3[[#This Row],[Valor]],Tabela3[[#This Row],[Valor]]-Tabela3[[#This Row],[Recebido]],0) -> 113 | L87: =IF(Tabela3[[#This Row],[Data Pagamento]]<>"",IF(Tabela3[[#This Row],[Data Pagamento]]>Tabela3[[#This Row],[Data Vencimento]],"Pago com Atraso","Pago no Prazo"),IF(Tabela3[[#This Row],[Data Vencimento]]<TODAY(),"Atrasado","Pendente")) -> Atrasado
A88: =ROW()-1 -> 87 | B88: 45246 | C88: =Tabela3[[#This Row],[Data Emissão]]+10 -> 45256 | D88: =TEXT(Tabela3[[#This Row],[Data Vencimento]],"mmm") -> nov | E88: Material Escolar | F88: Celina Justo | G88: 379 | H88: 45251 | I88: Dinheiro | J88: 423 | K88: =IF(Tabela3[[#This Row],[Recebido]]<Tabela3[[#This Row],[Valor]],Tabela3[[#This Row],[Valor]]-Tabela3[[#This Row],[Recebido]],0) -> 0 | L88: =IF(Tabela3[[#This Row],[Data Pagamento]]<>"",IF(Tabela3[[#This Row],[Data Pagamento]]>Tabela3[[#This Row],[Data Vencimento]],"Pago com Atraso","Pago no Prazo"),IF(Tabela3[[#This Row],[Data Vencimento]]<TODAY(),"Atrasado","Pendente")) -> Pago no Prazo
A89: =ROW()-1 -> 88 | B89: 45247 | C89: =Tabela3[[#This Row],[Data Emissão]]+10 -> 45257 | D89: =TEXT(Tabela3[[#This Row],[Data Vencimento]],"mmm") -> nov | E89: Mensalidade Ens Fundamental | F89: Claire Underwood | G89: 162 | H89: 45257 | I89: Cheque | J89: 135 | K89: =IF(Tabela3[[#This Row],[Recebido]]<Tabela3[[#This Row],[Valor]],Tabela3[[#This Row],[Valor]]-Tabela3[[#This Row],[Recebido]],0) -> 27 | L89: =IF(Tabela3[[#This Row],[Data Pagamento]]<>"",IF(Tabela3[[#This Row],[Data Pagamento]]>Tabela3[[#This Row],[Data Vencimento]],"Pago com Atraso","Pago no Prazo"),IF(Tabela3[[#This Row],[Data Vencimento]]<TODAY(),"Atrasado","Pendente")) -> Pago no Prazo
A90: =ROW()-1 -> 89 | B90: 45248 | C90: =Tabela3[[#This Row],[Data Emissão]]+10 -> 45258 | D90: =TEXT(Tabela3[[#This Row],[Data Vencimento]],"mmm") -> nov | E90: Mensalidade Ens Médio | F90: Dona Benta | G90: 437 | H90: 45256 | I90: PIX | J90: 527 | K90: =IF(Tabela3[[#This Row],[Recebido]]<Tabela3[[#This Row],[Valor]],Tabela3[[#This Row],[Valor]]-Tabela3[[#This Row],[Recebido]],0) -> 0 | L90: =IF(Tabela3[[#This Row],[Data Pagamento]]<>"",IF(Tabela3[[#This Row],[Data Pagamento]]>Tabela3[[#This Row],[Data Vencimento]],"Pago com Atraso","Pago no Prazo"),IF(Tabela3[[#This Row],[Data Vencimento]]<TODAY(),"Atrasado","Pendente")) -> Pago no Prazo
A91: =ROW()-1 -> 90 | B91: 45249 | C91: =Tabela3[[#This Row],[Data Emissão]]+10 -> 45259 | D91: =TEXT(Tabela3[[#This Row],[Data Vencimento]],"mmm") -> nov | E91: Atividades Extra Muros | F91: Dwight Schrute | G91: 272 | H91: 45260 | I91: Boleto | J91: 345 | K91: =IF(Tabela3[[#This Row],[Recebido]]<Tabela3[[#This Row],[Valor]],Tabela3[[#This Row],[Valor]]-Tabela3[[#This Row],[Recebido]],0) -> 0 | L91: =IF(Tabela3[[#This Row],[Data Pagamento]]<>"",IF(Tabela3[[#This Row],[Data Pagamento]]>Tabela3[[#This Row],[Data Vencimento]],"Pago com Atraso","Pago no Prazo"),IF(Tabela3[[#This Row],[Data Vencimento]]<TODAY(),"Atrasado","Pendente")) -> Pago com Atraso
A92: =ROW()-1 -> 91 | B92: 45250 | C92: =Tabela3[[#This Row],[Data Emissão]]+10 -> 45260 | D92: =TEXT(Tabela3[[#This Row],[Data Vencimento]],"mmm") -> nov | E92: Matrícula Ens Fundamental | F92: Felipe Duarte | G92: 201 | H92: 45261 | I92: Dinheiro | J92: 243 | K92: =IF(Tabela3[[#This Row],[Recebido]]<Tabela3[[#This Row],[Valor]],Tabela3[[#This Row],[Valor]]-Tabela3[[#This Row],[Recebido]],0) -> 0 | L92: =IF(Tabela3[[#This Row],[Data Pagamento]]<>"",IF(Tabela3[[#This Row],[Data Pagamento]]>Tabela3[[#This Row],[Data Vencimento]],"Pago com Atraso","Pago no Prazo"),IF(Tabela3[[#This Row],[Data Vencimento]]<TODAY(),"Atrasado","Pendente")) -> Pago com Atraso
A93: =ROW()-1 -> 92 | B93: 45251 | C93: =Tabela3[[#This Row],[Data Emissão]]+10 -> 45261 | D93: =TEXT(Tabela3[[#This Row],[Data Vencimento]],"mmm") -> dez | E93: Matrícula Ens Médio | F93: Marco Santos | G93: 328 | H93: 45256 | I93: Cheque | J93: 346 | K93: =IF(Tabela3[[#This Row],[Recebido]]<Tabela3[[#This Row],[Valor]],Tabela3[[#This Row],[Valor]]-Tabela3[[#This Row],[Recebido]],0) -> 0 | L93: =IF(Tabela3[[#This Row],[Data Pagamento]]<>"",IF(Tabela3[[#This Row],[Data Pagamento]]>Tabela3[[#This Row],[Data Vencimento]],"Pago com Atraso","Pago no Prazo"),IF(Tabela3[[#This Row],[Data Vencimento]]<TODAY(),"Atrasado","Pendente")) -> Pago no Prazo
A94: =ROW()-1 -> 93 | B94: 45252 | C94: =Tabela3[[#This Row],[Data Emissão]]+10 -> 45262 | D94: =TEXT(Tabela3[[#This Row],[Data Vencimento]],"mmm") -> dez | E94: Material Escolar | F94: Mariana Rosa | G94: 170 | H94: 45259 | I94: PIX | J94: 140 | K94: =IF(Tabela3[[#This Row],[Recebido]]<Tabela3[[#This Row],[Valor]],Tabela3[[#This Row],[Valor]]-Tabela3[[#This Row],[Recebido]],0) -> 30 | L94: =IF(Tabela3[[#This Row],[Data Pagamento]]<>"",IF(Tabela3[[#This Row],[Data Pagamento]]>Tabela3[[#This Row],[Data Vencimento]],"Pago com Atraso","Pago no Prazo"),IF(Tabela3[[#This Row],[Data Vencimento]]<TODAY(),"Atrasado","Pendente")) -> Pago no Prazo
A95: =ROW()-1 -> 94 | B95: 45253 | C95: =Tabela3[[#This Row],[Data Emissão]]+10 -> 45263 | D95: =TEXT(Tabela3[[#This Row],[Data Vencimento]],"mmm") -> dez | E95: Mensalidade Ens Fundamental | F95: Michael Scott | G95: 362 | H95: 45264 | I95: Boleto | J95: 417 | K95: =IF(Tabela3[[#This Row],[Recebido]]<Tabela3[[#This Row],[Valor]],Tabela3[[#This Row],[Valor]]-Tabela3[[#This Row],[Recebido]],0) -> 0 | L95: =IF(Tabela3[[#This Row],[Data Pagamento]]<>"",IF(Tabela3[[#This Row],[Data Pagamento]]>Tabela3[[#This Row],[Data Vencimento]],"Pago com Atraso","Pago no Prazo"),IF(Tabela3[[#This Row],[Data Vencimento]]<TODAY(),"Atrasado","Pendente")) -> Pago com Atraso
...

Sheet Resumo Geral
A1: Ano | B1: Jan | C1: Fev | D1: Mar | E1: Abr | F1: Mai | G1: Jun | H1: Jul | I1: Ago | J1: Set | K1: Out | L1: Nov | M1: Dez
A2: Quantidade de contas a receber | B2: =COUNTIFS(Registro!$L:$L,"Pendente",Registro!$D:$D,'Resumo Geral'!B$1)+COUNTIFS(Registro!$L:$L,"Atrasado",Registro!$D:$D,'Resumo Geral'!B$1) -> 0 | C2: =COUNTIFS(Registro!$L:$L,"Pendente",Registro!$D:$D,'Resumo Geral'!C$1)+COUNTIFS(Registro!$L:$L,"Atrasado",Registro!$D:$D,'Resumo Geral'!C$1) -> 0 | D2: =COUNTIFS(Registro!$L:$L,"Pendente",Registro!$D:$D,'Resumo Geral'!D$1)+COUNTIFS(Registro!$L:$L,"Atrasado",Registro!$D:$D,'Resumo Geral'!D$1) -> 0 | E2: =COUNTIFS(Registro!$L:$L,"Pendente",Registro!$D:$D,'Resumo Geral'!E$1)+COUNTIFS(Registro!$L:$L,"Atrasado",Registro!$D:$D,'Resumo Geral'!E$1) -> 0 | F2: =COUNTIFS(Registro!$L:$L,"Pendente",Registro!$D:$D,'Resumo Geral'!F$1)+COUNTIFS(Registro!$L:$L,"Atrasado",Registro!$D:$D,'Resumo Geral'!F$1) -> 0 | G2: =COUNTIFS(Registro!$L:$L,"Pendente",Registro!$D:$D,'Resumo Geral'!G$1)+COUNTIFS(Registro!$L:$L,"Atrasado",Registro!$D:$D,'Resumo Geral'!G$1) -> 0 | H2: =COUNTIFS(Registro!$L:$L,"Pendente",Registro!$D:$D,'Resumo Geral'!H$1)+COUNTIFS(Registro!$L:$L,"Atrasado",Registro!$D:$D,'Resumo Geral'!H$1) -> 0 | I2: =COUNTIFS(Registro!$L:$L,"Pendente",Registro!$D:$D,'Resumo Geral'!I$1)+COUNTIFS(Registro!$L:$L,"Atrasado",Registro!$D:$D,'Resumo Geral'!I$1) -> 0 | ... M2: =COUNTIFS(Registro!$L:$L,"Pendente",Registro!$D:$D,'Resumo Geral'!M$1)+COUNTIFS(Registro!$L:$L,"Atrasado",Registro!$D:$D,'Resumo Geral'!M$1) -> 8
A3: Valor de contas a receber | B3: =SUMIFS(Registro!$G:$G,Registro!$L:$L,"Pendente",Registro!$D:$D,'Resumo Geral'!B$1)+SUMIFS(Registro!$G:$G,Registro!$L:$L,"Atrasado",Registro!$D:$D,'Resumo Geral'!B$1) -> 0 | C3: =SUMIFS(Registro!$G:$G,Registro!$L:$L,"Pendente",Registro!$D:$D,'Resumo Geral'!C$1)+SUMIFS(Registro!$G:$G,Registro!$L:$L,"Atrasado",Registro!$D:$D,'Resumo Geral'!C$1) -> 0 | D3: =SUMIFS(Registro!$G:$G,Registro!$L:$L,"Pendente",Registro!$D:$D,'Resumo Geral'!D$1)+SUMIFS(Registro!$G:$G,Registro!$L:$L,"Atrasado",Registro!$D:$D,'Resumo Geral'!D$1) -> 0 | E3: =SUMIFS(Registro!$G:$G,Registro!$L:$L,"Pendente",Registro!$D:$D,'Resumo Geral'!E$1)+SUMIFS(Registro!$G:$G,Registro!$L:$L,"Atrasado",Registro!$D:$D,'Resumo Geral'!E$1) -> 0 | F3: =SUMIFS(Registro!$G:$G,Registro!$L:$L,"Pendente",Registro!$D:$D,'Resumo Geral'!F$1)+SUMIFS(Registro!$G:$G,Registro!$L:$L,"Atrasado",Registro!$D:$D,'Resumo Geral'!F$1) -> 0 | G3: =SUMIFS(Registro!$G:$G,Registro!$L:$L,"Pendente",Registro!$D:$D,'Resumo Geral'!G$1)+SUMIFS(Registro!$G:$G,Registro!$L:$L,"Atrasado",Registro!$D:$D,'Resumo Geral'!G$1) -> 0 | H3: =SUMIFS(Registro!$G:$G,Registro!$L:$L,"Pendente",Registro!$D:$D,'Resumo Geral'!H$1)+SUMIFS(Registro!$G:$G,Registro!$L:$L,"Atrasado",Registro!$D:$D,'Resumo Geral'!H$1) -> 0 | I3: =SUMIFS(Registro!$G:$G,Registro!$L:$L,"Pendente",Registro!$D:$D,'Resumo Geral'!I$1)+SUMIFS(Registro!$G:$G,Registro!$L:$L,"Atrasado",Registro!$D:$D,'Resumo Geral'!I$1) -> 0 | ... M3: =SUMIFS(Registro!$G:$G,Registro!$L:$L,"Pendente",Registro!$D:$D,'Resumo Geral'!M$1)+SUMIFS(Registro!$G:$G,Registro!$L:$L,"Atrasado",Registro!$D:$D,'Resumo Geral'!M$1) -> 2882
A4: Quantidade de contas recebidas | B4: =COUNTIFS(Registro!$L:$L,"Pago no Prazo",Registro!$D:$D,'Resumo Geral'!B$1)+COUNTIFS(Registro!$L:$L,"Pago com Atraso",Registro!$D:$D,'Resumo Geral'!B$1) -> 5 | C4: =COUNTIFS(Registro!$L:$L,"Pago no Prazo",Registro!$D:$D,'Resumo Geral'!C$1)+COUNTIFS(Registro!$L:$L,"Pago com Atraso",Registro!$D:$D,'Resumo Geral'!C$1) -> 10 | D4: =COUNTIFS(Registro!$L:$L,"Pago no Prazo",Registro!$D:$D,'Resumo Geral'!D$1)+COUNTIFS(Registro!$L:$L,"Pago com Atraso",Registro!$D:$D,'Resumo Geral'!D$1) -> 8 | E4: =COUNTIFS(Registro!$L:$L,"Pago no Prazo",Registro!$D:$D,'Resumo Geral'!E$1)+COUNTIFS(Registro!$L:$L,"Pago com Atraso",Registro!$D:$D,'Resumo Geral'!E$1) -> 9 | F4: =COUNTIFS(Registro!$L:$L,"Pago no Prazo",Registro!$D:$D,'Resumo Geral'!F$1)+COUNTIFS(Registro!$L:$L,"Pago com Atraso",Registro!$D:$D,'Resumo Geral'!F$1) -> 9 | G4: =COUNTIFS(Registro!$L:$L,"Pago no Prazo",Registro!$D:$D,'Resumo Geral'!G$1)+COUNTIFS(Registro!$L:$L,"Pago com Atraso",Registro!$D:$D,'Resumo Geral'!G$1) -> 8 | H4: =COUNTIFS(Registro!$L:$L,"Pago no Prazo",Registro!$D:$D,'Resumo Geral'!H$1)+COUNTIFS(Registro!$L:$L,"Pago com Atraso",Registro!$D:$D,'Resumo Geral'!H$1) -> 8 | I4: =COUNTIFS(Registro!$L:$L,"Pago no Prazo",Registro!$D:$D,'Resumo Geral'!I$1)+COUNTIFS(Registro!$L:$L,"Pago com Atraso",Registro!$D:$D,'Resumo Geral'!I$1) -> 10 | ... M4: =COUNTIFS(Registro!$L:$L,"Pago no Prazo",Registro!$D:$D,'Resumo Geral'!M$1)+COUNTIFS(Registro!$L:$L,"Pago com Atraso",Registro!$D:$D,'Resumo Geral'!M$1) -> 13
A5: Valor de contas recebidas | B5: =SUMIFS(Registro!$G:$G,Registro!$L:$L,"Pago no Prazo",Registro!$D:$D,'Resumo Geral'!B$1)+SUMIFS(Registro!$G:$G,Registro!$L:$L,"Pago com Atraso",Registro!$D:$D,'Resumo Geral'!B$1) -> 1307 | C5: =SUMIFS(Registro!$G:$G,Registro!$L:$L,"Pago no Prazo",Registro!$D:$D,'Resumo Geral'!C$1)+SUMIFS(Registro!$G:$G,Registro!$L:$L,"Pago com Atraso",Registro!$D:$D,'Resumo Geral'!C$1) -> 2753 | D5: =SUMIFS(Registro!$G:$G,Registro!$L:$L,"Pago no Prazo",Registro!$D:$D,'Resumo Geral'!D$1)+SUMIFS(Registro!$G:$G,Registro!$L:$L,"Pago com Atraso",Registro!$D:$D,'Resumo Geral'!D$1) -> 2438 | E5: =SUMIFS(Registro!$G:$G,Registro!$L:$L,"Pago no Prazo",Registro!$D:$D,'Resumo Geral'!E$1)+SUMIFS(Registro!$G:$G,Registro!$L:$L,"Pago com Atraso",Registro!$D:$D,'Resumo Geral'!E$1) -> 2595 | F5: =SUMIFS(Registro!$G:$G,Registro!$L:$L,"Pago no Prazo",Registro!$D:$D,'Resumo Geral'!F$1)+SUMIFS(Registro!$G:$G,Registro!$L:$L,"Pago com Atraso",Registro!$D:$D,'Resumo Geral'!F$1) -> 2448 | G5: =SUMIFS(Registro!$G:$G,Registro!$L:$L,"Pago no Prazo",Registro!$D:$D,'Resumo Geral'!G$1)+SUMIFS(Registro!$G:$G,Registro!$L:$L,"Pago com Atraso",Registro!$D:$D,'Resumo Geral'!G$1) -> 2088 | H5: =SUMIFS(Registro!$G:$G,Registro!$L:$L,"Pago no Prazo",Registro!$D:$D,'Resumo Geral'!H$1)+SUMIFS(Registro!$G:$G,Registro!$L:$L,"Pago com Atraso",Registro!$D:$D,'Resumo Geral'!H$1) -> 2561 | I5: =SUMIFS(Registro!$G:$G,Registro!$L:$L,"Pago no Prazo",Registro!$D:$D,'Resumo Geral'!I$1)+SUMIFS(Registro!$G:$G,Registro!$L:$L,"Pago com Atraso",Registro!$D:$D,'Resumo Geral'!I$1) -> 2799 | ... M5: =SUMIFS(Registro!$G:$G,Registro!$L:$L,"Pago no Prazo",Registro!$D:$D,'Resumo Geral'!M$1)+SUMIFS(Registro!$G:$G,Registro!$L:$L,"Pago com Atraso",Registro!$D:$D,'Resumo Geral'!M$1) -> 3956
A6: Quantidade recebidas com atraso | B6: =COUNTIFS(Registro!$L:$L,"Pago com Atraso",Registro!$D:$D,'Resumo Geral'!B$1) -> 3 | C6: =COUNTIFS(Registro!$L:$L,"Pago com Atraso",Registro!$D:$D,'Resumo Geral'!C$1) -> 5 | D6: =COUNTIFS(Registro!$L:$L,"Pago com Atraso",Registro!$D:$D,'Resumo Geral'!D$1) -> 4 | E6: =COUNTIFS(Registro!$L:$L,"Pago com Atraso",Registro!$D:$D,'Resumo Geral'!E$1) -> 5 | F6: =COUNTIFS(Registro!$L:$L,"Pago com Atraso",Registro!$D:$D,'Resumo Geral'!F$1) -> 6 | G6: =COUNTIFS(Registro!$L:$L,"Pago com Atraso",Registro!$D:$D,'Resumo Geral'!G$1) -> 4 | H6: =COUNTIFS(Registro!$L:$L,"Pago com Atraso",Registro!$D:$D,'Resumo Geral'!H$1) -> 3 | I6: =COUNTIFS(Registro!$L:$L,"Pago com Atraso",Registro!$D:$D,'Resumo Geral'!I$1) -> 3 | ... M6: =COUNTIFS(Registro!$L:$L,"Pago com Atraso",Registro!$D:$D,'Resumo Geral'!M$1) -> 5
A7: Valor de contas recebidas com atraso | B7: =SUMIFS(Registro!$G:$G,Registro!$L:$L,"Pago com Atraso",Registro!$D:$D,'Resumo Geral'!B$1) -> 801 | C7: =SUMIFS(Registro!$G:$G,Registro!$L:$L,"Pago com Atraso",Registro!$D:$D,'Resumo Geral'!C$1) -> 1190 | D7: =SUMIFS(Registro!$G:$G,Registro!$L:$L,"Pago com Atraso",Registro!$D:$D,'Resumo Geral'!D$1) -> 937 | E7: =SUMIFS(Registro!$G:$G,Registro!$L:$L,"Pago com Atraso",Registro!$D:$D,'Resumo Geral'!E$1) -> 1202 | F7: =SUMIFS(Registro!$G:$G,Registro!$L:$L,"Pago com Atraso",Registro!$D:$D,'Resumo Geral'!F$1) -> 1719 | G7: =SUMIFS(Registro!$G:$G,Registro!$L:$L,"Pago com Atraso",Registro!$D:$D,'Resumo Geral'!G$1) -> 1099 | H7: =SUMIFS(Registro!$G:$G,Registro!$L:$L,"Pago com Atraso",Registro!$D:$D,'Resumo Geral'!H$1) -> 953 | I7: =SUMIFS(Registro!$G:$G,Registro!$L:$L,"Pago com Atraso",Registro!$D:$D,'Resumo Geral'!I$1) -> 655 | ... M7: =SUMIFS(Registro!$G:$G,Registro!$L:$L,"Pago com Atraso",Registro!$D:$D,'Resumo Geral'!M$1) -> 1693
A8: Quantidade de contas vencidas | B8: =COUNTIFS(Registro!$L:$L,"Atrasado",Registro!$D:$D,'Resumo Geral'!B$1) -> 0 | C8: =COUNTIFS(Registro!$L:$L,"Atrasado",Registro!$D:$D,'Resumo Geral'!C$1) -> 0 | D8: =COUNTIFS(Registro!$L:$L,"Atrasado",Registro!$D:$D,'Resumo Geral'!D$1) -> 0 | E8: =COUNTIFS(Registro!$L:$L,"Atrasado",Registro!$D:$D,'Resumo Geral'!E$1) -> 0 | F8: =COUNTIFS(Registro!$L:$L,"Atrasado",Registro!$D:$D,'Resumo Geral'!F$1) -> 0 | G8: =COUNTIFS(Registro!$L:$L,"Atrasado",Registro!$D:$D,'Resumo Geral'!G$1) -> 0 | H8: =COUNTIFS(Registro!$L:$L,"Atrasado",Registro!$D:$D,'Resumo Geral'!H$1) -> 0 | I8: =COUNTIFS(Registro!$L:$L,"Atrasado",Registro!$D:$D,'Resumo Geral'!I$1) -> 0 | ... M8: =COUNTIFS(Registro!$L:$L,"Atrasado",Registro!$D:$D,'Resumo Geral'!M$1) -> 0
A9: Valor de contas vencidas | B9: =SUMIFS(Registro!$G:$G,Registro!$L:$L,"Atrasado",Registro!$D:$D,'Resumo Geral'!B$1) -> 0 | C9: =SUMIFS(Registro!$G:$G,Registro!$L:$L,"Atrasado",Registro!$D:$D,'Resumo Geral'!C$1) -> 0 | D9: =SUMIFS(Registro!$G:$G,Registro!$L:$L,"Atrasado",Registro!$D:$D,'Resumo Geral'!D$1) -> 0 | E9: =SUMIFS(Registro!$G:$G,Registro!$L:$L,"Atrasado",Registro!$D:$D,'Resumo Geral'!E$1) -> 0 | F9: =SUMIFS(Registro!$G:$G,Registro!$L:$L,"Atrasado",Registro!$D:$D,'Resumo Geral'!F$1) -> 0 | G9: =SUMIFS(Registro!$G:$G,Registro!$L:$L,"Atrasado",Registro!$D:$D,'Resumo Geral'!G$1) -> 0 | H9: =SUMIFS(Registro!$G:$G,Registro!$L:$L,"Atrasado",Registro!$D:$D,'Resumo Geral'!H$1) -> 0 | I9: =SUMIFS(Registro!$G:$G,Registro!$L:$L,"Atrasado",Registro!$D:$D,'Resumo Geral'!I$1) -> 0 | ... M9: =SUMIFS(Registro!$G:$G,Registro!$L:$L,"Atrasado",Registro!$D:$D,'Resumo Geral'!M$1) -> 0

Sheet Análises
A1: EM ABERTO | D1: GERAL | G1: ATRASADO
A3: Status | B3: (Vários itens) | D3: Rótulos de Linha | E3: Contagem de Forma Pgto | G3: Status | H3: Atrasado
D4: Cheque | E4: 28
A5: Rótulos de Linha | B5: Contagem de Status | D5: PIX | E5: 27 | G5: Rótulos de Linha | H5: Soma de Valor
A6: Atividades Extra Muros | B6: 1 | D6: Boleto | E6: 26 | G6: Agostinho Carrara | H6: 356
A7: Mensalidade Ens Médio | B7: 1 | D7: Dinheiro | E7: 26 | G7: Dona Benta | H7: 266
A8: Mensalidade Ens Fundamental | B8: 2 | D8: Total Geral | E8: 107 | G8: Mariana Rosa | H8: 116
A9: Matrícula Ens Fundamental | B9: 3 | G9: Samantha Alves | H9: 451
A10: Material Escolar | B10: 3 | G10: Total Geral | H10: 1189
A11: Matrícula Ens Médio | B11: 3
A12: Total Geral | B12: 13
D14: Rótulos de Linha | E14: Contagem de Status
D15: Atrasado | E15: 5 | G15: Status | H15: Atrasado
D16: Pago com Atraso | E16: 48
D17: Pago no Prazo | E17: 51 | G17: Categoria | H17: Contagem de Categoria
A18: Status | B18: (Vários itens) | D18: Pendente | E18: 8 | G18: Matrícula Ens Médio | H18: 2
D19: Total Geral | E19: 112 | G19: Matrícula Ens Fundamental | H19: 2
A20: Rótulos de Linha | B20: Contagem de Status | G20: Material Escolar | H20: 1
A21: dez | B21: 8 | G21: Total Geral | H21: 5
A22: set | B22: 3
A23: out | B23: 2
A24: Total Geral | B24: 13
D25: Rótulos de Linha | E25: Soma de Valor
D26: Claire Underwood | E26: 2158
D27: Michael Scott | E27: 2263
D28: Marco Santos | E28: 2281
D29: Celina Justo | E29: 2398
D30: Suzane Barbosa | E30: 2469
D31: Walter White | E31: 2524
D32: Dona Benta | E32: 2531
D33: Dwight Schrute | E33: 2628
D34: Adalberto Torres | E34: 2744
D35: Felipe Duarte | E35: 2774
D36: Total Geral | E36: 24770
D45: Rótulos de Linha | E45: Soma de Valor
D46: jan | E46: 1307
D47: fev | E47: 2753
D48: mar | E48: 2438
D49: abr | E49: 2595
D50: mai | E50: 2448
...

Sheet Dashboard
