Workbook

Sheet CAPA

Sheet Tutorial
B1: TUTORIAL
B5: ABA VISÃO GERAL
B23: ABA LISTAS
B43: ABA CALENDÁRIO
B61: ABAS JANEIRO À DEZEMBRO

Sheet VISÃO GERAL
B1: VISÃO GERAL 2021
B4: JANEIRO | E4: FEVEREIRO | F4: FEVEREIRO | H4: MARÇO | I4: MARÇO | K4: ABRIL | L4: ABRIL | N4: MAIO | O4: MAIO | Q4: JUNHO | R4: JUNHO | T4: JULHO | U4: JULHO | W4: AGOSTO | X4: AGOSTO | Z4: SETEMBRO | AA4: SETEMBRO | AC4: OUTUBRO | AD4: OUTUBRO | AF4: NOVEMBRO | AG4: NOVEMBRO | AI4: DEZEMBRO | AJ4: DEZEMBRO
B5: 1 | C5: Reencontrei antigos amigos | E5: 1 | H5: 1 | K5: 1 | N5: 1 | Q5: 1 | T5: 1 | W5: 1 | Z5: 1 | AC5: 1 | AF5: 1 | AI5: 1
B6: 2 | C6: Voltei para a academia | E6: 2 | H6: 2 | K6: 2 | N6: 2 | Q6: 2 | T6: 2 | W6: 2 | Z6: 2 | AC6: 2 | AF6: 2 | AI6: 2
B7: 3 | E7: 3 | H7: 3 | K7: 3 | N7: 3 | Q7: 3 | T7: 3 | W7: 3 | Z7: 3 | AC7: 3 | AF7: 3 | AI7: 3
B8: 4 | E8: 4 | H8: 4 | K8: 4 | N8: 4 | Q8: 4 | T8: 4 | W8: 4 | Z8: 4 | AC8: 4 | AF8: 4 | AI8: 4
B9: 5 | E9: 5 | H9: 5 | K9: 5 | N9: 5 | Q9: 5 | T9: 5 | W9: 5 | Z9: 5 | AC9: 5 | AF9: 5 | AI9: 5
B10: 6 | E10: 6 | H10: 6 | K10: 6 | N10: 6 | Q10: 6 | T10: 6 | W10: 6 | Z10: 6 | AC10: 6 | AF10: 6 | AI10: 6
B11: 7 | E11: =E10+1 -> 7 | H11: 7 | K11: 7 | N11: 7 | Q11: 7 | T11: 7 | W11: 7 | Z11: 7 | AC11: 7 | AF11: 7 | AI11: 7
B12: 8 | E12: 8 | H12: 8 | K12: 8 | N12: 8 | Q12: 8 | T12: 8 | W12: 8 | Z12: 8 | AC12: 8 | AF12: 8 | AI12: 8
B13: 9 | E13: 9 | H13: 9 | K13: 9 | N13: 9 | Q13: 9 | T13: 9 | W13: 9 | Z13: 9 | AC13: 9 | AF13: 9 | AI13: 9
B14: 10 | E14: 10 | H14: 10 | K14: 10 | N14: 10 | Q14: 10 | T14: 10 | W14: 10 | Z14: 10 | AC14: 10 | AF14: 10 | AI14: 10
B15: 11 | E15: 11 | H15: 11 | K15: 11 | N15: 11 | Q15: 11 | T15: 11 | W15: 11 | Z15: 11 | AC15: 11 | AF15: 11 | AI15: 11
B16: 12 | E16: 12 | H16: 12 | K16: 12 | N16: 12 | Q16: 12 | T16: 12 | W16: 12 | Z16: 12 | AC16: 12 | AF16: 12 | AI16: 12
B17: 13 | E17: 13 | H17: 13 | K17: 13 | N17: 13 | Q17: 13 | T17: 13 | W17: 13 | Z17: 13 | AC17: 13 | AF17: 13 | AI17: 13
B18: 14 | E18: 14 | H18: 14 | K18: 14 | N18: 14 | Q18: 14 | T18: 14 | W18: 14 | Z18: 14 | AC18: 14 | AF18: 14 | AI18: 14
B19: 15 | E19: 15 | H19: 15 | K19: 15 | N19: 15 | Q19: 15 | T19: 15 | W19: 15 | Z19: 15 | AC19: 15 | AF19: 15 | AI19: 15
B20: 16 | E20: 16 | H20: 16 | K20: 16 | N20: 16 | Q20: 16 | T20: 16 | W20: 16 | Z20: 16 | AC20: 16 | AF20: 16 | AI20: 16
B21: 17 | E21: 17 | H21: 17 | K21: 17 | N21: 17 | Q21: 17 | T21: 17 | W21: 17 | Z21: 17 | AC21: 17 | AF21: 17 | AI21: 17
B22: 18 | E22: 18 | H22: 18 | K22: 18 | N22: 18 | Q22: 18 | T22: 18 | W22: 18 | Z22: 18 | AC22: 18 | AF22: 18 | AI22: 18
B23: 19 | E23: 19 | H23: 19 | K23: 19 | N23: 19 | Q23: 19 | T23: 19 | W23: 19 | Z23: 19 | AC23: 19 | AF23: 19 | AI23: 19
... B32: 28 | E32: 28 | H32: 28 | K32: 28 | N32: 28 | Q32: 28 | T32: 28 | W32: 28 | Z32: 28 | AC32: 28 | AF32: 28 | AI32: 28
B33: 29 | H33: 29 | K33: 29 | N33: 29 | Q33: 29 | T33: 29 | W33: 29 | Z33: 29 | AC33: 29 | AF33: 29 | AI33: 29
B34: 30 | H34: 30 | K34: 30 | N34: 30 | Q34: 30 | T34: 30 | W34: 30 | Z34: 30 | AC34: 30 | AF34: 30 | AI34: 30
B35: 31 | H35: 31 | N35: 31 | Q35: 31 | W35: 31 | AC35: 31 | AI35: 31

Sheet LISTAS
B1: LISTAS DE METAS
B4: LISTA DE METAS PARA: | E4: LISTA DE METAS PARA:
B5: JANEIRO | E5: FEVEREIRO
C6: Estudar inglês | F6: Viajar para Ilha Grande
C7: Começar academia | F7: Rever amigos 1 vez/mês
C8: Tirar 1 dia/semana para organizar a vida
B18: LISTA DE METAS PARA: | E18: LISTA DE METAS PARA:
B19: MARÇO | E19: ABRIL
B32: LISTA DE METAS PARA: | E32: LISTA DE METAS PARA:
B33: MAIO | E33: JUNHO
B46: LISTA DE METAS PARA: | E46: LISTA DE METAS PARA:
B47: JULHO | E47: AGOSTO
B60: LISTA DE METAS PARA: | E60: LISTA DE METAS PARA:
B61: SETEMBRO | E61: OUTUBRO
B74: LISTA DE METAS PARA: | E74: LISTA DE METAS PARA:
B75: NOVEMBRO | E75: DEZEMBRO

Sheet CALENDÁRIO
B1: CALENDÁRIO 2021
C4: * Clique no dia para ser direcionado para a agenda
C6: JANEIRO | K6: FEVEREIRO | S6: MARÇO | AA6: ABRIL
C7: S | D7: T | E7: Q | F7: Q | G7: S | H7: S | I7: D | K7: S | L7: T | M7: Q | N7: Q | O7: S | P7: S | Q7: D | S7: S | T7: T | U7: Q | V7: Q | W7: S | X7: S | Y7: D | AA7: S | AB7: T | AC7: Q | AD7: Q | AE7: S | AF7: S | AG7: D
G8: =HYPERLINK("#" & $C$6 & "!B" & MATCH('CALENDÁRIO aux'!G8,INDIRECT($C$6 &"!$B:$B"),0) + 3,'CALENDÁRIO aux'!G8) -> 1 | H8: =HYPERLINK("#" & $C$6 & "!B" & MATCH('CALENDÁRIO aux'!H8,INDIRECT($C$6 &"!$B:$B"),0) + 3,'CALENDÁRIO aux'!H8) -> 2 | I8: =HYPERLINK("#" & $C$6 & "!B" & MATCH('CALENDÁRIO aux'!I8,INDIRECT($C$6 &"!$B:$B"),0) + 3,'CALENDÁRIO aux'!I8) -> 3 | K8: =HYPERLINK("#" & $K$6 & "!B" & MATCH('CALENDÁRIO aux'!K8,INDIRECT($K$6 &"!$B:$B"),0) + 3,'CALENDÁRIO aux'!K8) -> 1 | L8: =HYPERLINK("#" & $K$6 & "!B" & MATCH('CALENDÁRIO aux'!L8,INDIRECT($K$6 &"!$B:$B"),0) + 3,'CALENDÁRIO aux'!L8) -> 2 | M8: =HYPERLINK("#" & $K$6 & "!B" & MATCH('CALENDÁRIO aux'!M8,INDIRECT($K$6 &"!$B:$B"),0) + 3,'CALENDÁRIO aux'!M8) -> 3 | N8: =HYPERLINK("#" & $K$6 & "!B" & MATCH('CALENDÁRIO aux'!N8,INDIRECT($K$6 &"!$B:$B"),0) + 3,'CALENDÁRIO aux'!N8) -> 4 | O8: =HYPERLINK("#" & $K$6 & "!B" & MATCH('CALENDÁRIO aux'!O8,INDIRECT($K$6 &"!$B:$B"),0) + 3,'CALENDÁRIO aux'!O8) -> 5 | P8: =HYPERLINK("#" & $K$6 & "!B" & MATCH('CALENDÁRIO aux'!P8,INDIRECT($K$6 &"!$B:$B"),0) + 3,'CALENDÁRIO aux'!P8) -> 6 | Q8: =HYPERLINK("#" & $K$6 & "!B" & MATCH('CALENDÁRIO aux'!Q8,INDIRECT($K$6 &"!$B:$B"),0) + 3,'CALENDÁRIO aux'!Q8) -> 7 | S8: =HYPERLINK("#" & $S$6 & "!B" & MATCH('CALENDÁRIO aux'!S8,INDIRECT($S$6 &"!$B:$B"),0) + 3,'CALENDÁRIO aux'!S8) -> 1 | T8: =HYPERLINK("#" & $S$6 & "!B" & MATCH('CALENDÁRIO aux'!T8,INDIRECT($S$6 &"!$B:$B"),0) + 3,'CALENDÁRIO aux'!T8) -> 2 | U8: =HYPERLINK("#" & $S$6 & "!B" & MATCH('CALENDÁRIO aux'!U8,INDIRECT($S$6 &"!$B:$B"),0) + 3,'CALENDÁRIO aux'!U8) -> 3 | V8: =HYPERLINK("#" & $S$6 & "!B" & MATCH('CALENDÁRIO aux'!V8,INDIRECT($S$6 &"!$B:$B"),0) + 3,'CALENDÁRIO aux'!V8) -> 4 | W8: =HYPERLINK("#" & $S$6 & "!B" & MATCH('CALENDÁRIO aux'!W8,INDIRECT($S$6 &"!$B:$B"),0) + 3,'CALENDÁRIO aux'!W8) -> 5 | X8: =HYPERLINK("#" & $S$6 & "!B" & MATCH('CALENDÁRIO aux'!X8,INDIRECT($S$6 &"!$B:$B"),0) + 3,'CALENDÁRIO aux'!X8) -> 6 | Y8: =HYPERLINK("#" & $S$6 & "!B" & MATCH('CALENDÁRIO aux'!Y8,INDIRECT($S$6 &"!$B:$B"),0) + 3,'CALENDÁRIO aux'!Y8) -> 7 | AD8: =HYPERLINK("#" & $AA$6 & "!B" & MATCH('CALENDÁRIO aux'!AD8,INDIRECT($AA$6 &"!$B:$B"),0) + 3,'CALENDÁRIO aux'!AD8) -> 1 | AE8: =HYPERLINK("#" & $AA$6 & "!B" & MATCH('CALENDÁRIO aux'!AE8,INDIRECT($AA$6 &"!$B:$B"),0) + 3,'CALENDÁRIO aux'!AE8) -> 2 | AF8: =HYPERLINK("#" & $AA$6 & "!B" & MATCH('CALENDÁRIO aux'!AF8,INDIRECT($AA$6 &"!$B:$B"),0) + 3,'CALENDÁRIO aux'!AF8) -> 3 | AG8: =HYPERLINK("#" & $AA$6 & "!B" & MATCH('CALENDÁRIO aux'!AG8,INDIRECT($AA$6 &"!$B:$B"),0) + 3,'CALENDÁRIO aux'!AG8) -> 4
C9: =HYPERLINK("#" & $C$6 & "!B" & MATCH('CALENDÁRIO aux'!C9,INDIRECT($C$6 &"!$B:$B"),0) + 3,'CALENDÁRIO aux'!C9) -> 4 | D9: =HYPERLINK("#" & $C$6 & "!B" & MATCH('CALENDÁRIO aux'!D9,INDIRECT($C$6 &"!$B:$B"),0) + 3,'CALENDÁRIO aux'!D9) -> 5 | E9: =HYPERLINK("#" & $C$6 & "!B" & MATCH('CALENDÁRIO aux'!E9,INDIRECT($C$6 &"!$B:$B"),0) + 3,'CALENDÁRIO aux'!E9) -> 6 | F9: =HYPERLINK("#" & $C$6 & "!B" & MATCH('CALENDÁRIO aux'!F9,INDIRECT($C$6 &"!$B:$B"),0) + 3,'CALENDÁRIO aux'!F9) -> 7 | G9: =HYPERLINK("#" & $C$6 & "!B" & MATCH('CALENDÁRIO aux'!G9,INDIRECT($C$6 &"!$B:$B"),0) + 3,'CALENDÁRIO aux'!G9) -> 8 | H9: =HYPERLINK("#" & $C$6 & "!B" & MATCH('CALENDÁRIO aux'!H9,INDIRECT($C$6 &"!$B:$B"),0) + 3,'CALENDÁRIO aux'!H9) -> 9 | I9: =HYPERLINK("#" & $C$6 & "!B" & MATCH('CALENDÁRIO aux'!I9,INDIRECT($C$6 &"!$B:$B"),0) + 3,'CALENDÁRIO aux'!I9) -> 10 | K9: =HYPERLINK("#" & $K$6 & "!B" & MATCH('CALENDÁRIO aux'!K9,INDIRECT($K$6 &"!$B:$B"),0) + 3,'CALENDÁRIO aux'!K9) -> 8 | L9: =HYPERLINK("#" & $K$6 & "!B" & MATCH('CALENDÁRIO aux'!L9,INDIRECT($K$6 &"!$B:$B"),0) + 3,'CALENDÁRIO aux'!L9) -> 9 | M9: =HYPERLINK("#" & $K$6 & "!B" & MATCH('CALENDÁRIO aux'!M9,INDIRECT($K$6 &"!$B:$B"),0) + 3,'CALENDÁRIO aux'!M9) -> 10 | N9: =HYPERLINK("#" & $K$6 & "!B" & MATCH('CALENDÁRIO aux'!N9,INDIRECT($K$6 &"!$B:$B"),0) + 3,'CALENDÁRIO aux'!N9) -> 11 | O9: =HYPERLINK("#" & $K$6 & "!B" & MATCH('CALENDÁRIO aux'!O9,INDIRECT($K$6 &"!$B:$B"),0) + 3,'CALENDÁRIO aux'!O9) -> 12 | P9: =HYPERLINK("#" & $K$6 & "!B" & MATCH('CALENDÁRIO aux'!P9,INDIRECT($K$6 &"!$B:$B"),0) + 3,'CALENDÁRIO aux'!P9) -> 13 | Q9: =HYPERLINK("#" & $K$6 & "!B" & MATCH('CALENDÁRIO aux'!Q9,INDIRECT($K$6 &"!$B:$B"),0) + 3,'CALENDÁRIO aux'!Q9) -> 14 | S9: =HYPERLINK("#" & $S$6 & "!B" & MATCH('CALENDÁRIO aux'!S9,INDIRECT($S$6 &"!$B:$B"),0) + 3,'CALENDÁRIO aux'!S9) -> 8 | T9: =HYPERLINK("#" & $S$6 & "!B" & MATCH('CALENDÁRIO aux'!T9,INDIRECT($S$6 &"!$B:$B"),0) + 3,'CALENDÁRIO aux'!T9) -> 9 | U9: =HYPERLINK("#" & $S$6 & "!B" & MATCH('CALENDÁRIO aux'!U9,INDIRECT($S$6 &"!$B:$B"),0) + 3,'CALENDÁRIO aux'!U9) -> 10 | V9: =HYPERLINK("#" & $S$6 & "!B" & MATCH('CALENDÁRIO aux'!V9,INDIRECT($S$6 &"!$B:$B"),0) + 3,'CALENDÁRIO aux'!V9) -> 11 | W9: =HYPERLINK("#" & $S$6 & "!B" & MATCH('CALENDÁRIO aux'!W9,INDIRECT($S$6 &"!$B:$B"),0) + 3,'CALENDÁRIO aux'!W9) -> 12 | X9: =HYPERLINK("#" & $S$6 & "!B" & MATCH('CALENDÁRIO aux'!X9,INDIRECT($S$6 &"!$B:$B"),0) + 3,'CALENDÁRIO aux'!X9) -> 13 | Y9: =HYPERLINK("#" & $S$6 & "!B" & MATCH('CALENDÁRIO aux'!Y9,INDIRECT($S$6 &"!$B:$B"),0) + 3,'CALENDÁRIO aux'!Y9) -> 14 | AA9: =HYPERLINK("#" & $AA$6 & "!B" & MATCH('CALENDÁRIO aux'!AA9,INDIRECT($AA$6 &"!$B:$B"),0) + 3,'CALENDÁRIO aux'!AA9) -> 5 | AB9: =HYPERLINK("#" & $AA$6 & "!B" & MATCH('CALENDÁRIO aux'!AB9,INDIRECT($AA$6 &"!$B:$B"),0) + 3,'CALENDÁRIO aux'!AB9) -> 6 | AC9: =HYPERLINK("#" & $AA$6 & "!B" & MATCH('CALENDÁRIO aux'!AC9,INDIRECT($AA$6 &"!$B:$B"),0) + 3,'CALENDÁRIO aux'!AC9) -> 7 | AD9: =HYPERLINK("#" & $AA$6 & "!B" & MATCH('CALENDÁRIO aux'!AD9,INDIRECT($AA$6 &"!$B:$B"),0) + 3,'CALENDÁRIO aux'!AD9) -> 8 | AE9: =HYPERLINK("#" & $AA$6 & "!B" & MATCH('CALENDÁRIO aux'!AE9,INDIRECT($AA$6 &"!$B:$B"),0) + 3,'CALENDÁRIO aux'!AE9) -> 9 | AF9: =HYPERLINK("#" & $AA$6 & "!B" & MATCH('CALENDÁRIO aux'!AF9,INDIRECT($AA$6 &"!$B:$B"),0) + 3,'CALENDÁRIO aux'!AF9) -> 10 | AG9: =HYPERLINK("#" & $AA$6 & "!B" & MATCH('CALENDÁRIO aux'!AG9,INDIRECT($AA$6 &"!$B:$B"),0) + 3,'CALENDÁRIO aux'!AG9) -> 11
C10: =HYPERLINK("#" & $C$6 & "!B" & MATCH('CALENDÁRIO aux'!C10,INDIRECT($C$6 &"!$B:$B"),0) + 3,'CALENDÁRIO aux'!C10) -> 11 | D10: =HYPERLINK("#" & $C$6 & "!B" & MATCH('CALENDÁRIO aux'!D10,INDIRECT($C$6 &"!$B:$B"),0) + 3,'CALENDÁRIO aux'!D10) -> 12 | E10: =HYPERLINK("#" & $C$6 & "!B" & MATCH('CALENDÁRIO aux'!E10,INDIRECT($C$6 &"!$B:$B"),0) + 3,'CALENDÁRIO aux'!E10) -> 13 | F10: =HYPERLINK("#" & $C$6 & "!B" & MATCH('CALENDÁRIO aux'!F10,INDIRECT($C$6 &"!$B:$B"),0) + 3,'CALENDÁRIO aux'!F10) -> 14 | G10: =HYPERLINK("#" & $C$6 & "!B" & MATCH('CALENDÁRIO aux'!G10,INDIRECT($C$6 &"!$B:$B"),0) + 3,'CALENDÁRIO aux'!G10) -> 15 | H10: =HYPERLINK("#" & $C$6 & "!B" & MATCH('CALENDÁRIO aux'!H10,INDIRECT($C$6 &"!$B:$B"),0) + 3,'CALENDÁRIO aux'!H10) -> 16 | I10: =HYPERLINK("#" & $C$6 & "!B" & MATCH('CALENDÁRIO aux'!I10,INDIRECT($C$6 &"!$B:$B"),0) + 3,'CALENDÁRIO aux'!I10) -> 17 | K10: =HYPERLINK("#" & $K$6 & "!B" & MATCH('CALENDÁRIO aux'!K10,INDIRECT($K$6 &"!$B:$B"),0) + 3,'CALENDÁRIO aux'!K10) -> 15 | L10: =HYPERLINK("#" & $K$6 & "!B" & MATCH('CALENDÁRIO aux'!L10,INDIRECT($K$6 &"!$B:$B"),0) + 3,'CALENDÁRIO aux'!L10) -> 16 | M10: =HYPERLINK("#" & $K$6 & "!B" & MATCH('CALENDÁRIO aux'!M10,INDIRECT($K$6 &"!$B:$B"),0) + 3,'CALENDÁRIO aux'!M10) -> 17 | N10: =HYPERLINK("#" & $K$6 & "!B" & MATCH('CALENDÁRIO aux'!N10,INDIRECT($K$6 &"!$B:$B"),0) + 3,'CALENDÁRIO aux'!N10) -> 18 | O10: =HYPERLINK("#" & $K$6 & "!B" & MATCH('CALENDÁRIO aux'!O10,INDIRECT($K$6 &"!$B:$B"),0) + 3,'CALENDÁRIO aux'!O10) -> 19 | P10: =HYPERLINK("#" & $K$6 & "!B" & MATCH('CALENDÁRIO aux'!P10,INDIRECT($K$6 &"!$B:$B"),0) + 3,'CALENDÁRIO aux'!P10) -> 20 | Q10: =HYPERLINK("#" & $K$6 & "!B" & MATCH('CALENDÁRIO aux'!Q10,INDIRECT($K$6 &"!$B:$B"),0) + 3,'CALENDÁRIO aux'!Q10) -> 21 | S10: =HYPERLINK("#" & $S$6 & "!B" & MATCH('CALENDÁRIO aux'!S10,INDIRECT($S$6 &"!$B:$B"),0) + 3,'CALENDÁRIO aux'!S10) -> 15 | T10: =HYPERLINK("#" & $S$6 & "!B" & MATCH('CALENDÁRIO aux'!T10,INDIRECT($S$6 &"!$B:$B"),0) + 3,'CALENDÁRIO aux'!T10) -> 16 | U10: =HYPERLINK("#" & $S$6 & "!B" & MATCH('CALENDÁRIO aux'!U10,INDIRECT($S$6 &"!$B:$B"),0) + 3,'CALENDÁRIO aux'!U10) -> 17 | V10: =HYPERLINK("#" & $S$6 & "!B" & MATCH('CALENDÁRIO aux'!V10,INDIRECT($S$6 &"!$B:$B"),0) + 3,'CALENDÁRIO aux'!V10) -> 18 | W10: =HYPERLINK("#" & $S$6 & "!B" & MATCH('CALENDÁRIO aux'!W10,INDIRECT($S$6 &"!$B:$B"),0) + 3,'CALENDÁRIO aux'!W10) -> 19 | X10: =HYPERLINK("#" & $S$6 & "!B" & MATCH('CALENDÁRIO aux'!X10,INDIRECT($S$6 &"!$B:$B"),0) + 3,'CALENDÁRIO aux'!X10) -> 20 | Y10: =HYPERLINK("#" & $S$6 & "!B" & MATCH('CALENDÁRIO aux'!Y10,INDIRECT($S$6 &"!$B:$B"),0) + 3,'CALENDÁRIO aux'!Y10) -> 21 | AA10: =HYPERLINK("#" & $AA$6 & "!B" & MATCH('CALENDÁRIO aux'!AA10,INDIRECT($AA$6 &"!$B:$B"),0) + 3,'CALENDÁRIO aux'!AA10) -> 12 | AB10: =HYPERLINK("#" & $AA$6 & "!B" & MATCH('CALENDÁRIO aux'!AB10,INDIRECT($AA$6 &"!$B:$B"),0) + 3,'CALENDÁRIO aux'!AB10) -> 13 | AC10: =HYPERLINK("#" & $AA$6 & "!B" & MATCH('CALENDÁRIO aux'!AC10,INDIRECT($AA$6 &"!$B:$B"),0) + 3,'CALENDÁRIO aux'!AC10) -> 14 | AD10: =HYPERLINK("#" & $AA$6 & "!B" & MATCH('CALENDÁRIO aux'!AD10,INDIRECT($AA$6 &"!$B:$B"),0) + 3,'CALENDÁRIO aux'!AD10) -> 15 | AE10: =HYPERLINK("#" & $AA$6 & "!B" & MATCH('CALENDÁRIO aux'!AE10,INDIRECT($AA$6 &"!$B:$B"),0) + 3,'CALENDÁRIO aux'!AE10) -> 16 | AF10: =HYPERLINK("#" & $AA$6 & "!B" & MATCH('CALENDÁRIO aux'!AF10,INDIRECT($AA$6 &"!$B:$B"),0) + 3,'CALENDÁRIO aux'!AF10) -> 17 | AG10: =HYPERLINK("#" & $AA$6 & "!B" & MATCH('CALENDÁRIO aux'!AG10,INDIRECT($AA$6 &"!$B:$B"),0) + 3,'CALENDÁRIO aux'!AG10) -> 18
C11: =HYPERLINK("#" & $C$6 & "!B" & MATCH('CALENDÁRIO aux'!C11,INDIRECT($C$6 &"!$B:$B"),0) + 3,'CALENDÁRIO aux'!C11) -> 18 | D11: =HYPERLINK("#" & $C$6 & "!B" & MATCH('CALENDÁRIO aux'!D11,INDIRECT($C$6 &"!$B:$B"),0) + 3,'CALENDÁRIO aux'!D11) -> 19 | E11: =HYPERLINK("#" & $C$6 & "!B" & MATCH('CALENDÁRIO aux'!E11,INDIRECT($C$6 &"!$B:$B"),0) + 3,'CALENDÁRIO aux'!E11) -> 20 | F11: =HYPERLINK("#" & $C$6 & "!B" & MATCH('CALENDÁRIO aux'!F11,INDIRECT($C$6 &"!$B:$B"),0) + 3,'CALENDÁRIO aux'!F11) -> 21 | G11: =HYPERLINK("#" & $C$6 & "!B" & MATCH('CALENDÁRIO aux'!G11,INDIRECT($C$6 &"!$B:$B"),0) + 3,'CALENDÁRIO aux'!G11) -> 22 | H11: =HYPERLINK("#" & $C$6 & "!B" & MATCH('CALENDÁRIO aux'!H11,INDIRECT($C$6 &"!$B:$B"),0) + 3,'CALENDÁRIO aux'!H11) -> 23 | I11: =HYPERLINK("#" & $C$6 & "!B" & MATCH('CALENDÁRIO aux'!I11,INDIRECT($C$6 &"!$B:$B"),0) + 3,'CALENDÁRIO aux'!I11) -> 24 | K11: =HYPERLINK("#" & $K$6 & "!B" & MATCH('CALENDÁRIO aux'!K11,INDIRECT($K$6 &"!$B:$B"),0) + 3,'CALENDÁRIO aux'!K11) -> 22 | L11: =HYPERLINK("#" & $K$6 & "!B" & MATCH('CALENDÁRIO aux'!L11,INDIRECT($K$6 &"!$B:$B"),0) + 3,'CALENDÁRIO aux'!L11) -> 23 | M11: =HYPERLINK("#" & $K$6 & "!B" & MATCH('CALENDÁRIO aux'!M11,INDIRECT($K$6 &"!$B:$B"),0) + 3,'CALENDÁRIO aux'!M11) -> 24 | N11: =HYPERLINK("#" & $K$6 & "!B" & MATCH('CALENDÁRIO aux'!N11,INDIRECT($K$6 &"!$B:$B"),0) + 3,'CALENDÁRIO aux'!N11) -> 25 | O11: =HYPERLINK("#" & $K$6 & "!B" & MATCH('CALENDÁRIO aux'!O11,INDIRECT($K$6 &"!$B:$B"),0) + 3,'CALENDÁRIO aux'!O11) -> 26 | P11: =HYPERLINK("#" & $K$6 & "!B" & MATCH('CALENDÁRIO aux'!P11,INDIRECT($K$6 &"!$B:$B"),0) + 3,'CALENDÁRIO aux'!P11) -> 27 | Q11: =HYPERLINK("#" & $K$6 & "!B" & MATCH('CALENDÁRIO aux'!Q11,INDIRECT($K$6 &"!$B:$B"),0) + 3,'CALENDÁRIO aux'!Q11) -> 28 | S11: =HYPERLINK("#" & $S$6 & "!B" & MATCH('CALENDÁRIO aux'!S11,INDIRECT($S$6 &"!$B:$B"),0) + 3,'CALENDÁRIO aux'!S11) -> 22 | T11: =HYPERLINK("#" & $S$6 & "!B" & MATCH('CALENDÁRIO aux'!T11,INDIRECT($S$6 &"!$B:$B"),0) + 3,'CALENDÁRIO aux'!T11) -> 23 | U11: =HYPERLINK("#" & $S$6 & "!B" & MATCH('CALENDÁRIO aux'!U11,INDIRECT($S$6 &"!$B:$B"),0) + 3,'CALENDÁRIO aux'!U11) -> 24 | V11: =HYPERLINK("#" & $S$6 & "!B" & MATCH('CALENDÁRIO aux'!V11,INDIRECT($S$6 &"!$B:$B"),0) + 3,'CALENDÁRIO aux'!V11) -> 25 | W11: =HYPERLINK("#" & $S$6 & "!B" & MATCH('CALENDÁRIO aux'!W11,INDIRECT($S$6 &"!$B:$B"),0) + 3,'CALENDÁRIO aux'!W11) -> 26 | X11: =HYPERLINK("#" & $S$6 & "!B" & MATCH('CALENDÁRIO aux'!X11,INDIRECT($S$6 &"!$B:$B"),0) + 3,'CALENDÁRIO aux'!X11) -> 27 | Y11: =HYPERLINK("#" & $S$6 & "!B" & MATCH('CALENDÁRIO aux'!Y11,INDIRECT($S$6 &"!$B:$B"),0) + 3,'CALENDÁRIO aux'!Y11) -> 28 | AA11: =HYPERLINK("#" & $AA$6 & "!B" & MATCH('CALENDÁRIO aux'!AA11,INDIRECT($AA$6 &"!$B:$B"),0) + 3,'CALENDÁRIO aux'!AA11) -> 19 | AB11: =HYPERLINK("#" & $AA$6 & "!B" & MATCH('CALENDÁRIO aux'!AB11,INDIRECT($AA$6 &"!$B:$B"),0) + 3,'CALENDÁRIO aux'!AB11) -> 20 | AC11: =HYPERLINK("#" & $AA$6 & "!B" & MATCH('CALENDÁRIO aux'!AC11,INDIRECT($AA$6 &"!$B:$B"),0) + 3,'CALENDÁRIO aux'!AC11) -> 21 | AD11: =HYPERLINK("#" & $AA$6 & "!B" & MATCH('CALENDÁRIO aux'!AD11,INDIRECT($AA$6 &"!$B:$B"),0) + 3,'CALENDÁRIO aux'!AD11) -> 22 | AE11: =HYPERLINK("#" & $AA$6 & "!B" & MATCH('CALENDÁRIO aux'!AE11,INDIRECT($AA$6 &"!$B:$B"),0) + 3,'CALENDÁRIO aux'!AE11) -> 23 | AF11: =HYPERLINK("#" & $AA$6 & "!B" & MATCH('CALENDÁRIO aux'!AF11,INDIRECT($AA$6 &"!$B:$B"),0) + 3,'CALENDÁRIO aux'!AF11) -> 24 | AG11: =HYPERLINK("#" & $AA$6 & "!B" & MATCH('CALENDÁRIO aux'!AG11,INDIRECT($AA$6 &"!$B:$B"),0) + 3,'CALENDÁRIO aux'!AG11) -> 25
C12: =HYPERLINK("#" & $C$6 & "!B" & MATCH('CALENDÁRIO aux'!C12,INDIRECT($C$6 &"!$B:$B"),0) + 3,'CALENDÁRIO aux'!C12) -> 25 | D12: =HYPERLINK("#" & $C$6 & "!B" & MATCH('CALENDÁRIO aux'!D12,INDIRECT($C$6 &"!$B:$B"),0) + 3,'CALENDÁRIO aux'!D12) -> 26 | E12: =HYPERLINK("#" & $C$6 & "!B" & MATCH('CALENDÁRIO aux'!E12,INDIRECT($C$6 &"!$B:$B"),0) + 3,'CALENDÁRIO aux'!E12) -> 27 | F12: =HYPERLINK("#" & $C$6 & "!B" & MATCH('CALENDÁRIO aux'!F12,INDIRECT($C$6 &"!$B:$B"),0) + 3,'CALENDÁRIO aux'!F12) -> 28 | G12: =HYPERLINK("#" & $C$6 & "!B" & MATCH('CALENDÁRIO aux'!G12,INDIRECT($C$6 &"!$B:$B"),0) + 3,'CALENDÁRIO aux'!G12) -> 29 | H12: =HYPERLINK("#" & $C$6 & "!B" & MATCH('CALENDÁRIO aux'!H12,INDIRECT($C$6 &"!$B:$B"),0) + 3,'CALENDÁRIO aux'!H12) -> 30 | I12: =HYPERLINK("#" & $C$6 & "!B" & MATCH('CALENDÁRIO aux'!I12,INDIRECT($C$6 &"!$B:$B"),0) + 3,'CALENDÁRIO aux'!I12) -> 31 | S12: =HYPERLINK("#" & $S$6 & "!B" & MATCH('CALENDÁRIO aux'!S12,INDIRECT($S$6 &"!$B:$B"),0) + 3,'CALENDÁRIO aux'!S12) -> 29 | T12: =HYPERLINK("#" & $S$6 & "!B" & MATCH('CALENDÁRIO aux'!T12,INDIRECT($S$6 &"!$B:$B"),0) + 3,'CALENDÁRIO aux'!T12) -> 30 | U12: =HYPERLINK("#" & $S$6 & "!B" & MATCH('CALENDÁRIO aux'!U12,INDIRECT($S$6 &"!$B:$B"),0) + 3,'CALENDÁRIO aux'!U12) -> 31 | AA12: =HYPERLINK("#" & $AA$6 & "!B" & MATCH('CALENDÁRIO aux'!AA12,INDIRECT($AA$6 &"!$B:$B"),0) + 3,'CALENDÁRIO aux'!AA12) -> 26 | AB12: =HYPERLINK("#" & $AA$6 & "!B" & MATCH('CALENDÁRIO aux'!AB12,INDIRECT($AA$6 &"!$B:$B"),0) + 3,'CALENDÁRIO aux'!AB12) -> 27 | AC12: =HYPERLINK("#" & $AA$6 & "!B" & MATCH('CALENDÁRIO aux'!AC12,INDIRECT($AA$6 &"!$B:$B"),0) + 3,'CALENDÁRIO aux'!AC12) -> 28 | AD12: =HYPERLINK("#" & $AA$6 & "!B" & MATCH('CALENDÁRIO aux'!AD12,INDIRECT($AA$6 &"!$B:$B"),0) + 3,'CALENDÁRIO aux'!AD12) -> 29 | AE12: =HYPERLINK("#" & $AA$6 & "!B" & MATCH('CALENDÁRIO aux'!AE12,INDIRECT($AA$6 &"!$B:$B"),0) + 3,'CALENDÁRIO aux'!AE12) -> 30
C14: 1 | D14: Confraternização Universal | K14: 16 | L14: Carnaval | AA14: 2 | AB14: Paixão
K15: 17 | L15: Cinzas | AA15: 21 | AB15: Tiradentes
C17: MAIO | K17: JUNHO | S17: JULHO | AA17: AGOSTO
C18: S | D18: T | E18: Q | F18: Q | G18: S | H18: S | I18: D | K18: S | L18: T | M18: Q | N18: Q | O18: S | P18: S | Q18: D | S18: S | T18: T | U18: Q | V18: Q | W18: S | X18: S | Y18: D | AA18: S | AB18: T | AC18: Q | AD18: Q | AE18: S | AF18: S | AG18: D
H19: =HYPERLINK("#" & $C$17 & "!B" & MATCH('CALENDÁRIO aux'!H19,INDIRECT($C$17 &"!$B:$B"),0) + 3,'CALENDÁRIO aux'!H19) -> 1 | I19: =HYPERLINK("#" & $C$17 & "!B" & MATCH('CALENDÁRIO aux'!I19,INDIRECT($C$17 &"!$B:$B"),0) + 3,'CALENDÁRIO aux'!I19) -> 2 | L19: =HYPERLINK("#" & $K$17 & "!B" & MATCH('CALENDÁRIO aux'!L19,INDIRECT($K$17 &"!$B:$B"),0) + 3,'CALENDÁRIO aux'!L19) -> 1 | M19: =HYPERLINK("#" & $K$17 & "!B" & MATCH('CALENDÁRIO aux'!M19,INDIRECT($K$17 &"!$B:$B"),0) + 3,'CALENDÁRIO aux'!M19) -> 2 | N19: =HYPERLINK("#" & $K$17 & "!B" & MATCH('CALENDÁRIO aux'!N19,INDIRECT($K$17 &"!$B:$B"),0) + 3,'CALENDÁRIO aux'!N19) -> 3 | O19: =HYPERLINK("#" & $K$17 & "!B" & MATCH('CALENDÁRIO aux'!O19,INDIRECT($K$17 &"!$B:$B"),0) + 3,'CALENDÁRIO aux'!O19) -> 4 | P19: =HYPERLINK("#" & $K$17 & "!B" & MATCH('CALENDÁRIO aux'!P19,INDIRECT($K$17 &"!$B:$B"),0) + 3,'CALENDÁRIO aux'!P19) -> 5 | Q19: =HYPERLINK("#" & $K$17 & "!B" & MATCH('CALENDÁRIO aux'!Q19,INDIRECT($K$17 &"!$B:$B"),0) + 3,'CALENDÁRIO aux'!Q19) -> 6 | V19: =HYPERLINK("#" & $S$17 & "!B" & MATCH('CALENDÁRIO aux'!V19,INDIRECT($S$17 &"!$B:$B"),0) + 3,'CALENDÁRIO aux'!V19) -> 1 | W19: =HYPERLINK("#" & $S$17 & "!B" & MATCH('CALENDÁRIO aux'!W19,INDIRECT($S$17 &"!$B:$B"),0) + 3,'CALENDÁRIO aux'!W19) -> 2 | X19: =HYPERLINK("#" & $S$17 & "!B" & MATCH('CALENDÁRIO aux'!X19,INDIRECT($S$17 &"!$B:$B"),0) + 3,'CALENDÁRIO aux'!X19) -> 3 | Y19: =HYPERLINK("#" & $S$17 & "!B" & MATCH('CALENDÁRIO aux'!Y19,INDIRECT($S$17 &"!$B:$B"),0) + 3,'CALENDÁRIO aux'!Y19) -> 4 | AG19: =HYPERLINK("#" & $AA$17 & "!B" & MATCH('CALENDÁRIO aux'!AG19,INDIRECT($AA$17 &"!$B:$B"),0) + 3,'CALENDÁRIO aux'!AG19) -> 1
C20: =HYPERLINK("#" & $C$17 & "!B" & MATCH('CALENDÁRIO aux'!C20,INDIRECT($C$17 &"!$B:$B"),0) + 3,'CALENDÁRIO aux'!C20) -> 3 | D20: =HYPERLINK("#" & $C$17 & "!B" & MATCH('CALENDÁRIO aux'!D20,INDIRECT($C$17 &"!$B:$B"),0) + 3,'CALENDÁRIO aux'!D20) -> 4 | E20: =HYPERLINK("#" & $C$17 & "!B" & MATCH('CALENDÁRIO aux'!E20,INDIRECT($C$17 &"!$B:$B"),0) + 3,'CALENDÁRIO aux'!E20) -> 5 | F20: =HYPERLINK("#" & $C$17 & "!B" & MATCH('CALENDÁRIO aux'!F20,INDIRECT($C$17 &"!$B:$B"),0) + 3,'CALENDÁRIO aux'!F20) -> 6 | G20: =HYPERLINK("#" & $C$17 & "!B" & MATCH('CALENDÁRIO aux'!G20,INDIRECT($C$17 &"!$B:$B"),0) + 3,'CALENDÁRIO aux'!G20) -> 7 | H20: =HYPERLINK("#" & $C$17 & "!B" & MATCH('CALENDÁRIO aux'!H20,INDIRECT($C$17 &"!$B:$B"),0) + 3,'CALENDÁRIO aux'!H20) -> 8 | I20: =HYPERLINK("#" & $C$17 & "!B" & MATCH('CALENDÁRIO aux'!I20,INDIRECT($C$17 &"!$B:$B"),0) + 3,'CALENDÁRIO aux'!I20) -> 9 | K20: =HYPERLINK("#" & $K$17 & "!B" & MATCH('CALENDÁRIO aux'!K20,INDIRECT($K$17 &"!$B:$B"),0) + 3,'CALENDÁRIO aux'!K20) -> 7 | L20: =HYPERLINK("#" & $K$17 & "!B" & MATCH('CALENDÁRIO aux'!L20,INDIRECT($K$17 &"!$B:$B"),0) + 3,'CALENDÁRIO aux'!L20) -> 8 | M20: =HYPERLINK("#" & $K$17 & "!B" & MATCH('CALENDÁRIO aux'!M20,INDIRECT($K$17 &"!$B:$B"),0) + 3,'CALENDÁRIO aux'!M20) -> 9 | N20: =HYPERLINK("#" & $K$17 & "!B" & MATCH('CALENDÁRIO aux'!N20,INDIRECT($K$17 &"!$B:$B"),0) + 3,'CALENDÁRIO aux'!N20) -> 10 | O20: =HYPERLINK("#" & $K$17 & "!B" & MATCH('CALENDÁRIO aux'!O20,INDIRECT($K$17 &"!$B:$B"),0) + 3,'CALENDÁRIO aux'!O20) -> 11 | P20: =HYPERLINK("#" & $K$17 & "!B" & MATCH('CALENDÁRIO aux'!P20,INDIRECT($K$17 &"!$B:$B"),0) + 3,'CALENDÁRIO aux'!P20) -> 12 | Q20: =HYPERLINK("#" & $K$17 & "!B" & MATCH('CALENDÁRIO aux'!Q20,INDIRECT($K$17 &"!$B:$B"),0) + 3,'CALENDÁRIO aux'!Q20) -> 13 | S20: =HYPERLINK("#" & $S$17 & "!B" & MATCH('CALENDÁRIO aux'!S20,INDIRECT($S$17 &"!$B:$B"),0) + 3,'CALENDÁRIO aux'!S20) -> 5 | T20: =HYPERLINK("#" & $S$17 & "!B" & MATCH('CALENDÁRIO aux'!T20,INDIRECT($S$17 &"!$B:$B"),0) + 3,'CALENDÁRIO aux'!T20) -> 6 | U20: =HYPERLINK("#" & $S$17 & "!B" & MATCH('CALENDÁRIO aux'!U20,INDIRECT($S$17 &"!$B:$B"),0) + 3,'CALENDÁRIO aux'!U20) -> 7 | V20: =HYPERLINK("#" & $S$17 & "!B" & MATCH('CALENDÁRIO aux'!V20,INDIRECT($S$17 &"!$B:$B"),0) + 3,'CALENDÁRIO aux'!V20) -> 8 | W20: =HYPERLINK("#" & $S$17 & "!B" & MATCH('CALENDÁRIO aux'!W20,INDIRECT($S$17 &"!$B:$B"),0) + 3,'CALENDÁRIO aux'!W20) -> 9 | X20: =HYPERLINK("#" & $S$17 & "!B" & MATCH('CALENDÁRIO aux'!X20,INDIRECT($S$17 &"!$B:$B"),0) + 3,'CALENDÁRIO aux'!X20) -> 10 | Y20: =HYPERLINK("#" & $S$17 & "!B" & MATCH('CALENDÁRIO aux'!Y20,INDIRECT($S$17 &"!$B:$B"),0) + 3,'CALENDÁRIO aux'!Y20) -> 11 | AA20: =HYPERLINK("#" & $AA$17 & "!B" & MATCH('CALENDÁRIO aux'!AA20,INDIRECT($AA$17 &"!$B:$B"),0) + 3,'CALENDÁRIO aux'!AA20) -> 2 | AB20: =HYPERLINK("#" & $AA$17 & "!B" & MATCH('CALENDÁRIO aux'!AB20,INDIRECT($AA$17 &"!$B:$B"),0) + 3,'CALENDÁRIO aux'!AB20) -> 3 | AC20: =HYPERLINK("#" & $AA$17 & "!B" & MATCH('CALENDÁRIO aux'!AC20,INDIRECT($AA$17 &"!$B:$B"),0) + 3,'CALENDÁRIO aux'!AC20) -> 4 | AD20: =HYPERLINK("#" & $AA$17 & "!B" & MATCH('CALENDÁRIO aux'!AD20,INDIRECT($AA$17 &"!$B:$B"),0) + 3,'CALENDÁRIO aux'!AD20) -> 5 | AE20: =HYPERLINK("#" & $AA$17 & "!B" & MATCH('CALENDÁRIO aux'!AE20,INDIRECT($AA$17 &"!$B:$B"),0) + 3,'CALENDÁRIO aux'!AE20) -> 6 | AF20: =HYPERLINK("#" & $AA$17 & "!B" & MATCH('CALENDÁRIO aux'!AF20,INDIRECT($AA$17 &"!$B:$B"),0) + 3,'CALENDÁRIO aux'!AF20) -> 7 | AG20: =HYPERLINK("#" & $AA$17 & "!B" & MATCH('CALENDÁRIO aux'!AG20,INDIRECT($AA$17 &"!$B:$B"),0) + 3,'CALENDÁRIO aux'!AG20) -> 8
C21: =HYPERLINK("#" & $C$17 & "!B" & MATCH('CALENDÁRIO aux'!C21,INDIRECT($C$17 &"!$B:$B"),0) + 3,'CALENDÁRIO aux'!C21) -> 10 | D21: =HYPERLINK("#" & $C$17 & "!B" & MATCH('CALENDÁRIO aux'!D21,INDIRECT($C$17 &"!$B:$B"),0) + 3,'CALENDÁRIO aux'!D21) -> 11 | E21: =HYPERLINK("#" & $C$17 & "!B" & MATCH('CALENDÁRIO aux'!E21,INDIRECT($C$17 &"!$B:$B"),0) + 3,'CALENDÁRIO aux'!E21) -> 12 | F21: =HYPERLINK("#" & $C$17 & "!B" & MATCH('CALENDÁRIO aux'!F21,INDIRECT($C$17 &"!$B:$B"),0) + 3,'CALENDÁRIO aux'!F21) -> 13 | G21: =HYPERLINK("#" & $C$17 & "!B" & MATCH('CALENDÁRIO aux'!G21,INDIRECT($C$17 &"!$B:$B"),0) + 3,'CALENDÁRIO aux'!G21) -> 14 | H21: =HYPERLINK("#" & $C$17 & "!B" & MATCH('CALENDÁRIO aux'!H21,INDIRECT($C$17 &"!$B:$B"),0) + 3,'CALENDÁRIO aux'!H21) -> 15 | I21: =HYPERLINK("#" & $C$17 & "!B" & MATCH('CALENDÁRIO aux'!I21,INDIRECT($C$17 &"!$B:$B"),0) + 3,'CALENDÁRIO aux'!I21) -> 16 | K21: =HYPERLINK("#" & $K$17 & "!B" & MATCH('CALENDÁRIO aux'!K21,INDIRECT($K$17 &"!$B:$B"),0) + 3,'CALENDÁRIO aux'!K21) -> 14 | L21: =HYPERLINK("#" & $K$17 & "!B" & MATCH('CALENDÁRIO aux'!L21,INDIRECT($K$17 &"!$B:$B"),0) + 3,'CALENDÁRIO aux'!L21) -> 15 | M21: =HYPERLINK("#" & $K$17 & "!B" & MATCH('CALENDÁRIO aux'!M21,INDIRECT($K$17 &"!$B:$B"),0) + 3,'CALENDÁRIO aux'!M21) -> 16 | N21: =HYPERLINK("#" & $K$17 & "!B" & MATCH('CALENDÁRIO aux'!N21,INDIRECT($K$17 &"!$B:$B"),0) + 3,'CALENDÁRIO aux'!N21) -> 17 | O21: =HYPERLINK("#" & $K$17 & "!B" & MATCH('CALENDÁRIO aux'!O21,INDIRECT($K$17 &"!$B:$B"),0) + 3,'CALENDÁRIO aux'!O21) -> 18 | P21: =HYPERLINK("#" & $K$17 & "!B" & MATCH('CALENDÁRIO aux'!P21,INDIRECT($K$17 &"!$B:$B"),0) + 3,'CALENDÁRIO aux'!P21) -> 19 | Q21: =HYPERLINK("#" & $K$17 & "!B" & MATCH('CALENDÁRIO aux'!Q21,INDIRECT($K$17 &"!$B:$B"),0) + 3,'CALENDÁRIO aux'!Q21) -> 20 | S21: =HYPERLINK("#" & $S$17 & "!B" & MATCH('CALENDÁRIO aux'!S21,INDIRECT($S$17 &"!$B:$B"),0) + 3,'CALENDÁRIO aux'!S21) -> 12 | T21: =HYPERLINK("#" & $S$17 & "!B" & MATCH('CALENDÁRIO aux'!T21,INDIRECT($S$17 &"!$B:$B"),0) + 3,'CALENDÁRIO aux'!T21) -> 13 | U21: =HYPERLINK("#" & $S$17 & "!B" & MATCH('CALENDÁRIO aux'!U21,INDIRECT($S$17 &"!$B:$B"),0) + 3,'CALENDÁRIO aux'!U21) -> 14 | V21: =HYPERLINK("#" & $S$17 & "!B" & MATCH('CALENDÁRIO aux'!V21,INDIRECT($S$17 &"!$B:$B"),0) + 3,'CALENDÁRIO aux'!V21) -> 15 | W21: =HYPERLINK("#" & $S$17 & "!B" & MATCH('CALENDÁRIO aux'!W21,INDIRECT($S$17 &"!$B:$B"),0) + 3,'CALENDÁRIO aux'!W21) -> 16 | X21: =HYPERLINK("#" & $S$17 & "!B" & MATCH('CALENDÁRIO aux'!X21,INDIRECT($S$17 &"!$B:$B"),0) + 3,'CALENDÁRIO aux'!X21) -> 17 | Y21: =HYPERLINK("#" & $S$17 & "!B" & MATCH('CALENDÁRIO aux'!Y21,INDIRECT($S$17 &"!$B:$B"),0) + 3,'CALENDÁRIO aux'!Y21) -> 18 | AA21: =HYPERLINK("#" & $AA$17 & "!B" & MATCH('CALENDÁRIO aux'!AA21,INDIRECT($AA$17 &"!$B:$B"),0) + 3,'CALENDÁRIO aux'!AA21) -> 9 | AB21: =HYPERLINK("#" & $AA$17 & "!B" & MATCH('CALENDÁRIO aux'!AB21,INDIRECT($AA$17 &"!$B:$B"),0) + 3,'CALENDÁRIO aux'!AB21) -> 10 | AC21: =HYPERLINK("#" & $AA$17 & "!B" & MATCH('CALENDÁRIO aux'!AC21,INDIRECT($AA$17 &"!$B:$B"),0) + 3,'CALENDÁRIO aux'!AC21) -> 11 | AD21: =HYPERLINK("#" & $AA$17 & "!B" & MATCH('CALENDÁRIO aux'!AD21,INDIRECT($AA$17 &"!$B:$B"),0) + 3,'CALENDÁRIO aux'!AD21) -> 12 | AE21: =HYPERLINK("#" & $AA$17 & "!B" & MATCH('CALENDÁRIO aux'!AE21,INDIRECT($AA$17 &"!$B:$B"),0) + 3,'CALENDÁRIO aux'!AE21) -> 13 | AF21: =HYPERLINK("#" & $AA$17 & "!B" & MATCH('CALENDÁRIO aux'!AF21,INDIRECT($AA$17 &"!$B:$B"),0) + 3,'CALENDÁRIO aux'!AF21) -> 14 | AG21: =HYPERLINK("#" & $AA$17 & "!B" & MATCH('CALENDÁRIO aux'!AG21,INDIRECT($AA$17 &"!$B:$B"),0) + 3,'CALENDÁRIO aux'!AG21) -> 15
C22: =HYPERLINK("#" & $C$17 & "!B" & MATCH('CALENDÁRIO aux'!C22,INDIRECT($C$17 &"!$B:$B"),0) + 3,'CALENDÁRIO aux'!C22) -> 17 | D22: =HYPERLINK("#" & $C$17 & "!B" & MATCH('CALENDÁRIO aux'!D22,INDIRECT($C$17 &"!$B:$B"),0) + 3,'CALENDÁRIO aux'!D22) -> 18 | E22: =HYPERLINK("#" & $C$17 & "!B" & MATCH('CALENDÁRIO aux'!E22,INDIRECT($C$17 &"!$B:$B"),0) + 3,'CALENDÁRIO aux'!E22) -> 19 | F22: =HYPERLINK("#" & $C$17 & "!B" & MATCH('CALENDÁRIO aux'!F22,INDIRECT($C$17 &"!$B:$B"),0) + 3,'CALENDÁRIO aux'!F22) -> 20 | G22: =HYPERLINK("#" & $C$17 & "!B" & MATCH('CALENDÁRIO aux'!G22,INDIRECT($C$17 &"!$B:$B"),0) + 3,'CALENDÁRIO aux'!G22) -> 21 | H22: =HYPERLINK("#" & $C$17 & "!B" & MATCH('CALENDÁRIO aux'!H22,INDIRECT($C$17 &"!$B:$B"),0) + 3,'CALENDÁRIO aux'!H22) -> 22 | I22: =HYPERLINK("#" & $C$17 & "!B" & MATCH('CALENDÁRIO aux'!I22,INDIRECT($C$17 &"!$B:$B"),0) + 3,'CALENDÁRIO aux'!I22) -> 23 | K22: =HYPERLINK("#" & $K$17 & "!B" & MATCH('CALENDÁRIO aux'!K22,INDIRECT($K$17 &"!$B:$B"),0) + 3,'CALENDÁRIO aux'!K22) -> 21 | L22: =HYPERLINK("#" & $K$17 & "!B" & MATCH('CALENDÁRIO aux'!L22,INDIRECT($K$17 &"!$B:$B"),0) + 3,'CALENDÁRIO aux'!L22) -> 22 | M22: =HYPERLINK("#" & $K$17 & "!B" & MATCH('CALENDÁRIO aux'!M22,INDIRECT($K$17 &"!$B:$B"),0) + 3,'CALENDÁRIO aux'!M22) -> 23 | N22: =HYPERLINK("#" & $K$17 & "!B" & MATCH('CALENDÁRIO aux'!N22,INDIRECT($K$17 &"!$B:$B"),0) + 3,'CALENDÁRIO aux'!N22) -> 24 | O22: =HYPERLINK("#" & $K$17 & "!B" & MATCH('CALENDÁRIO aux'!O22,INDIRECT($K$17 &"!$B:$B"),0) + 3,'CALENDÁRIO aux'!O22) -> 25 | P22: =HYPERLINK("#" & $K$17 & "!B" & MATCH('CALENDÁRIO aux'!P22,INDIRECT($K$17 &"!$B:$B"),0) + 3,'CALENDÁRIO aux'!P22) -> 26 | Q22: =HYPERLINK("#" & $K$17 & "!B" & MATCH('CALENDÁRIO aux'!Q22,INDIRECT($K$17 &"!$B:$B"),0) + 3,'CALENDÁRIO aux'!Q22) -> 27 | S22: =HYPERLINK("#" & $S$17 & "!B" & MATCH('CALENDÁRIO aux'!S22,INDIRECT($S$17 &"!$B:$B"),0) + 3,'CALENDÁRIO aux'!S22) -> 19 | T22: =HYPERLINK("#" & $S$17 & "!B" & MATCH('CALENDÁRIO aux'!T22,INDIRECT($S$17 &"!$B:$B"),0) + 3,'CALENDÁRIO aux'!T22) -> 20 | U22: =HYPERLINK("#" & $S$17 & "!B" & MATCH('CALENDÁRIO aux'!U22,INDIRECT($S$17 &"!$B:$B"),0) + 3,'CALENDÁRIO aux'!U22) -> 21 | V22: =HYPERLINK("#" & $S$17 & "!B" & MATCH('CALENDÁRIO aux'!V22,INDIRECT($S$17 &"!$B:$B"),0) + 3,'CALENDÁRIO aux'!V22) -> 22 | W22: =HYPERLINK("#" & $S$17 & "!B" & MATCH('CALENDÁRIO aux'!W22,INDIRECT($S$17 &"!$B:$B"),0) + 3,'CALENDÁRIO aux'!W22) -> 23 | X22: =HYPERLINK("#" & $S$17 & "!B" & MATCH('CALENDÁRIO aux'!X22,INDIRECT($S$17 &"!$B:$B"),0) + 3,'CALENDÁRIO aux'!X22) -> 24 | Y22: =HYPERLINK("#" & $S$17 & "!B" & MATCH('CALENDÁRIO aux'!Y22,INDIRECT($S$17 &"!$B:$B"),0) + 3,'CALENDÁRIO aux'!Y22) -> 25 | AA22: =HYPERLINK("#" & $AA$17 & "!B" & MATCH('CALENDÁRIO aux'!AA22,INDIRECT($AA$17 &"!$B:$B"),0) + 3,'CALENDÁRIO aux'!AA22) -> 16 | AB22: =HYPERLINK("#" & $AA$17 & "!B" & MATCH('CALENDÁRIO aux'!AB22,INDIRECT($AA$17 &"!$B:$B"),0) + 3,'CALENDÁRIO aux'!AB22) -> 17 | AC22: =HYPERLINK("#" & $AA$17 & "!B" & MATCH('CALENDÁRIO aux'!AC22,INDIRECT($AA$17 &"!$B:$B"),0) + 3,'CALENDÁRIO aux'!AC22) -> 18 | AD22: =HYPERLINK("#" & $AA$17 & "!B" & MATCH('CALENDÁRIO aux'!AD22,INDIRECT($AA$17 &"!$B:$B"),0) + 3,'CALENDÁRIO aux'!AD22) -> 19 | AE22: =HYPERLINK("#" & $AA$17 & "!B" & MATCH('CALENDÁRIO aux'!AE22,INDIRECT($AA$17 &"!$B:$B"),0) + 3,'CALENDÁRIO aux'!AE22) -> 20 | AF22: =HYPERLINK("#" & $AA$17 & "!B" & MATCH('CALENDÁRIO aux'!AF22,INDIRECT($AA$17 &"!$B:$B"),0) + 3,'CALENDÁRIO aux'!AF22) -> 21 | AG22: =HYPERLINK("#" & $AA$17 & "!B" & MATCH('CALENDÁRIO aux'!AG22,INDIRECT($AA$17 &"!$B:$B"),0) + 3,'CALENDÁRIO aux'!AG22) -> 22
C23: =HYPERLINK("#" & $C$17 & "!B" & MATCH('CALENDÁRIO aux'!C23,INDIRECT($C$17 &"!$B:$B"),0) + 3,'CALENDÁRIO aux'!C23) -> 24 | D23: =HYPERLINK("#" & $C$17 & "!B" & MATCH('CALENDÁRIO aux'!D23,INDIRECT($C$17 &"!$B:$B"),0) + 3,'CALENDÁRIO aux'!D23) -> 25 | E23: =HYPERLINK("#" & $C$17 & "!B" & MATCH('CALENDÁRIO aux'!E23,INDIRECT($C$17 &"!$B:$B"),0) + 3,'CALENDÁRIO aux'!E23) -> 26 | F23: =HYPERLINK("#" & $C$17 & "!B" & MATCH('CALENDÁRIO aux'!F23,INDIRECT($C$17 &"!$B:$B"),0) + 3,'CALENDÁRIO aux'!F23) -> 27 | G23: =HYPERLINK("#" & $C$17 & "!B" & MATCH('CALENDÁRIO aux'!G23,INDIRECT($C$17 &"!$B:$B"),0) + 3,'CALENDÁRIO aux'!G23) -> 28 | H23: =HYPERLINK("#" & $C$17 & "!B" & MATCH('CALENDÁRIO aux'!H23,INDIRECT($C$17 &"!$B:$B"),0) + 3,'CALENDÁRIO aux'!H23) -> 29 | I23: =HYPERLINK("#" & $C$17 & "!B" & MATCH('CALENDÁRIO aux'!I23,INDIRECT($C$17 &"!$B:$B"),0) + 3,'CALENDÁRIO aux'!I23) -> 30 | K23: =HYPERLINK("#" & $K$17 & "!B" & MATCH('CALENDÁRIO aux'!K23,INDIRECT($K$17 &"!$B:$B"),0) + 3,'CALENDÁRIO aux'!K23) -> 28 | L23: =HYPERLINK("#" & $K$17 & "!B" & MATCH('CALENDÁRIO aux'!L23,INDIRECT($K$17 &"!$B:$B"),0) + 3,'CALENDÁRIO aux'!L23) -> 29 | M23: =HYPERLINK("#" & $K$17 & "!B" & MATCH('CALENDÁRIO aux'!M23,INDIRECT($K$17 &"!$B:$B"),0) + 3,'CALENDÁRIO aux'!M23) -> 30 | S23: =HYPERLINK("#" & $S$17 & "!B" & MATCH('CALENDÁRIO aux'!S23,INDIRECT($S$17 &"!$B:$B"),0) + 3,'CALENDÁRIO aux'!S23) -> 26 | T23: =HYPERLINK("#" & $S$17 & "!B" & MATCH('CALENDÁRIO aux'!T23,INDIRECT($S$17 &"!$B:$B"),0) + 3,'CALENDÁRIO aux'!T23) -> 27 | U23: =HYPERLINK("#" & $S$17 & "!B" & MATCH('CALENDÁRIO aux'!U23,INDIRECT($S$17 &"!$B:$B"),0) + 3,'CALENDÁRIO aux'!U23) -> 28 | V23: =HYPERLINK("#" & $S$17 & "!B" & MATCH('CALENDÁRIO aux'!V23,INDIRECT($S$17 &"!$B:$B"),0) + 3,'CALENDÁRIO aux'!V23) -> 29 | W23: =HYPERLINK("#" & $S$17 & "!B" & MATCH('CALENDÁRIO aux'!W23,INDIRECT($S$17 &"!$B:$B"),0) + 3,'CALENDÁRIO aux'!W23) -> 30 | X23: =HYPERLINK("#" & $S$17 & "!B" & MATCH('CALENDÁRIO aux'!X23,INDIRECT($S$17 &"!$B:$B"),0) + 3,'CALENDÁRIO aux'!X23) -> 31 | AA23: =HYPERLINK("#" & $AA$17 & "!B" & MATCH('CALENDÁRIO aux'!AA23,INDIRECT($AA$17 &"!$B:$B"),0) + 3,'CALENDÁRIO aux'!AA23) -> 23 | AB23: =HYPERLINK("#" & $AA$17 & "!B" & MATCH('CALENDÁRIO aux'!AB23,INDIRECT($AA$17 &"!$B:$B"),0) + 3,'CALENDÁRIO aux'!AB23) -> 24 | AC23: =HYPERLINK("#" & $AA$17 & "!B" & MATCH('CALENDÁRIO aux'!AC23,INDIRECT($AA$17 &"!$B:$B"),0) + 3,'CALENDÁRIO aux'!AC23) -> 25 | AD23: =HYPERLINK("#" & $AA$17 & "!B" & MATCH('CALENDÁRIO aux'!AD23,INDIRECT($AA$17 &"!$B:$B"),0) + 3,'CALENDÁRIO aux'!AD23) -> 26 | AE23: =HYPERLINK("#" & $AA$17 & "!B" & MATCH('CALENDÁRIO aux'!AE23,INDIRECT($AA$17 &"!$B:$B"),0) + 3,'CALENDÁRIO aux'!AE23) -> 27 | AF23: =HYPERLINK("#" & $AA$17 & "!B" & MATCH('CALENDÁRIO aux'!AF23,INDIRECT($AA$17 &"!$B:$B"),0) + 3,'CALENDÁRIO aux'!AF23) -> 28 | AG23: =HYPERLINK("#" & $AA$17 & "!B" & MATCH('CALENDÁRIO aux'!AG23,INDIRECT($AA$17 &"!$B:$B"),0) + 3,'CALENDÁRIO aux'!AG23) -> 29
C24: =HYPERLINK("#" & $C$17 & "!B" & MATCH('CALENDÁRIO aux'!C24,INDIRECT($C$17 &"!$B:$B"),0) + 3,'CALENDÁRIO aux'!C24) -> 31 | AA24: =HYPERLINK("#" & $AA$17 & "!B" & MATCH('CALENDÁRIO aux'!AA24,INDIRECT($AA$17 &"!$B:$B"),0) + 3,'CALENDÁRIO aux'!AA24) -> 30 | AB24: =HYPERLINK("#" & $AA$17 & "!B" & MATCH('CALENDÁRIO aux'!AB24,INDIRECT($AA$17 &"!$B:$B"),0) + 3,'CALENDÁRIO aux'!AB24) -> 31
C26: 1 | D26: Dia do Trabalho | K26: 3 | L26: Corpus Christi
C29: SETEMBRO | K29: OUTUBRO | S29: NOVEMBRO | AA29: DEZEMBRO
C30: S | D30: T | E30: Q | F30: Q | G30: S | H30: S | I30: D | K30: S | L30: T | M30: Q | N30: Q | O30: S | P30: S | Q30: D | S30: S | T30: T | U30: Q | V30: Q | W30: S | X30: S | Y30: D | AA30: S | AB30: T | AC30: Q | AD30: Q | AE30: S | AF30: S | AG30: D
E31: =HYPERLINK("#" & $C$29 & "!B" & MATCH('CALENDÁRIO aux'!E31,INDIRECT($C$29 &"!$B:$B"),0) + 3,'CALENDÁRIO aux'!E31) -> 1 | F31: =HYPERLINK("#" & $C$29 & "!B" & MATCH('CALENDÁRIO aux'!F31,INDIRECT($C$29 &"!$B:$B"),0) + 3,'CALENDÁRIO aux'!F31) -> 2 | G31: =HYPERLINK("#" & $C$29 & "!B" & MATCH('CALENDÁRIO aux'!G31,INDIRECT($C$29 &"!$B:$B"),0) + 3,'CALENDÁRIO aux'!G31) -> 3 | H31: =HYPERLINK("#" & $C$29 & "!B" & MATCH('CALENDÁRIO aux'!H31,INDIRECT($C$29 &"!$B:$B"),0) + 3,'CALENDÁRIO aux'!H31) -> 4 | I31: =HYPERLINK("#" & $C$29 & "!B" & MATCH('CALENDÁRIO aux'!I31,INDIRECT($C$29 &"!$B:$B"),0) + 3,'CALENDÁRIO aux'!I31) -> 5 | O31: =HYPERLINK("#" & $K$29 & "!B" & MATCH('CALENDÁRIO aux'!O31,INDIRECT($K$29 &"!$B:$B"),0) + 3,'CALENDÁRIO aux'!O31) -> 1 | P31: =HYPERLINK("#" & $K$29 & "!B" & MATCH('CALENDÁRIO aux'!P31,INDIRECT($K$29 &"!$B:$B"),0) + 3,'CALENDÁRIO aux'!P31) -> 2 | Q31: =HYPERLINK("#" & $K$29 & "!B" & MATCH('CALENDÁRIO aux'!Q31,INDIRECT($K$29 &"!$B:$B"),0) + 3,'CALENDÁRIO aux'!Q31) -> 3 | S31: =HYPERLINK("#" & $S$29 & "!B" & MATCH('CALENDÁRIO aux'!S31,INDIRECT($S$29 &"!$B:$B"),0) + 3,'CALENDÁRIO aux'!S31) -> 1 | T31: =HYPERLINK("#" & $S$29 & "!B" & MATCH('CALENDÁRIO aux'!T31,INDIRECT($S$29 &"!$B:$B"),0) + 3,'CALENDÁRIO aux'!T31) -> 2 | U31: =HYPERLINK("#" & $S$29 & "!B" & MATCH('CALENDÁRIO aux'!U31,INDIRECT($S$29 &"!$B:$B"),0) + 3,'CALENDÁRIO aux'!U31) -> 3 | V31: =HYPERLINK("#" & $S$29 & "!B" & MATCH('CALENDÁRIO aux'!V31,INDIRECT($S$29 &"!$B:$B"),0) + 3,'CALENDÁRIO aux'!V31) -> 4 | W31: =HYPERLINK("#" & $S$29 & "!B" & MATCH('CALENDÁRIO aux'!W31,INDIRECT($S$29 &"!$B:$B"),0) + 3,'CALENDÁRIO aux'!W31) -> 5 | X31: =HYPERLINK("#" & $S$29 & "!B" & MATCH('CALENDÁRIO aux'!X31,INDIRECT($S$29 &"!$B:$B"),0) + 3,'CALENDÁRIO aux'!X31) -> 6 | Y31: =HYPERLINK("#" & $S$29 & "!B" & MATCH('CALENDÁRIO aux'!Y31,INDIRECT($S$29 &"!$B:$B"),0) + 3,'CALENDÁRIO aux'!Y31) -> 7 | AC31: =HYPERLINK("#" & $AA$29 & "!B" & MATCH('CALENDÁRIO aux'!AC31,INDIRECT($AA$29 &"!$B:$B"),0) + 3,'CALENDÁRIO aux'!AC31) -> 1 | AD31: =HYPERLINK("#" & $AA$29 & "!B" & MATCH('CALENDÁRIO aux'!AD31,INDIRECT($AA$29 &"!$B:$B"),0) + 3,'CALENDÁRIO aux'!AD31) -> 2 | AE31: =HYPERLINK("#" & $AA$29 & "!B" & MATCH('CALENDÁRIO aux'!AE31,INDIRECT($AA$29 &"!$B:$B"),0) + 3,'CALENDÁRIO aux'!AE31) -> 3 | AF31: =HYPERLINK("#" & $AA$29 & "!B" & MATCH('CALENDÁRIO aux'!AF31,INDIRECT($AA$29 &"!$B:$B"),0) + 3,'CALENDÁRIO aux'!AF31) -> 4 | AG31: =HYPERLINK("#" & $AA$29 & "!B" & MATCH('CALENDÁRIO aux'!AG31,INDIRECT($AA$29 &"!$B:$B"),0) + 3,'CALENDÁRIO aux'!AG31) -> 5
C32: =HYPERLINK("#" & $C$29 & "!B" & MATCH('CALENDÁRIO aux'!C32,INDIRECT($C$29 &"!$B:$B"),0) + 3,'CALENDÁRIO aux'!C32) -> 6 | D32: =HYPERLINK("#" & $C$29 & "!B" & MATCH('CALENDÁRIO aux'!D32,INDIRECT($C$29 &"!$B:$B"),0) + 3,'CALENDÁRIO aux'!D32) -> 7 | E32: =HYPERLINK("#" & $C$29 & "!B" & MATCH('CALENDÁRIO aux'!E32,INDIRECT($C$29 &"!$B:$B"),0) + 3,'CALENDÁRIO aux'!E32) -> 8 | F32: =HYPERLINK("#" & $C$29 & "!B" & MATCH('CALENDÁRIO aux'!F32,INDIRECT($C$29 &"!$B:$B"),0) + 3,'CALENDÁRIO aux'!F32) -> 9 | G32: =HYPERLINK("#" & $C$29 & "!B" & MATCH('CALENDÁRIO aux'!G32,INDIRECT($C$29 &"!$B:$B"),0) + 3,'CALENDÁRIO aux'!G32) -> 10 | H32: =HYPERLINK("#" & $C$29 & "!B" & MATCH('CALENDÁRIO aux'!H32,INDIRECT($C$29 &"!$B:$B"),0) + 3,'CALENDÁRIO aux'!H32) -> 11 | I32: =HYPERLINK("#" & $C$29 & "!B" & MATCH('CALENDÁRIO aux'!I32,INDIRECT($C$29 &"!$B:$B"),0) + 3,'CALENDÁRIO aux'!I32) -> 12 | K32: =HYPERLINK("#" & $K$29 & "!B" & MATCH('CALENDÁRIO aux'!K32,INDIRECT($K$29 &"!$B:$B"),0) + 3,'CALENDÁRIO aux'!K32) -> 4 | L32: =HYPERLINK("#" & $K$29 & "!B" & MATCH('CALENDÁRIO aux'!L32,INDIRECT($K$29 &"!$B:$B"),0) + 3,'CALENDÁRIO aux'!L32) -> 5 | M32: =HYPERLINK("#" & $K$29 & "!B" & MATCH('CALENDÁRIO aux'!M32,INDIRECT($K$29 &"!$B:$B"),0) + 3,'CALENDÁRIO aux'!M32) -> 6 | N32: =HYPERLINK("#" & $K$29 & "!B" & MATCH('CALENDÁRIO aux'!N32,INDIRECT($K$29 &"!$B:$B"),0) + 3,'CALENDÁRIO aux'!N32) -> 7 | O32: =HYPERLINK("#" & $K$29 & "!B" & MATCH('CALENDÁRIO aux'!O32,INDIRECT($K$29 &"!$B:$B"),0) + 3,'CALENDÁRIO aux'!O32) -> 8 | P32: =HYPERLINK("#" & $K$29 & "!B" & MATCH('CALENDÁRIO aux'!P32,INDIRECT($K$29 &"!$B:$B"),0) + 3,'CALENDÁRIO aux'!P32) -> 9 | Q32: =HYPERLINK("#" & $K$29 & "!B" & MATCH('CALENDÁRIO aux'!Q32,INDIRECT($K$29 &"!$B:$B"),0) + 3,'CALENDÁRIO aux'!Q32) -> 10 | S32: =HYPERLINK("#" & $S$29 & "!B" & MATCH('CALENDÁRIO aux'!S32,INDIRECT($S$29 &"!$B:$B"),0) + 3,'CALENDÁRIO aux'!S32) -> 8 | T32: =HYPERLINK("#" & $S$29 & "!B" & MATCH('CALENDÁRIO aux'!T32,INDIRECT($S$29 &"!$B:$B"),0) + 3,'CALENDÁRIO aux'!T32) -> 9 | U32: =HYPERLINK("#" & $S$29 & "!B" & MATCH('CALENDÁRIO aux'!U32,INDIRECT($S$29 &"!$B:$B"),0) + 3,'CALENDÁRIO aux'!U32) -> 10 | V32: =HYPERLINK("#" & $S$29 & "!B" & MATCH('CALENDÁRIO aux'!V32,INDIRECT($S$29 &"!$B:$B"),0) + 3,'CALENDÁRIO aux'!V32) -> 11 | W32: =HYPERLINK("#" & $S$29 & "!B" & MATCH('CALENDÁRIO aux'!W32,INDIRECT($S$29 &"!$B:$B"),0) + 3,'CALENDÁRIO aux'!W32) -> 12 | X32: =HYPERLINK("#" & $S$29 & "!B" & MATCH('CALENDÁRIO aux'!X32,INDIRECT($S$29 &"!$B:$B"),0) + 3,'CALENDÁRIO aux'!X32) -> 13 | Y32: =HYPERLINK("#" & $S$29 & "!B" & MATCH('CALENDÁRIO aux'!Y32,INDIRECT($S$29 &"!$B:$B"),0) + 3,'CALENDÁRIO aux'!Y32) -> 14 | AA32: =HYPERLINK("#" & $AA$29 & "!B" & MATCH('CALENDÁRIO aux'!AA32,INDIRECT($AA$29 &"!$B:$B"),0) + 3,'CALENDÁRIO aux'!AA32) -> 6 | AB32: =HYPERLINK("#" & $AA$29 & "!B" & MATCH('CALENDÁRIO aux'!AB32,INDIRECT($AA$29 &"!$B:$B"),0) + 3,'CALENDÁRIO aux'!AB32) -> 7 | AC32: =HYPERLINK("#" & $AA$29 & "!B" & MATCH('CALENDÁRIO aux'!AC32,INDIRECT($AA$29 &"!$B:$B"),0) + 3,'CALENDÁRIO aux'!AC32) -> 8 | AD32: =HYPERLINK("#" & $AA$29 & "!B" & MATCH('CALENDÁRIO aux'!AD32,INDIRECT($AA$29 &"!$B:$B"),0) + 3,'CALENDÁRIO aux'!AD32) -> 9 | AE32: =HYPERLINK("#" & $AA$29 & "!B" & MATCH('CALENDÁRIO aux'!AE32,INDIRECT($AA$29 &"!$B:$B"),0) + 3,'CALENDÁRIO aux'!AE32) -> 10 | AF32: =HYPERLINK("#" & $AA$29 & "!B" & MATCH('CALENDÁRIO aux'!AF32,INDIRECT($AA$29 &"!$B:$B"),0) + 3,'CALENDÁRIO aux'!AF32) -> 11 | AG32: =HYPERLINK("#" & $AA$29 & "!B" & MATCH('CALENDÁRIO aux'!AG32,INDIRECT($AA$29 &"!$B:$B"),0) + 3,'CALENDÁRIO aux'!AG32) -> 12
C33: =HYPERLINK("#" & $C$29 & "!B" & MATCH('CALENDÁRIO aux'!C33,INDIRECT($C$29 &"!$B:$B"),0) + 3,'CALENDÁRIO aux'!C33) -> 13 | D33: =HYPERLINK("#" & $C$29 & "!B" & MATCH('CALENDÁRIO aux'!D33,INDIRECT($C$29 &"!$B:$B"),0) + 3,'CALENDÁRIO aux'!D33) -> 14 | E33: =HYPERLINK("#" & $C$29 & "!B" & MATCH('CALENDÁRIO aux'!E33,INDIRECT($C$29 &"!$B:$B"),0) + 3,'CALENDÁRIO aux'!E33) -> 15 | F33: =HYPERLINK("#" & $C$29 & "!B" & MATCH('CALENDÁRIO aux'!F33,INDIRECT($C$29 &"!$B:$B"),0) + 3,'CALENDÁRIO aux'!F33) -> 16 | G33: =HYPERLINK("#" & $C$29 & "!B" & MATCH('CALENDÁRIO aux'!G33,INDIRECT($C$29 &"!$B:$B"),0) + 3,'CALENDÁRIO aux'!G33) -> 17 | H33: =HYPERLINK("#" & $C$29 & "!B" & MATCH('CALENDÁRIO aux'!H33,INDIRECT($C$29 &"!$B:$B"),0) + 3,'CALENDÁRIO aux'!H33) -> 18 | I33: =HYPERLINK("#" & $C$29 & "!B" & MATCH('CALENDÁRIO aux'!I33,INDIRECT($C$29 &"!$B:$B"),0) + 3,'CALENDÁRIO aux'!I33) -> 19 | K33: =HYPERLINK("#" & $K$29 & "!B" & MATCH('CALENDÁRIO aux'!K33,INDIRECT($K$29 &"!$B:$B"),0) + 3,'CALENDÁRIO aux'!K33) -> 11 | L33: =HYPERLINK("#" & $K$29 & "!B" & MATCH('CALENDÁRIO aux'!L33,INDIRECT($K$29 &"!$B:$B"),0) + 3,'CALENDÁRIO aux'!L33) -> 12 | M33: =HYPERLINK("#" & $K$29 & "!B" & MATCH('CALENDÁRIO aux'!M33,INDIRECT($K$29 &"!$B:$B"),0) + 3,'CALENDÁRIO aux'!M33) -> 13 | N33: =HYPERLINK("#" & $K$29 & "!B" & MATCH('CALENDÁRIO aux'!N33,INDIRECT($K$29 &"!$B:$B"),0) + 3,'CALENDÁRIO aux'!N33) -> 14 | O33: =HYPERLINK("#" & $K$29 & "!B" & MATCH('CALENDÁRIO aux'!O33,INDIRECT($K$29 &"!$B:$B"),0) + 3,'CALENDÁRIO aux'!O33) -> 15 | P33: =HYPERLINK("#" & $K$29 & "!B" & MATCH('CALENDÁRIO aux'!P33,INDIRECT($K$29 &"!$B:$B"),0) + 3,'CALENDÁRIO aux'!P33) -> 16 | Q33: =HYPERLINK("#" & $K$29 & "!B" & MATCH('CALENDÁRIO aux'!Q33,INDIRECT($K$29 &"!$B:$B"),0) + 3,'CALENDÁRIO aux'!Q33) -> 17 | S33: =HYPERLINK("#" & $S$29 & "!B" & MATCH('CALENDÁRIO aux'!S33,INDIRECT($S$29 &"!$B:$B"),0) + 3,'CALENDÁRIO aux'!S33) -> 15 | T33: =HYPERLINK("#" & $S$29 & "!B" & MATCH('CALENDÁRIO aux'!T33,INDIRECT($S$29 &"!$B:$B"),0) + 3,'CALENDÁRIO aux'!T33) -> 16 | U33: =HYPERLINK("#" & $S$29 & "!B" & MATCH('CALENDÁRIO aux'!U33,INDIRECT($S$29 &"!$B:$B"),0) + 3,'CALENDÁRIO aux'!U33) -> 17 | V33: =HYPERLINK("#" & $S$29 & "!B" & MATCH('CALENDÁRIO aux'!V33,INDIRECT($S$29 &"!$B:$B"),0) + 3,'CALENDÁRIO aux'!V33) -> 18 | W33: =HYPERLINK("#" & $S$29 & "!B" & MATCH('CALENDÁRIO aux'!W33,INDIRECT($S$29 &"!$B:$B"),0) + 3,'CALENDÁRIO aux'!W33) -> 19 | X33: =HYPERLINK("#" & $S$29 & "!B" & MATCH('CALENDÁRIO aux'!X33,INDIRECT($S$29 &"!$B:$B"),0) + 3,'CALENDÁRIO aux'!X33) -> 20 | Y33: =HYPERLINK("#" & $S$29 & "!B" & MATCH('CALENDÁRIO aux'!Y33,INDIRECT($S$29 &"!$B:$B"),0) + 3,'CALENDÁRIO aux'!Y33) -> 21 | AA33: =HYPERLINK("#" & $AA$29 & "!B" & MATCH('CALENDÁRIO aux'!AA33,INDIRECT($AA$29 &"!$B:$B"),0) + 3,'CALENDÁRIO aux'!AA33) -> 13 | AB33: =HYPERLINK("#" & $AA$29 & "!B" & MATCH('CALENDÁRIO aux'!AB33,INDIRECT($AA$29 &"!$B:$B"),0) + 3,'CALENDÁRIO aux'!AB33) -> 14 | AC33: =HYPERLINK("#" & $AA$29 & "!B" & MATCH('CALENDÁRIO aux'!AC33,INDIRECT($AA$29 &"!$B:$B"),0) + 3,'CALENDÁRIO aux'!AC33) -> 15 | AD33: =HYPERLINK("#" & $AA$29 & "!B" & MATCH('CALENDÁRIO aux'!AD33,INDIRECT($AA$29 &"!$B:$B"),0) + 3,'CALENDÁRIO aux'!AD33) -> 16 | AE33: =HYPERLINK("#" & $AA$29 & "!B" & MATCH('CALENDÁRIO aux'!AE33,INDIRECT($AA$29 &"!$B:$B"),0) + 3,'CALENDÁRIO aux'!AE33) -> 17 | AF33: =HYPERLINK("#" & $AA$29 & "!B" & MATCH('CALENDÁRIO aux'!AF33,INDIRECT($AA$29 &"!$B:$B"),0) + 3,'CALENDÁRIO aux'!AF33) -> 18 | AG33: =HYPERLINK("#" & $AA$29 & "!B" & MATCH('CALENDÁRIO aux'!AG33,INDIRECT($AA$29 &"!$B:$B"),0) + 3,'CALENDÁRIO aux'!AG33) -> 19
C34: =HYPERLINK("#" & $C$29 & "!B" & MATCH('CALENDÁRIO aux'!C34,INDIRECT($C$29 &"!$B:$B"),0) + 3,'CALENDÁRIO aux'!C34) -> 20 | D34: =HYPERLINK("#" & $C$29 & "!B" & MATCH('CALENDÁRIO aux'!D34,INDIRECT($C$29 &"!$B:$B"),0) + 3,'CALENDÁRIO aux'!D34) -> 21 | E34: =HYPERLINK("#" & $C$29 & "!B" & MATCH('CALENDÁRIO aux'!E34,INDIRECT($C$29 &"!$B:$B"),0) + 3,'CALENDÁRIO aux'!E34) -> 22 | F34: =HYPERLINK("#" & $C$29 & "!B" & MATCH('CALENDÁRIO aux'!F34,INDIRECT($C$29 &"!$B:$B"),0) + 3,'CALENDÁRIO aux'!F34) -> 23 | G34: =HYPERLINK("#" & $C$29 & "!B" & MATCH('CALENDÁRIO aux'!G34,INDIRECT($C$29 &"!$B:$B"),0) + 3,'CALENDÁRIO aux'!G34) -> 24 | H34: =HYPERLINK("#" & $C$29 & "!B" & MATCH('CALENDÁRIO aux'!H34,INDIRECT($C$29 &"!$B:$B"),0) + 3,'CALENDÁRIO aux'!H34) -> 25 | I34: =HYPERLINK("#" & $C$29 & "!B" & MATCH('CALENDÁRIO aux'!I34,INDIRECT($C$29 &"!$B:$B"),0) + 3,'CALENDÁRIO aux'!I34) -> 26 | K34: =HYPERLINK("#" & $K$29 & "!B" & MATCH('CALENDÁRIO aux'!K34,INDIRECT($K$29 &"!$B:$B"),0) + 3,'CALENDÁRIO aux'!K34) -> 18 | L34: =HYPERLINK("#" & $K$29 & "!B" & MATCH('CALENDÁRIO aux'!L34,INDIRECT($K$29 &"!$B:$B"),0) + 3,'CALENDÁRIO aux'!L34) -> 19 | M34: =HYPERLINK("#" & $K$29 & "!B" & MATCH('CALENDÁRIO aux'!M34,INDIRECT($K$29 &"!$B:$B"),0) + 3,'CALENDÁRIO aux'!M34) -> 20 | N34: =HYPERLINK("#" & $K$29 & "!B" & MATCH('CALENDÁRIO aux'!N34,INDIRECT($K$29 &"!$B:$B"),0) + 3,'CALENDÁRIO aux'!N34) -> 21 | O34: =HYPERLINK("#" & $K$29 & "!B" & MATCH('CALENDÁRIO aux'!O34,INDIRECT($K$29 &"!$B:$B"),0) + 3,'CALENDÁRIO aux'!O34) -> 22 | P34: =HYPERLINK("#" & $K$29 & "!B" & MATCH('CALENDÁRIO aux'!P34,INDIRECT($K$29 &"!$B:$B"),0) + 3,'CALENDÁRIO aux'!P34) -> 23 | Q34: =HYPERLINK("#" & $K$29 & "!B" & MATCH('CALENDÁRIO aux'!Q34,INDIRECT($K$29 &"!$B:$B"),0) + 3,'CALENDÁRIO aux'!Q34) -> 24 | S34: =HYPERLINK("#" & $S$29 & "!B" & MATCH('CALENDÁRIO aux'!S34,INDIRECT($S$29 &"!$B:$B"),0) + 3,'CALENDÁRIO aux'!S34) -> 22 | T34: =HYPERLINK("#" & $S$29 & "!B" & MATCH('CALENDÁRIO aux'!T34,INDIRECT($S$29 &"!$B:$B"),0) + 3,'CALENDÁRIO aux'!T34) -> 23 | U34: =HYPERLINK("#" & $S$29 & "!B" & MATCH('CALENDÁRIO aux'!U34,INDIRECT($S$29 &"!$B:$B"),0) + 3,'CALENDÁRIO aux'!U34) -> 24 | V34: =HYPERLINK("#" & $S$29 & "!B" & MATCH('CALENDÁRIO aux'!V34,INDIRECT($S$29 &"!$B:$B"),0) + 3,'CALENDÁRIO aux'!V34) -> 25 | W34: =HYPERLINK("#" & $S$29 & "!B" & MATCH('CALENDÁRIO aux'!W34,INDIRECT($S$29 &"!$B:$B"),0) + 3,'CALENDÁRIO aux'!W34) -> 26 | X34: =HYPERLINK("#" & $S$29 & "!B" & MATCH('CALENDÁRIO aux'!X34,INDIRECT($S$29 &"!$B:$B"),0) + 3,'CALENDÁRIO aux'!X34) -> 27 | Y34: =HYPERLINK("#" & $S$29 & "!B" & MATCH('CALENDÁRIO aux'!Y34,INDIRECT($S$29 &"!$B:$B"),0) + 3,'CALENDÁRIO aux'!Y34) -> 28 | AA34: =HYPERLINK("#" & $AA$29 & "!B" & MATCH('CALENDÁRIO aux'!AA34,INDIRECT($AA$29 &"!$B:$B"),0) + 3,'CALENDÁRIO aux'!AA34) -> 20 | AB34: =HYPERLINK("#" & $AA$29 & "!B" & MATCH('CALENDÁRIO aux'!AB34,INDIRECT($AA$29 &"!$B:$B"),0) + 3,'CALENDÁRIO aux'!AB34) -> 21 | AC34: =HYPERLINK("#" & $AA$29 & "!B" & MATCH('CALENDÁRIO aux'!AC34,INDIRECT($AA$29 &"!$B:$B"),0) + 3,'CALENDÁRIO aux'!AC34) -> 22 | AD34: =HYPERLINK("#" & $AA$29 & "!B" & MATCH('CALENDÁRIO aux'!AD34,INDIRECT($AA$29 &"!$B:$B"),0) + 3,'CALENDÁRIO aux'!AD34) -> 23 | AE34: =HYPERLINK("#" & $AA$29 & "!B" & MATCH('CALENDÁRIO aux'!AE34,INDIRECT($AA$29 &"!$B:$B"),0) + 3,'CALENDÁRIO aux'!AE34) -> 24 | AF34: =HYPERLINK("#" & $AA$29 & "!B" & MATCH('CALENDÁRIO aux'!AF34,INDIRECT($AA$29 &"!$B:$B"),0) + 3,'CALENDÁRIO aux'!AF34) -> 25 | AG34: =HYPERLINK("#" & $AA$29 & "!B" & MATCH('CALENDÁRIO aux'!AG34,INDIRECT($AA$29 &"!$B:$B"),0) + 3,'CALENDÁRIO aux'!AG34) -> 26
C35: =HYPERLINK("#" & $C$29 & "!B" & MATCH('CALENDÁRIO aux'!C35,INDIRECT($C$29 &"!$B:$B"),0) + 3,'CALENDÁRIO aux'!C35) -> 27 | D35: =HYPERLINK("#" & $C$29 & "!B" & MATCH('CALENDÁRIO aux'!D35,INDIRECT($C$29 &"!$B:$B"),0) + 3,'CALENDÁRIO aux'!D35) -> 28 | E35: =HYPERLINK("#" & $C$29 & "!B" & MATCH('CALENDÁRIO aux'!E35,INDIRECT($C$29 &"!$B:$B"),0) + 3,'CALENDÁRIO aux'!E35) -> 29 | F35: =HYPERLINK("#" & $C$29 & "!B" & MATCH('CALENDÁRIO aux'!F35,INDIRECT($C$29 &"!$B:$B"),0) + 3,'CALENDÁRIO aux'!F35) -> 30 | K35: =HYPERLINK("#" & $K$29 & "!B" & MATCH('CALENDÁRIO aux'!K35,INDIRECT($K$29 &"!$B:$B"),0) + 3,'CALENDÁRIO aux'!K35) -> 25 | L35: =HYPERLINK("#" & $K$29 & "!B" & MATCH('CALENDÁRIO aux'!L35,INDIRECT($K$29 &"!$B:$B"),0) + 3,'CALENDÁRIO aux'!L35) -> 26 | M35: =HYPERLINK("#" & $K$29 & "!B" & MATCH('CALENDÁRIO aux'!M35,INDIRECT($K$29 &"!$B:$B"),0) + 3,'CALENDÁRIO aux'!M35) -> 27 | N35: =HYPERLINK("#" & $K$29 & "!B" & MATCH('CALENDÁRIO aux'!N35,INDIRECT($K$29 &"!$B:$B"),0) + 3,'CALENDÁRIO aux'!N35) -> 28 | O35: =HYPERLINK("#" & $K$29 & "!B" & MATCH('CALENDÁRIO aux'!O35,INDIRECT($K$29 &"!$B:$B"),0) + 3,'CALENDÁRIO aux'!O35) -> 29 | P35: =HYPERLINK("#" & $K$29 & "!B" & MATCH('CALENDÁRIO aux'!P35,INDIRECT($K$29 &"!$B:$B"),0) + 3,'CALENDÁRIO aux'!P35) -> 30 | Q35: =HYPERLINK("#" & $K$29 & "!B" & MATCH('CALENDÁRIO aux'!Q35,INDIRECT($K$29 &"!$B:$B"),0) + 3,'CALENDÁRIO aux'!Q35) -> 31 | S35: =HYPERLINK("#" & $S$29 & "!B" & MATCH('CALENDÁRIO aux'!S35,INDIRECT($S$29 &"!$B:$B"),0) + 3,'CALENDÁRIO aux'!S35) -> 29 | T35: =HYPERLINK("#" & $S$29 & "!B" & MATCH('CALENDÁRIO aux'!T35,INDIRECT($S$29 &"!$B:$B"),0) + 3,'CALENDÁRIO aux'!T35) -> 30 | AA35: =HYPERLINK("#" & $AA$29 & "!B" & MATCH('CALENDÁRIO aux'!AA35,INDIRECT($AA$29 &"!$B:$B"),0) + 3,'CALENDÁRIO aux'!AA35) -> 27 | AB35: =HYPERLINK("#" & $AA$29 & "!B" & MATCH('CALENDÁRIO aux'!AB35,INDIRECT($AA$29 &"!$B:$B"),0) + 3,'CALENDÁRIO aux'!AB35) -> 28 | AC35: =HYPERLINK("#" & $AA$29 & "!B" & MATCH('CALENDÁRIO aux'!AC35,INDIRECT($AA$29 &"!$B:$B"),0) + 3,'CALENDÁRIO aux'!AC35) -> 29 | AD35: =HYPERLINK("#" & $AA$29 & "!B" & MATCH('CALENDÁRIO aux'!AD35,INDIRECT($AA$29 &"!$B:$B"),0) + 3,'CALENDÁRIO aux'!AD35) -> 30 | AE35: =HYPERLINK("#" & $AA$29 & "!B" & MATCH('CALENDÁRIO aux'!AE35,INDIRECT($AA$29 &"!$B:$B"),0) + 3,'CALENDÁRIO aux'!AE35) -> 31
C37: 7 | D37: Independência do Brasil | K37: 12 | L37: Nossa Senhora Aparecida | S37: 2 | T37: Finados | AA37: 25 | AB37: Natal
S38: 15 | T38: Proclamação da República

Sheet CALENDÁRIO aux
B1: CALENDÁRIO 2021
C4: * Clique no dia para ser direcionado para a agenda
C6: JANEIRO | K6: FEVEREIRO | S6: MARÇO | AA6: ABRIL
C7: S | D7: T | E7: Q | F7: Q | G7: S | H7: S | I7: D | K7: S | L7: T | M7: Q | N7: Q | O7: S | P7: S | Q7: D | S7: S | T7: T | U7: Q | V7: Q | W7: S | X7: S | Y7: D | AA7: S | AB7: T | AC7: Q | AD7: Q | AE7: S | AF7: S | AG7: D
G8: 1 | H8: 2 | I8: 3 | K8: 1 | L8: 2 | M8: 3 | N8: 4 | O8: 5 | P8: 6 | Q8: 7 | S8: 1 | T8: 2 | U8: 3 | V8: 4 | W8: 5 | X8: 6 | Y8: 7 | AD8: 1 | AE8: =AD8+1 -> 2 | AF8: =AE8+1 -> 3 | AG8: =AF8+1 -> 4
C9: 4 | D9: 5 | E9: 6 | F9: 7 | G9: 8 | H9: 9 | I9: 10 | K9: 8 | L9: 9 | M9: 10 | N9: 11 | O9: 12 | P9: 13 | Q9: 14 | S9: 8 | T9: 9 | U9: 10 | V9: 11 | W9: 12 | X9: 13 | Y9: 14 | AA9: 5 | AB9: 6 | AC9: 7 | AD9: 8 | AE9: 9 | AF9: 10 | AG9: 11
C10: 11 | D10: 12 | E10: 13 | F10: 14 | G10: 15 | H10: 16 | I10: 17 | K10: 15 | L10: 16 | M10: 17 | N10: 18 | O10: 19 | P10: 20 | Q10: 21 | S10: 15 | T10: 16 | U10: 17 | V10: 18 | W10: 19 | X10: 20 | Y10: 21 | AA10: =AA9+7 -> 12 | AB10: =AB9+7 -> 13 | AC10: =AC9+7 -> 14 | AD10: =AD9+7 -> 15 | AE10: =AE9+7 -> 16 | AF10: =AF9+7 -> 17 | AG10: =AG9+7 -> 18
C11: 18 | D11: 19 | E11: 20 | F11: 21 | G11: 22 | H11: 23 | I11: 24 | K11: 22 | L11: 23 | M11: 24 | N11: 25 | O11: 26 | P11: 27 | Q11: 28 | S11: 22 | T11: 23 | U11: 24 | V11: 25 | W11: 26 | X11: 27 | Y11: 28 | AA11: =AA10+7 -> 19 | AB11: =AB10+7 -> 20 | AC11: =AC10+7 -> 21 | AD11: =AD10+7 -> 22 | AE11: =AE10+7 -> 23 | AF11: =AF10+7 -> 24 | AG11: =AG10+7 -> 25
C12: 25 | D12: 26 | E12: 27 | F12: 28 | G12: 29 | H12: 30 | I12: 31 | S12: 29 | T12: 30 | U12: 31 | AA12: =AA11+7 -> 26 | AB12: =AB11+7 -> 27 | AC12: =AC11+7 -> 28 | AD12: =AD11+7 -> 29 | AE12: =AE11+7 -> 30
C14: 1 | D14: Confraternização Universal | K14: 16 | L14: Carnaval | AA14: 2 | AB14: Paixão
K15: 17 | L15: Cinzas | AA15: 21 | AB15: Tiradentes
C17: MAIO | K17: JUNHO | S17: JULHO | AA17: AGOSTO
C18: S | D18: T | E18: Q | F18: Q | G18: S | H18: S | I18: D | K18: S | L18: T | M18: Q | N18: Q | O18: S | P18: S | Q18: D | S18: S | T18: T | U18: Q | V18: Q | W18: S | X18: S | Y18: D | AA18: S | AB18: T | AC18: Q | AD18: Q | AE18: S | AF18: S | AG18: D
H19: 1 | I19: 2 | L19: 1 | M19: 2 | N19: 3 | O19: 4 | P19: 5 | Q19: 6 | V19: 1 | W19: 2 | X19: 3 | Y19: 4 | AG19: 1
C20: 3 | D20: 4 | E20: 5 | F20: 6 | G20: 7 | H20: 8 | I20: 9 | K20: 7 | L20: 8 | M20: 9 | N20: 10 | O20: 11 | P20: 12 | Q20: 13 | S20: 5 | T20: 6 | U20: 7 | V20: 8 | W20: 9 | X20: 10 | Y20: 11 | AA20: 2 | AB20: 3 | AC20: 4 | AD20: 5 | AE20: 6 | AF20: 7 | AG20: 8
C21: 10 | D21: 11 | E21: 12 | F21: 13 | G21: 14 | H21: 15 | I21: 16 | K21: 14 | L21: 15 | M21: 16 | N21: 17 | O21: 18 | P21: 19 | Q21: 20 | S21: 12 | T21: 13 | U21: 14 | V21: 15 | W21: 16 | X21: 17 | Y21: 18 | AA21: 9 | AB21: 10 | AC21: 11 | AD21: 12 | AE21: 13 | AF21: 14 | AG21: 15
C22: 17 | D22: 18 | E22: 19 | F22: 20 | G22: 21 | H22: 22 | I22: 23 | K22: 21 | L22: 22 | M22: 23 | N22: 24 | O22: 25 | P22: 26 | Q22: 27 | S22: 19 | T22: 20 | U22: 21 | V22: 22 | W22: 23 | X22: 24 | Y22: 25 | AA22: 16 | AB22: 17 | AC22: 18 | AD22: 19 | AE22: 20 | AF22: 21 | AG22: 22
C23: 24 | D23: 25 | E23: 26 | F23: 27 | G23: 28 | H23: 29 | I23: 30 | K23: 28 | L23: 29 | M23: 30 | S23: 26 | T23: 27 | U23: 28 | V23: 29 | W23: 30 | X23: 31 | AA23: 23 | AB23: 24 | AC23: 25 | AD23: 26 | AE23: 27 | AF23: 28 | AG23: 29
C24: 31 | AA24: 30 | AB24: 31
C26: 1 | D26: Dia do Trabalho | K26: 3 | L26: Corpus Christi
C29: SETEMBRO | K29: OUTUBRO | S29: NOVEMBRO | AA29: DEZEMBRO
C30: S | D30: T | E30: Q | F30: Q | G30: S | H30: S | I30: D | K30: S | L30: T | M30: Q | N30: Q | O30: S | P30: S | Q30: D | S30: S | T30: T | U30: Q | V30: Q | W30: S | X30: S | Y30: D | AA30: S | AB30: T | AC30: Q | AD30: Q | AE30: S | AF30: S | AG30: D
E31: 1 | F31: 2 | G31: 3 | H31: 4 | I31: 5 | O31: 1 | P31: 2 | Q31: 3 | S31: 1 | T31: 2 | U31: 3 | V31: 4 | W31: 5 | X31: 6 | Y31: 7 | AC31: 1 | AD31: 2 | AE31: 3 | AF31: 4 | AG31: 5
C32: 6 | D32: 7 | E32: 8 | F32: 9 | G32: 10 | H32: 11 | I32: 12 | K32: 4 | L32: 5 | M32: 6 | N32: 7 | O32: 8 | P32: 9 | Q32: 10 | S32: 8 | T32: 9 | U32: 10 | V32: 11 | W32: 12 | X32: 13 | Y32: 14 | AA32: 6 | AB32: 7 | AC32: 8 | AD32: 9 | AE32: 10 | AF32: 11 | AG32: 12
C33: 13 | D33: 14 | E33: 15 | F33: 16 | G33: 17 | H33: 18 | I33: 19 | K33: 11 | L33: 12 | M33: 13 | N33: 14 | O33: 15 | P33: 16 | Q33: 17 | S33: 15 | T33: 16 | U33: 17 | V33: 18 | W33: 19 | X33: 20 | Y33: 21 | AA33: 13 | AB33: 14 | AC33: 15 | AD33: 16 | AE33: 17 | AF33: 18 | AG33: 19
C34: 20 | D34: 21 | E34: 22 | F34: 23 | G34: 24 | H34: 25 | I34: 26 | K34: 18 | L34: 19 | M34: 20 | N34: 21 | O34: 22 | P34: 23 | Q34: 24 | S34: 22 | T34: 23 | U34: 24 | V34: 25 | W34: 26 | X34: 27 | Y34: 28 | AA34: 20 | AB34: 21 | AC34: 22 | AD34: 23 | AE34: 24 | AF34: 25 | AG34: 26
C35: 27 | D35: 28 | E35: 29 | F35: 30 | K35: 25 | L35: 26 | M35: 27 | N35: 28 | O35: 29 | P35: 30 | Q35: 31 | S35: 29 | T35: 30 | AA35: 27 | AB35: 28 | AC35: 29 | AD35: 30 | AE35: 31
C37: 7 | D37: Independência do Brasil | K37: 12 | L37: Nossa Senhora Aparecida | S37: 2 | T37: Finados | AA37: 25 | AB37: Natal
S38: 15 | T38: Proclamação da República

Sheet JANEIRO
B2: JANEIRO | U2: ACOMPANHAMENTO FINANCEIRO
B5: TOP 5 PRIORIDADES NO MÊS | M5: JANEIRO | X5: 2500 | AE5: =X5+SUMIF(AF16:AF61,"Entrada",AD16:AD61)-SUMIF(AF16:AF61,"Saída",AD16:AD61) -> 1500 | AT5: JANEIRO
M6: S | N6: T | O6: Q | P6: Q | Q6: S | R6: S | S6: D | V6: SALDO INICIAL: | AC6: SALDO FINAL: | AT6: S | AU6: T | AV6: Q | AW6: Q | AX6: S | AY6: S | AZ6: D
B7: 1. | Q7: =HYPERLINK("#" & $B$2 & "!B" & MATCH(CALENDÁRIO!G8,$B:$B,0) + 3,CALENDÁRIO!G8) -> 1 | R7: =HYPERLINK("#" & $B$2 & "!B" & MATCH(CALENDÁRIO!H8,$B:$B,0) + 3,CALENDÁRIO!H8) -> 2 | S7: =HYPERLINK("#" & $B$2 & "!B" & MATCH(CALENDÁRIO!I8,$B:$B,0) + 3,CALENDÁRIO!I8) -> 3 | AX7: 1 | AY7: 2 | AZ7: 3
B8: 2. | M8: =HYPERLINK("#" & $B$2 & "!B" & MATCH(CALENDÁRIO!C9,$B:$B,0) + 3,CALENDÁRIO!C9) -> 4 | N8: =HYPERLINK("#" & $B$2 & "!B" & MATCH(CALENDÁRIO!D9,$B:$B,0) + 3,CALENDÁRIO!D9) -> 5 | O8: =HYPERLINK("#" & $B$2 & "!B" & MATCH(CALENDÁRIO!E9,$B:$B,0) + 3,CALENDÁRIO!E9) -> 6 | P8: =HYPERLINK("#" & $B$2 & "!B" & MATCH(CALENDÁRIO!F9,$B:$B,0) + 3,CALENDÁRIO!F9) -> 7 | Q8: =HYPERLINK("#" & $B$2 & "!B" & MATCH(CALENDÁRIO!G9,$B:$B,0) + 3,CALENDÁRIO!G9) -> 8 | R8: =HYPERLINK("#" & $B$2 & "!B" & MATCH(CALENDÁRIO!H9,$B:$B,0) + 3,CALENDÁRIO!H9) -> 9 | S8: =HYPERLINK("#" & $B$2 & "!B" & MATCH(CALENDÁRIO!I9,$B:$B,0) + 3,CALENDÁRIO!I9) -> 10 | AT8: 4 | AU8: 5 | AV8: 6 | AW8: 7 | AX8: 8 | AY8: 9 | AZ8: 10
B9: 3. | M9: =HYPERLINK("#" & $B$2 & "!B" & MATCH(CALENDÁRIO!C10,$B:$B,0) + 3,CALENDÁRIO!C10) -> 11 | N9: =HYPERLINK("#" & $B$2 & "!B" & MATCH(CALENDÁRIO!D10,$B:$B,0) + 3,CALENDÁRIO!D10) -> 12 | O9: =HYPERLINK("#" & $B$2 & "!B" & MATCH(CALENDÁRIO!E10,$B:$B,0) + 3,CALENDÁRIO!E10) -> 13 | P9: =HYPERLINK("#" & $B$2 & "!B" & MATCH(CALENDÁRIO!F10,$B:$B,0) + 3,CALENDÁRIO!F10) -> 14 | Q9: =HYPERLINK("#" & $B$2 & "!B" & MATCH(CALENDÁRIO!G10,$B:$B,0) + 3,CALENDÁRIO!G10) -> 15 | R9: =HYPERLINK("#" & $B$2 & "!B" & MATCH(CALENDÁRIO!H10,$B:$B,0) + 3,CALENDÁRIO!H10) -> 16 | S9: =HYPERLINK("#" & $B$2 & "!B" & MATCH(CALENDÁRIO!I10,$B:$B,0) + 3,CALENDÁRIO!I10) -> 17 | AT9: 11 | AU9: 12 | AV9: 13 | AW9: 14 | AX9: 15 | AY9: 16 | AZ9: 17
B10: 4. | M10: =HYPERLINK("#" & $B$2 & "!B" & MATCH(CALENDÁRIO!C11,$B:$B,0) + 3,CALENDÁRIO!C11) -> 18 | N10: =HYPERLINK("#" & $B$2 & "!B" & MATCH(CALENDÁRIO!D11,$B:$B,0) + 3,CALENDÁRIO!D11) -> 19 | O10: =HYPERLINK("#" & $B$2 & "!B" & MATCH(CALENDÁRIO!E11,$B:$B,0) + 3,CALENDÁRIO!E11) -> 20 | P10: =HYPERLINK("#" & $B$2 & "!B" & MATCH(CALENDÁRIO!F11,$B:$B,0) + 3,CALENDÁRIO!F11) -> 21 | Q10: =HYPERLINK("#" & $B$2 & "!B" & MATCH(CALENDÁRIO!G11,$B:$B,0) + 3,CALENDÁRIO!G11) -> 22 | R10: =HYPERLINK("#" & $B$2 & "!B" & MATCH(CALENDÁRIO!H11,$B:$B,0) + 3,CALENDÁRIO!H11) -> 23 | S10: =HYPERLINK("#" & $B$2 & "!B" & MATCH(CALENDÁRIO!I11,$B:$B,0) + 3,CALENDÁRIO!I11) -> 24 | AT10: 18 | AU10: 19 | AV10: 20 | AW10: 21 | AX10: 22 | AY10: 23 | AZ10: 24
