Workbook
Name primeiro: INDIRECT("Imagens!B" & MATCH(Auxiliar!$T$10,Imagens!$A:$A,0))
Name segundo: INDIRECT("Imagens!B" & MATCH(Auxiliar!$T$11,Imagens!$A:$A,0))
Name terceiro: INDIRECT("Imagens!B" & MATCH(Auxiliar!$T$12,Imagens!$A:$A,0))

Sheet BOLÃO
B1: BOLÃO CAMPEONATO BRASILEIRO 2021
K14: ALON | N14: =SUM(N19:N398) -> 710 | P14: DIEGO | S14: =SUM(S19:S398) -> 693 | U14: AMANDA | X14: =SUM(X19:X398) -> 696 | Z14: ALESSANDRA | AC14: =SUM(AC19:AC398) -> 609 | AE14: SÉRGIO | AH14: =SUM(AH19:AH398) -> 569
C18: RODADA | D18: MANDANTE | E18: RESULTADO | H18: VISITANTE | K18: PALPITE | N18: Pontuação | P18: PALPITE | S18: Pontuação | U18: PALPITE | X18: Pontuação | Z18: PALPITE | AC18: Pontuação | AE18: PALPITE | AH18: Pontuação
C19: 1 | D19: FLA | E19: 2 | F19: x | G19: 5 | H19: PAL | K19: 0 | L19: x | M19: 2 | N19: =IF(OR($E19="",$G19=""),"",IF(AND(K19=$E19,M19=$G19),Auxiliar!$C$11,IF(AND(SIGN($E19-$G19)=SIGN(K19-M19),MAX($E19,$G19)=MAX(K19,M19)),Auxiliar!$C$12,IF(ABS($E19-$G19)=ABS(K19-M19),Auxiliar!$C$13,IF(AND(SIGN($E19-$G19)=SIGN(K19-M19),MIN($E19,$G19)=MIN(K19,M19)),Auxiliar!$C$14,IF(SIGN($E19-$G19)=SIGN(K19-M19),Auxiliar!$C$15,IF(K19=M19,Auxiliar!$C$16,0))))))) -> 10 | P19: 1 | Q19: x | R19: 2 | S19: =IF(OR($E19="",$G19=""),"",IF(AND(P19=$E19,R19=$G19),Auxiliar!$C$11,IF(AND(SIGN($E19-$G19)=SIGN(P19-R19),MAX($E19,$G19)=MAX(P19,R19)),Auxiliar!$C$12,IF(ABS($E19-$G19)=ABS(P19-R19),Auxiliar!$C$13,IF(AND(SIGN($E19-$G19)=SIGN(P19-R19),MIN($E19,$G19)=MIN(P19,R19)),Auxiliar!$C$14,IF(SIGN($E19-$G19)=SIGN(P19-R19),Auxiliar!$C$15,IF(P19=R19,Auxiliar!$C$16,0))))))) -> 10 | U19: 0 | V19: x | W19: 1 | X19: =IF(OR($E19="",$G19=""),"",IF(AND(U19=$E19,W19=$G19),Auxiliar!$C$11,IF(AND(SIGN($E19-$G19)=SIGN(U19-W19),MAX($E19,$G19)=MAX(U19,W19)),Auxiliar!$C$12,IF(ABS($E19-$G19)=ABS(U19-W19),Auxiliar!$C$13,IF(AND(SIGN($E19-$G19)=SIGN(U19-W19),MIN($E19,$G19)=MIN(U19,W19)),Auxiliar!$C$14,IF(SIGN($E19-$G19)=SIGN(U19-W19),Auxiliar!$C$15,IF(U19=W19,Auxiliar!$C$16,0))))))) -> 10 | Z19: 1 | AA19: x | AB19: 2 | AC19: =IF(OR($E19="",$G19=""),"",IF(AND(Z19=$E19,AB19=$G19),Auxiliar!$C$11,IF(AND(SIGN($E19-$G19)=SIGN(Z19-AB19),MAX($E19,$G19)=MAX(Z19,AB19)),Auxiliar!$C$12,IF(ABS($E19-$G19)=ABS(Z19-AB19),Auxiliar!$C$13,IF(AND(SIGN($E19-$G19)=SIGN(Z19-AB19),MIN($E19,$G19)=MIN(Z19,AB19)),Auxiliar!$C$14,IF(SIGN($E19-$G19)=SIGN(Z19-AB19),Auxiliar!$C$15,IF(Z19=AB19,Auxiliar!$C$16,0))))))) -> 10 | AE19: 4 | AF19: x | AG19: 3 | AH19: =IF(OR($E19="",$G19=""),"",IF(AND(AE19=$E19,AG19=$G19),Auxiliar!$C$11,IF(AND(SIGN($E19-$G19)=SIGN(AE19-AG19),MAX($E19,$G19)=MAX(AE19,AG19)),Auxiliar!$C$12,IF(ABS($E19-$G19)=ABS(AE19-AG19),Auxiliar!$C$13,IF(AND(SIGN($E19-$G19)=SIGN(AE19-AG19),MIN($E19,$G19)=MIN(AE19,AG19)),Auxiliar!$C$14,IF(SIGN($E19-$G19)=SIGN(AE19-AG19),Auxiliar!$C$15,IF(AE19=AG19,Auxiliar!$C$16,0))))))) -> 0
C20: 1 | D20: COR | E20: 2 | F20: x | G20: 5 | H20: ACG | K20: 0 | L20: x | M20: 2 | N20: =IF(OR($E20="",$G20=""),"",IF(AND(K20=$E20,M20=$G20),Auxiliar!$C$11,IF(AND(SIGN($E20-$G20)=SIGN(K20-M20),MAX($E20,$G20)=MAX(K20,M20)),Auxiliar!$C$12,IF(ABS($E20-$G20)=ABS(K20-M20),Auxiliar!$C$13,IF(AND(SIGN($E20-$G20)=SIGN(K20-M20),MIN($E20,$G20)=MIN(K20,M20)),Auxiliar!$C$14,IF(SIGN($E20-$G20)=SIGN(K20-M20),Auxiliar!$C$15,IF(K20=M20,Auxiliar!$C$16,0))))))) -> 10 | P20: 0 | Q20: x | R20: 2 | S20: =IF(OR($E20="",$G20=""),"",IF(AND(P20=$E20,R20=$G20),Auxiliar!$C$11,IF(AND(SIGN($E20-$G20)=SIGN(P20-R20),MAX($E20,$G20)=MAX(P20,R20)),Auxiliar!$C$12,IF(ABS($E20-$G20)=ABS(P20-R20),Auxiliar!$C$13,IF(AND(SIGN($E20-$G20)=SIGN(P20-R20),MIN($E20,$G20)=MIN(P20,R20)),Auxiliar!$C$14,IF(SIGN($E20-$G20)=SIGN(P20-R20),Auxiliar!$C$15,IF(P20=R20,Auxiliar!$C$16,0))))))) -> 10 | U20: 1 | V20: x | W20: 4 | X20: =IF(OR($E20="",$G20=""),"",IF(AND(U20=$E20,W20=$G20),Auxiliar!$C$11,IF(AND(SIGN($E20-$G20)=SIGN(U20-W20),MAX($E20,$G20)=MAX(U20,W20)),Auxiliar!$C$12,IF(ABS($E20-$G20)=ABS(U20-W20),Auxiliar!$C$13,IF(AND(SIGN($E20-$G20)=SIGN(U20-W20),MIN($E20,$G20)=MIN(U20,W20)),Auxiliar!$C$14,IF(SIGN($E20-$G20)=SIGN(U20-W20),Auxiliar!$C$15,IF(U20=W20,Auxiliar!$C$16,0))))))) -> 15 | Z20: 5 | AA20: x | AB20: 4 | AC20: =IF(OR($E20="",$G20=""),"",IF(AND(Z20=$E20,AB20=$G20),Auxiliar!$C$11,IF(AND(SIGN($E20-$G20)=SIGN(Z20-AB20),MAX($E20,$G20)=MAX(Z20,AB20)),Auxiliar!$C$12,IF(ABS($E20-$G20)=ABS(Z20-AB20),Auxiliar!$C$13,IF(AND(SIGN($E20-$G20)=SIGN(Z20-AB20),MIN($E20,$G20)=MIN(Z20,AB20)),Auxiliar!$C$14,IF(SIGN($E20-$G20)=SIGN(Z20-AB20),Auxiliar!$C$15,IF(Z20=AB20,Auxiliar!$C$16,0))))))) -> 0 | AE20: 3 | AF20: x | AG20: 4 | AH20: =IF(OR($E20="",$G20=""),"",IF(AND(AE20=$E20,AG20=$G20),Auxiliar!$C$11,IF(AND(SIGN($E20-$G20)=SIGN(AE20-AG20),MAX($E20,$G20)=MAX(AE20,AG20)),Auxiliar!$C$12,IF(ABS($E20-$G20)=ABS(AE20-AG20),Auxiliar!$C$13,IF(AND(SIGN($E20-$G20)=SIGN(AE20-AG20),MIN($E20,$G20)=MIN(AE20,AG20)),Auxiliar!$C$14,IF(SIGN($E20-$G20)=SIGN(AE20-AG20),Auxiliar!$C$15,IF(AE20=AG20,Auxiliar!$C$16,0))))))) -> 10
C21: 1 | D21: SAO | E21: 3 | F21: x | G21: 1 | H21: FLU | K21: 2 | L21: x | M21: 4 | N21: =IF(OR($E21="",$G21=""),"",IF(AND(K21=$E21,M21=$G21),Auxiliar!$C$11,IF(AND(SIGN($E21-$G21)=SIGN(K21-M21),MAX($E21,$G21)=MAX(K21,M21)),Auxiliar!$C$12,IF(ABS($E21-$G21)=ABS(K21-M21),Auxiliar!$C$13,IF(AND(SIGN($E21-$G21)=SIGN(K21-M21),MIN($E21,$G21)=MIN(K21,M21)),Auxiliar!$C$14,IF(SIGN($E21-$G21)=SIGN(K21-M21),Auxiliar!$C$15,IF(K21=M21,Auxiliar!$C$16,0))))))) -> 15 | P21: 3 | Q21: x | R21: 2 | S21: =IF(OR($E21="",$G21=""),"",IF(AND(P21=$E21,R21=$G21),Auxiliar!$C$11,IF(AND(SIGN($E21-$G21)=SIGN(P21-R21),MAX($E21,$G21)=MAX(P21,R21)),Auxiliar!$C$12,IF(ABS($E21-$G21)=ABS(P21-R21),Auxiliar!$C$13,IF(AND(SIGN($E21-$G21)=SIGN(P21-R21),MIN($E21,$G21)=MIN(P21,R21)),Auxiliar!$C$14,IF(SIGN($E21-$G21)=SIGN(P21-R21),Auxiliar!$C$15,IF(P21=R21,Auxiliar!$C$16,0))))))) -> 18 | U21: 1 | V21: x | W21: 0 | X21: =IF(OR($E21="",$G21=""),"",IF(AND(U21=$E21,W21=$G21),Auxiliar!$C$11,IF(AND(SIGN($E21-$G21)=SIGN(U21-W21),MAX($E21,$G21)=MAX(U21,W21)),Auxiliar!$C$12,IF(ABS($E21-$G21)=ABS(U21-W21),Auxiliar!$C$13,IF(AND(SIGN($E21-$G21)=SIGN(U21-W21),MIN($E21,$G21)=MIN(U21,W21)),Auxiliar!$C$14,IF(SIGN($E21-$G21)=SIGN(U21-W21),Auxiliar!$C$15,IF(U21=W21,Auxiliar!$C$16,0))))))) -> 10 | Z21: 2 | AA21: x | AB21: 2 | AC21: =IF(OR($E21="",$G21=""),"",IF(AND(Z21=$E21,AB21=$G21),Auxiliar!$C$11,IF(AND(SIGN($E21-$G21)=SIGN(Z21-AB21),MAX($E21,$G21)=MAX(Z21,AB21)),Auxiliar!$C$12,IF(ABS($E21-$G21)=ABS(Z21-AB21),Auxiliar!$C$13,IF(AND(SIGN($E21-$G21)=SIGN(Z21-AB21),MIN($E21,$G21)=MIN(Z21,AB21)),Auxiliar!$C$14,IF(SIGN($E21-$G21)=SIGN(Z21-AB21),Auxiliar!$C$15,IF(Z21=AB21,Auxiliar!$C$16,0))))))) -> 5 | AE21: 1 | AF21: x | AG21: 3 | AH21: =IF(OR($E21="",$G21=""),"",IF(AND(AE21=$E21,AG21=$G21),Auxiliar!$C$11,IF(AND(SIGN($E21-$G21)=SIGN(AE21-AG21),MAX($E21,$G21)=MAX(AE21,AG21)),Auxiliar!$C$12,IF(ABS($E21-$G21)=ABS(AE21-AG21),Auxiliar!$C$13,IF(AND(SIGN($E21-$G21)=SIGN(AE21-AG21),MIN($E21,$G21)=MIN(AE21,AG21)),Auxiliar!$C$14,IF(SIGN($E21-$G21)=SIGN(AE21-AG21),Auxiliar!$C$15,IF(AE21=AG21,Auxiliar!$C$16,0))))))) -> 15
C22: 1 | D22: CAM | E22: 2 | F22: x | G22: 1 | H22: FOR | K22: 2 | L22: x | M22: 1 | N22: =IF(OR($E22="",$G22=""),"",IF(AND(K22=$E22,M22=$G22),Auxiliar!$C$11,IF(AND(SIGN($E22-$G22)=SIGN(K22-M22),MAX($E22,$G22)=MAX(K22,M22)),Auxiliar!$C$12,IF(ABS($E22-$G22)=ABS(K22-M22),Auxiliar!$C$13,IF(AND(SIGN($E22-$G22)=SIGN(K22-M22),MIN($E22,$G22)=MIN(K22,M22)),Auxiliar!$C$14,IF(SIGN($E22-$G22)=SIGN(K22-M22),Auxiliar!$C$15,IF(K22=M22,Auxiliar!$C$16,0))))))) -> 25 | P22: 5 | Q22: x | R22: 2 | S22: =IF(OR($E22="",$G22=""),"",IF(AND(P22=$E22,R22=$G22),Auxiliar!$C$11,IF(AND(SIGN($E22-$G22)=SIGN(P22-R22),MAX($E22,$G22)=MAX(P22,R22)),Auxiliar!$C$12,IF(ABS($E22-$G22)=ABS(P22-R22),Auxiliar!$C$13,IF(AND(SIGN($E22-$G22)=SIGN(P22-R22),MIN($E22,$G22)=MIN(P22,R22)),Auxiliar!$C$14,IF(SIGN($E22-$G22)=SIGN(P22-R22),Auxiliar!$C$15,IF(P22=R22,Auxiliar!$C$16,0))))))) -> 10 | U22: 2 | V22: x | W22: 2 | X22: =IF(OR($E22="",$G22=""),"",IF(AND(U22=$E22,W22=$G22),Auxiliar!$C$11,IF(AND(SIGN($E22-$G22)=SIGN(U22-W22),MAX($E22,$G22)=MAX(U22,W22)),Auxiliar!$C$12,IF(ABS($E22-$G22)=ABS(U22-W22),Auxiliar!$C$13,IF(AND(SIGN($E22-$G22)=SIGN(U22-W22),MIN($E22,$G22)=MIN(U22,W22)),Auxiliar!$C$14,IF(SIGN($E22-$G22)=SIGN(U22-W22),Auxiliar!$C$15,IF(U22=W22,Auxiliar!$C$16,0))))))) -> 5 | Z22: 2 | AA22: x | AB22: 5 | AC22: =IF(OR($E22="",$G22=""),"",IF(AND(Z22=$E22,AB22=$G22),Auxiliar!$C$11,IF(AND(SIGN($E22-$G22)=SIGN(Z22-AB22),MAX($E22,$G22)=MAX(Z22,AB22)),Auxiliar!$C$12,IF(ABS($E22-$G22)=ABS(Z22-AB22),Auxiliar!$C$13,IF(AND(SIGN($E22-$G22)=SIGN(Z22-AB22),MIN($E22,$G22)=MIN(Z22,AB22)),Auxiliar!$C$14,IF(SIGN($E22-$G22)=SIGN(Z22-AB22),Auxiliar!$C$15,IF(Z22=AB22,Auxiliar!$C$16,0))))))) -> 0 | AE22: 2 | AF22: x | AG22: 3 | AH22: =IF(OR($E22="",$G22=""),"",IF(AND(AE22=$E22,AG22=$G22),Auxiliar!$C$11,IF(AND(SIGN($E22-$G22)=SIGN(AE22-AG22),MAX($E22,$G22)=MAX(AE22,AG22)),Auxiliar!$C$12,IF(ABS($E22-$G22)=ABS(AE22-AG22),Auxiliar!$C$13,IF(AND(SIGN($E22-$G22)=SIGN(AE22-AG22),MIN($E22,$G22)=MIN(AE22,AG22)),Auxiliar!$C$14,IF(SIGN($E22-$G22)=SIGN(AE22-AG22),Auxiliar!$C$15,IF(AE22=AG22,Auxiliar!$C$16,0))))))) -> 15
C23: 1 | D23: INT | E23: 3 | F23: x | G23: 2 | H23: SPT | K23: 0 | L23: x | M23: 3 | N23: =IF(OR($E23="",$G23=""),"",IF(AND(K23=$E23,M23=$G23),Auxiliar!$C$11,IF(AND(SIGN($E23-$G23)=SIGN(K23-M23),MAX($E23,$G23)=MAX(K23,M23)),Auxiliar!$C$12,IF(ABS($E23-$G23)=ABS(K23-M23),Auxiliar!$C$13,IF(AND(SIGN($E23-$G23)=SIGN(K23-M23),MIN($E23,$G23)=MIN(K23,M23)),Auxiliar!$C$14,IF(SIGN($E23-$G23)=SIGN(K23-M23),Auxiliar!$C$15,IF(K23=M23,Auxiliar!$C$16,0))))))) -> 0 | P23: 2 | Q23: x | R23: 4 | S23: =IF(OR($E23="",$G23=""),"",IF(AND(P23=$E23,R23=$G23),Auxiliar!$C$11,IF(AND(SIGN($E23-$G23)=SIGN(P23-R23),MAX($E23,$G23)=MAX(P23,R23)),Auxiliar!$C$12,IF(ABS($E23-$G23)=ABS(P23-R23),Auxiliar!$C$13,IF(AND(SIGN($E23-$G23)=SIGN(P23-R23),MIN($E23,$G23)=MIN(P23,R23)),Auxiliar!$C$14,IF(SIGN($E23-$G23)=SIGN(P23-R23),Auxiliar!$C$15,IF(P23=R23,Auxiliar!$C$16,0))))))) -> 0 | U23: 5 | V23: x | W23: 0 | X23: =IF(OR($E23="",$G23=""),"",IF(AND(U23=$E23,W23=$G23),Auxiliar!$C$11,IF(AND(SIGN($E23-$G23)=SIGN(U23-W23),MAX($E23,$G23)=MAX(U23,W23)),Auxiliar!$C$12,IF(ABS($E23-$G23)=ABS(U23-W23),Auxiliar!$C$13,IF(AND(SIGN($E23-$G23)=SIGN(U23-W23),MIN($E23,$G23)=MIN(U23,W23)),Auxiliar!$C$14,IF(SIGN($E23-$G23)=SIGN(U23-W23),Auxiliar!$C$15,IF(U23=W23,Auxiliar!$C$16,0))))))) -> 10 | Z23: 1 | AA23: x | AB23: 0 | AC23: =IF(OR($E23="",$G23=""),"",IF(AND(Z23=$E23,AB23=$G23),Auxiliar!$C$11,IF(AND(SIGN($E23-$G23)=SIGN(Z23-AB23),MAX($E23,$G23)=MAX(Z23,AB23)),Auxiliar!$C$12,IF(ABS($E23-$G23)=ABS(Z23-AB23),Auxiliar!$C$13,IF(AND(SIGN($E23-$G23)=SIGN(Z23-AB23),MIN($E23,$G23)=MIN(Z23,AB23)),Auxiliar!$C$14,IF(SIGN($E23-$G23)=SIGN(Z23-AB23),Auxiliar!$C$15,IF(Z23=AB23,Auxiliar!$C$16,0))))))) -> 15 | AE23: 0 | AF23: x | AG23: 5 | AH23: =IF(OR($E23="",$G23=""),"",IF(AND(AE23=$E23,AG23=$G23),Auxiliar!$C$11,IF(AND(SIGN($E23-$G23)=SIGN(AE23-AG23),MAX($E23,$G23)=MAX(AE23,AG23)),Auxiliar!$C$12,IF(ABS($E23-$G23)=ABS(AE23-AG23),Auxiliar!$C$13,IF(AND(SIGN($E23-$G23)=SIGN(AE23-AG23),MIN($E23,$G23)=MIN(AE23,AG23)),Auxiliar!$C$14,IF(SIGN($E23-$G23)=SIGN(AE23-AG23),Auxiliar!$C$15,IF(AE23=AG23,Auxiliar!$C$16,0))))))) -> 0
C24: 1 | D24: CEA | E24: 2 | F24: x | G24: 1 | H24: GRE | K24: 5 | L24: x | M24: 3 | N24: =IF(OR($E24="",$G24=""),"",IF(AND(K24=$E24,M24=$G24),Auxiliar!$C$11,IF(AND(SIGN($E24-$G24)=SIGN(K24-M24),MAX($E24,$G24)=MAX(K24,M24)),Auxiliar!$C$12,IF(ABS($E24-$G24)=ABS(K24-M24),Auxiliar!$C$13,IF(AND(SIGN($E24-$G24)=SIGN(K24-M24),MIN($E24,$G24)=MIN(K24,M24)),Auxiliar!$C$14,IF(SIGN($E24-$G24)=SIGN(K24-M24),Auxiliar!$C$15,IF(K24=M24,Auxiliar!$C$16,0))))))) -> 10 | P24: 5 | Q24: x | R24: 3 | S24: =IF(OR($E24="",$G24=""),"",IF(AND(P24=$E24,R24=$G24),Auxiliar!$C$11,IF(AND(SIGN($E24-$G24)=SIGN(P24-R24),MAX($E24,$G24)=MAX(P24,R24)),Auxiliar!$C$12,IF(ABS($E24-$G24)=ABS(P24-R24),Auxiliar!$C$13,IF(AND(SIGN($E24-$G24)=SIGN(P24-R24),MIN($E24,$G24)=MIN(P24,R24)),Auxiliar!$C$14,IF(SIGN($E24-$G24)=SIGN(P24-R24),Auxiliar!$C$15,IF(P24=R24,Auxiliar!$C$16,0))))))) -> 10 | U24: 4 | V24: x | W24: 3 | X24: =IF(OR($E24="",$G24=""),"",IF(AND(U24=$E24,W24=$G24),Auxiliar!$C$11,IF(AND(SIGN($E24-$G24)=SIGN(U24-W24),MAX($E24,$G24)=MAX(U24,W24)),Auxiliar!$C$12,IF(ABS($E24-$G24)=ABS(U24-W24),Auxiliar!$C$13,IF(AND(SIGN($E24-$G24)=SIGN(U24-W24),MIN($E24,$G24)=MIN(U24,W24)),Auxiliar!$C$14,IF(SIGN($E24-$G24)=SIGN(U24-W24),Auxiliar!$C$15,IF(U24=W24,Auxiliar!$C$16,0))))))) -> 15 | Z24: 1 | AA24: x | AB24: 4 | AC24: =IF(OR($E24="",$G24=""),"",IF(AND(Z24=$E24,AB24=$G24),Auxiliar!$C$11,IF(AND(SIGN($E24-$G24)=SIGN(Z24-AB24),MAX($E24,$G24)=MAX(Z24,AB24)),Auxiliar!$C$12,IF(ABS($E24-$G24)=ABS(Z24-AB24),Auxiliar!$C$13,IF(AND(SIGN($E24-$G24)=SIGN(Z24-AB24),MIN($E24,$G24)=MIN(Z24,AB24)),Auxiliar!$C$14,IF(SIGN($E24-$G24)=SIGN(Z24-AB24),Auxiliar!$C$15,IF(Z24=AB24,Auxiliar!$C$16,0))))))) -> 0 | AE24: 2 | AF24: x | AG24: 1 | AH24: =IF(OR($E24="",$G24=""),"",IF(AND(AE24=$E24,AG24=$G24),Auxiliar!$C$11,IF(AND(SIGN($E24-$G24)=SIGN(AE24-AG24),MAX($E24,$G24)=MAX(AE24,AG24)),Auxiliar!$C$12,IF(ABS($E24-$G24)=ABS(AE24-AG24),Auxiliar!$C$13,IF(AND(SIGN($E24-$G24)=SIGN(AE24-AG24),MIN($E24,$G24)=MIN(AE24,AG24)),Auxiliar!$C$14,IF(SIGN($E24-$G24)=SIGN(AE24-AG24),Auxiliar!$C$15,IF(AE24=AG24,Auxiliar!$C$16,0))))))) -> 25
C25: 1 | D25: BAH | E25: 3 | F25: x | G25: 0 | H25: SAN | K25: 0 | L25: x | M25: 4 | N25: =IF(OR($E25="",$G25=""),"",IF(AND(K25=$E25,M25=$G25),Auxiliar!$C$11,IF(AND(SIGN($E25-$G25)=SIGN(K25-M25),MAX($E25,$G25)=MAX(K25,M25)),Auxiliar!$C$12,IF(ABS($E25-$G25)=ABS(K25-M25),Auxiliar!$C$13,IF(AND(SIGN($E25-$G25)=SIGN(K25-M25),MIN($E25,$G25)=MIN(K25,M25)),Auxiliar!$C$14,IF(SIGN($E25-$G25)=SIGN(K25-M25),Auxiliar!$C$15,IF(K25=M25,Auxiliar!$C$16,0))))))) -> 0 | P25: 5 | Q25: x | R25: 4 | S25: =IF(OR($E25="",$G25=""),"",IF(AND(P25=$E25,R25=$G25),Auxiliar!$C$11,IF(AND(SIGN($E25-$G25)=SIGN(P25-R25),MAX($E25,$G25)=MAX(P25,R25)),Auxiliar!$C$12,IF(ABS($E25-$G25)=ABS(P25-R25),Auxiliar!$C$13,IF(AND(SIGN($E25-$G25)=SIGN(P25-R25),MIN($E25,$G25)=MIN(P25,R25)),Auxiliar!$C$14,IF(SIGN($E25-$G25)=SIGN(P25-R25),Auxiliar!$C$15,IF(P25=R25,Auxiliar!$C$16,0))))))) -> 10 | U25: 4 | V25: x | W25: 1 | X25: =IF(OR($E25="",$G25=""),"",IF(AND(U25=$E25,W25=$G25),Auxiliar!$C$11,IF(AND(SIGN($E25-$G25)=SIGN(U25-W25),MAX($E25,$G25)=MAX(U25,W25)),Auxiliar!$C$12,IF(ABS($E25-$G25)=ABS(U25-W25),Auxiliar!$C$13,IF(AND(SIGN($E25-$G25)=SIGN(U25-W25),MIN($E25,$G25)=MIN(U25,W25)),Auxiliar!$C$14,IF(SIGN($E25-$G25)=SIGN(U25-W25),Auxiliar!$C$15,IF(U25=W25,Auxiliar!$C$16,0))))))) -> 15 | Z25: 4 | AA25: x | AB25: 1 | AC25: =IF(OR($E25="",$G25=""),"",IF(AND(Z25=$E25,AB25=$G25),Auxiliar!$C$11,IF(AND(SIGN($E25-$G25)=SIGN(Z25-AB25),MAX($E25,$G25)=MAX(Z25,AB25)),Auxiliar!$C$12,IF(ABS($E25-$G25)=ABS(Z25-AB25),Auxiliar!$C$13,IF(AND(SIGN($E25-$G25)=SIGN(Z25-AB25),MIN($E25,$G25)=MIN(Z25,AB25)),Auxiliar!$C$14,IF(SIGN($E25-$G25)=SIGN(Z25-AB25),Auxiliar!$C$15,IF(Z25=AB25,Auxiliar!$C$16,0))))))) -> 15 | AE25: 5 | AF25: x | AG25: 3 | AH25: =IF(OR($E25="",$G25=""),"",IF(AND(AE25=$E25,AG25=$G25),Auxiliar!$C$11,IF(AND(SIGN($E25-$G25)=SIGN(AE25-AG25),MAX($E25,$G25)=MAX(AE25,AG25)),Auxiliar!$C$12,IF(ABS($E25-$G25)=ABS(AE25-AG25),Auxiliar!$C$13,IF(AND(SIGN($E25-$G25)=SIGN(AE25-AG25),MIN($E25,$G25)=MIN(AE25,AG25)),Auxiliar!$C$14,IF(SIGN($E25-$G25)=SIGN(AE25-AG25),Auxiliar!$C$15,IF(AE25=AG25,Auxiliar!$C$16,0))))))) -> 10
C26: 1 | D26: CHA | E26: 5 | F26: x | G26: 0 | H26: BGT | K26: 4 | L26: x | M26: 5 | N26: =IF(OR($E26="",$G26=""),"",IF(AND(K26=$E26,M26=$G26),Auxiliar!$C$11,IF(AND(SIGN($E26-$G26)=SIGN(K26-M26),MAX($E26,$G26)=MAX(K26,M26)),Auxiliar!$C$12,IF(ABS($E26-$G26)=ABS(K26-M26),Auxiliar!$C$13,IF(AND(SIGN($E26-$G26)=SIGN(K26-M26),MIN($E26,$G26)=MIN(K26,M26)),Auxiliar!$C$14,IF(SIGN($E26-$G26)=SIGN(K26-M26),Auxiliar!$C$15,IF(K26=M26,Auxiliar!$C$16,0))))))) -> 0 | P26: 0 | Q26: x | R26: 0 | S26: =IF(OR($E26="",$G26=""),"",IF(AND(P26=$E26,R26=$G26),Auxiliar!$C$11,IF(AND(SIGN($E26-$G26)=SIGN(P26-R26),MAX($E26,$G26)=MAX(P26,R26)),Auxiliar!$C$12,IF(ABS($E26-$G26)=ABS(P26-R26),Auxiliar!$C$13,IF(AND(SIGN($E26-$G26)=SIGN(P26-R26),MIN($E26,$G26)=MIN(P26,R26)),Auxiliar!$C$14,IF(SIGN($E26-$G26)=SIGN(P26-R26),Auxiliar!$C$15,IF(P26=R26,Auxiliar!$C$16,0))))))) -> 5 | U26: 0 | V26: x | W26: 1 | X26: =IF(OR($E26="",$G26=""),"",IF(AND(U26=$E26,W26=$G26),Auxiliar!$C$11,IF(AND(SIGN($E26-$G26)=SIGN(U26-W26),MAX($E26,$G26)=MAX(U26,W26)),Auxiliar!$C$12,IF(ABS($E26-$G26)=ABS(U26-W26),Auxiliar!$C$13,IF(AND(SIGN($E26-$G26)=SIGN(U26-W26),MIN($E26,$G26)=MIN(U26,W26)),Auxiliar!$C$14,IF(SIGN($E26-$G26)=SIGN(U26-W26),Auxiliar!$C$15,IF(U26=W26,Auxiliar!$C$16,0))))))) -> 0 | Z26: 3 | AA26: x | AB26: 0 | AC26: =IF(OR($E26="",$G26=""),"",IF(AND(Z26=$E26,AB26=$G26),Auxiliar!$C$11,IF(AND(SIGN($E26-$G26)=SIGN(Z26-AB26),MAX($E26,$G26)=MAX(Z26,AB26)),Auxiliar!$C$12,IF(ABS($E26-$G26)=ABS(Z26-AB26),Auxiliar!$C$13,IF(AND(SIGN($E26-$G26)=SIGN(Z26-AB26),MIN($E26,$G26)=MIN(Z26,AB26)),Auxiliar!$C$14,IF(SIGN($E26-$G26)=SIGN(Z26-AB26),Auxiliar!$C$15,IF(Z26=AB26,Auxiliar!$C$16,0))))))) -> 12 | AE26: 0 | AF26: x | AG26: 4 | AH26: =IF(OR($E26="",$G26=""),"",IF(AND(AE26=$E26,AG26=$G26),Auxiliar!$C$11,IF(AND(SIGN($E26-$G26)=SIGN(AE26-AG26),MAX($E26,$G26)=MAX(AE26,AG26)),Auxiliar!$C$12,IF(ABS($E26-$G26)=ABS(AE26-AG26),Auxiliar!$C$13,IF(AND(SIGN($E26-$G26)=SIGN(AE26-AG26),MIN($E26,$G26)=MIN(AE26,AG26)),Auxiliar!$C$14,IF(SIGN($E26-$G26)=SIGN(AE26-AG26),Auxiliar!$C$15,IF(AE26=AG26,Auxiliar!$C$16,0))))))) -> 0
C27: 1 | D27: CAP | E27: 0 | F27: x | G27: 4 | H27: AME | K27: 5 | L27: x | M27: 1 | N27: =IF(OR($E27="",$G27=""),"",IF(AND(K27=$E27,M27=$G27),Auxiliar!$C$11,IF(AND(SIGN($E27-$G27)=SIGN(K27-M27),MAX($E27,$G27)=MAX(K27,M27)),Auxiliar!$C$12,IF(ABS($E27-$G27)=ABS(K27-M27),Auxiliar!$C$13,IF(AND(SIGN($E27-$G27)=SIGN(K27-M27),MIN($E27,$G27)=MIN(K27,M27)),Auxiliar!$C$14,IF(SIGN($E27-$G27)=SIGN(K27-M27),Auxiliar!$C$15,IF(K27=M27,Auxiliar!$C$16,0))))))) -> 15 | P27: 2 | Q27: x | R27: 4 | S27: =IF(OR($E27="",$G27=""),"",IF(AND(P27=$E27,R27=$G27),Auxiliar!$C$11,IF(AND(SIGN($E27-$G27)=SIGN(P27-R27),MAX($E27,$G27)=MAX(P27,R27)),Auxiliar!$C$12,IF(ABS($E27-$G27)=ABS(P27-R27),Auxiliar!$C$13,IF(AND(SIGN($E27-$G27)=SIGN(P27-R27),MIN($E27,$G27)=MIN(P27,R27)),Auxiliar!$C$14,IF(SIGN($E27-$G27)=SIGN(P27-R27),Auxiliar!$C$15,IF(P27=R27,Auxiliar!$C$16,0))))))) -> 18 | U27: 0 | V27: x | W27: 5 | X27: =IF(OR($E27="",$G27=""),"",IF(AND(U27=$E27,W27=$G27),Auxiliar!$C$11,IF(AND(SIGN($E27-$G27)=SIGN(U27-W27),MAX($E27,$G27)=MAX(U27,W27)),Auxiliar!$C$12,IF(ABS($E27-$G27)=ABS(U27-W27),Auxiliar!$C$13,IF(AND(SIGN($E27-$G27)=SIGN(U27-W27),MIN($E27,$G27)=MIN(U27,W27)),Auxiliar!$C$14,IF(SIGN($E27-$G27)=SIGN(U27-W27),Auxiliar!$C$15,IF(U27=W27,Auxiliar!$C$16,0))))))) -> 12 | Z27: 5 | AA27: x | AB27: 2 | AC27: =IF(OR($E27="",$G27=""),"",IF(AND(Z27=$E27,AB27=$G27),Auxiliar!$C$11,IF(AND(SIGN($E27-$G27)=SIGN(Z27-AB27),MAX($E27,$G27)=MAX(Z27,AB27)),Auxiliar!$C$12,IF(ABS($E27-$G27)=ABS(Z27-AB27),Auxiliar!$C$13,IF(AND(SIGN($E27-$G27)=SIGN(Z27-AB27),MIN($E27,$G27)=MIN(Z27,AB27)),Auxiliar!$C$14,IF(SIGN($E27-$G27)=SIGN(Z27-AB27),Auxiliar!$C$15,IF(Z27=AB27,Auxiliar!$C$16,0))))))) -> 0 | AE27: 4 | AF27: x | AG27: 0 | AH27: =IF(OR($E27="",$G27=""),"",IF(AND(AE27=$E27,AG27=$G27),Auxiliar!$C$11,IF(AND(SIGN($E27-$G27)=SIGN(AE27-AG27),MAX($E27,$G27)=MAX(AE27,AG27)),Auxiliar!$C$12,IF(ABS($E27-$G27)=ABS(AE27-AG27),Auxiliar!$C$13,IF(AND(SIGN($E27-$G27)=SIGN(AE27-AG27),MIN($E27,$G27)=MIN(AE27,AG27)),Auxiliar!$C$14,IF(SIGN($E27-$G27)=SIGN(AE27-AG27),Auxiliar!$C$15,IF(AE27=AG27,Auxiliar!$C$16,0))))))) -> 15
C28: 1 | D28: CUI | E28: 2 | F28: x | G28: 5 | H28: JUV | K28: 3 | L28: x | M28: 2 | N28: =IF(OR($E28="",$G28=""),"",IF(AND(K28=$E28,M28=$G28),Auxiliar!$C$11,IF(AND(SIGN($E28-$G28)=SIGN(K28-M28),MAX($E28,$G28)=MAX(K28,M28)),Auxiliar!$C$12,IF(ABS($E28-$G28)=ABS(K28-M28),Auxiliar!$C$13,IF(AND(SIGN($E28-$G28)=SIGN(K28-M28),MIN($E28,$G28)=MIN(K28,M28)),Auxiliar!$C$14,IF(SIGN($E28-$G28)=SIGN(K28-M28),Auxiliar!$C$15,IF(K28=M28,Auxiliar!$C$16,0))))))) -> 0 | P28: 3 | Q28: x | R28: 4 | S28: =IF(OR($E28="",$G28=""),"",IF(AND(P28=$E28,R28=$G28),Auxiliar!$C$11,IF(AND(SIGN($E28-$G28)=SIGN(P28-R28),MAX($E28,$G28)=MAX(P28,R28)),Auxiliar!$C$12,IF(ABS($E28-$G28)=ABS(P28-R28),Auxiliar!$C$13,IF(AND(SIGN($E28-$G28)=SIGN(P28-R28),MIN($E28,$G28)=MIN(P28,R28)),Auxiliar!$C$14,IF(SIGN($E28-$G28)=SIGN(P28-R28),Auxiliar!$C$15,IF(P28=R28,Auxiliar!$C$16,0))))))) -> 10 | U28: 4 | V28: x | W28: 5 | X28: =IF(OR($E28="",$G28=""),"",IF(AND(U28=$E28,W28=$G28),Auxiliar!$C$11,IF(AND(SIGN($E28-$G28)=SIGN(U28-W28),MAX($E28,$G28)=MAX(U28,W28)),Auxiliar!$C$12,IF(ABS($E28-$G28)=ABS(U28-W28),Auxiliar!$C$13,IF(AND(SIGN($E28-$G28)=SIGN(U28-W28),MIN($E28,$G28)=MIN(U28,W28)),Auxiliar!$C$14,IF(SIGN($E28-$G28)=SIGN(U28-W28),Auxiliar!$C$15,IF(U28=W28,Auxiliar!$C$16,0))))))) -> 18 | Z28: 4 | AA28: x | AB28: 0 | AC28: =IF(OR($E28="",$G28=""),"",IF(AND(Z28=$E28,AB28=$G28),Auxiliar!$C$11,IF(AND(SIGN($E28-$G28)=SIGN(Z28-AB28),MAX($E28,$G28)=MAX(Z28,AB28)),Auxiliar!$C$12,IF(ABS($E28-$G28)=ABS(Z28-AB28),Auxiliar!$C$13,IF(AND(SIGN($E28-$G28)=SIGN(Z28-AB28),MIN($E28,$G28)=MIN(Z28,AB28)),Auxiliar!$C$14,IF(SIGN($E28-$G28)=SIGN(Z28-AB28),Auxiliar!$C$15,IF(Z28=AB28,Auxiliar!$C$16,0))))))) -> 0 | AE28: 5 | AF28: x | AG28: 0 | AH28: =IF(OR($E28="",$G28=""),"",IF(AND(AE28=$E28,AG28=$G28),Auxiliar!$C$11,IF(AND(SIGN($E28-$G28)=SIGN(AE28-AG28),MAX($E28,$G28)=MAX(AE28,AG28)),Auxiliar!$C$12,IF(ABS($E28-$G28)=ABS(AE28-AG28),Auxiliar!$C$13,IF(AND(SIGN($E28-$G28)=SIGN(AE28-AG28),MIN($E28,$G28)=MIN(AE28,AG28)),Auxiliar!$C$14,IF(SIGN($E28-$G28)=SIGN(AE28-AG28),Auxiliar!$C$15,IF(AE28=AG28,Auxiliar!$C$16,0))))))) -> 0
C29: =C19+1 -> 2 | D29: GRE | E29: 1 | F29: x | G29: 4 | H29: FLA | K29: 4 | L29: x | M29: 1 | N29: =IF(OR($E29="",$G29=""),"",IF(AND(K29=$E29,M29=$G29),Auxiliar!$C$11,IF(AND(SIGN($E29-$G29)=SIGN(K29-M29),MAX($E29,$G29)=MAX(K29,M29)),Auxiliar!$C$12,IF(ABS($E29-$G29)=ABS(K29-M29),Auxiliar!$C$13,IF(AND(SIGN($E29-$G29)=SIGN(K29-M29),MIN($E29,$G29)=MIN(K29,M29)),Auxiliar!$C$14,IF(SIGN($E29-$G29)=SIGN(K29-M29),Auxiliar!$C$15,IF(K29=M29,Auxiliar!$C$16,0))))))) -> 15 | P29: 5 | Q29: x | R29: 3 | S29: =IF(OR($E29="",$G29=""),"",IF(AND(P29=$E29,R29=$G29),Auxiliar!$C$11,IF(AND(SIGN($E29-$G29)=SIGN(P29-R29),MAX($E29,$G29)=MAX(P29,R29)),Auxiliar!$C$12,IF(ABS($E29-$G29)=ABS(P29-R29),Auxiliar!$C$13,IF(AND(SIGN($E29-$G29)=SIGN(P29-R29),MIN($E29,$G29)=MIN(P29,R29)),Auxiliar!$C$14,IF(SIGN($E29-$G29)=SIGN(P29-R29),Auxiliar!$C$15,IF(P29=R29,Auxiliar!$C$16,0))))))) -> 0 | U29: 4 | V29: x | W29: 4 | X29: =IF(OR($E29="",$G29=""),"",IF(AND(U29=$E29,W29=$G29),Auxiliar!$C$11,IF(AND(SIGN($E29-$G29)=SIGN(U29-W29),MAX($E29,$G29)=MAX(U29,W29)),Auxiliar!$C$12,IF(ABS($E29-$G29)=ABS(U29-W29),Auxiliar!$C$13,IF(AND(SIGN($E29-$G29)=SIGN(U29-W29),MIN($E29,$G29)=MIN(U29,W29)),Auxiliar!$C$14,IF(SIGN($E29-$G29)=SIGN(U29-W29),Auxiliar!$C$15,IF(U29=W29,Auxiliar!$C$16,0))))))) -> 5 | Z29: 0 | AA29: x | AB29: 1 | AC29: =IF(OR($E29="",$G29=""),"",IF(AND(Z29=$E29,AB29=$G29),Auxiliar!$C$11,IF(AND(SIGN($E29-$G29)=SIGN(Z29-AB29),MAX($E29,$G29)=MAX(Z29,AB29)),Auxiliar!$C$12,IF(ABS($E29-$G29)=ABS(Z29-AB29),Auxiliar!$C$13,IF(AND(SIGN($E29-$G29)=SIGN(Z29-AB29),MIN($E29,$G29)=MIN(Z29,AB29)),Auxiliar!$C$14,IF(SIGN($E29-$G29)=SIGN(Z29-AB29),Auxiliar!$C$15,IF(Z29=AB29,Auxiliar!$C$16,0))))))) -> 10 | AE29: 5 | AF29: x | AG29: 2 | AH29: =IF(OR($E29="",$G29=""),"",IF(AND(AE29=$E29,AG29=$G29),Auxiliar!$C$11,IF(AND(SIGN($E29-$G29)=SIGN(AE29-AG29),MAX($E29,$G29)=MAX(AE29,AG29)),Auxiliar!$C$12,IF(ABS($E29-$G29)=ABS(AE29-AG29),Auxiliar!$C$13,IF(AND(SIGN($E29-$G29)=SIGN(AE29-AG29),MIN($E29,$G29)=MIN(AE29,AG29)),Auxiliar!$C$14,IF(SIGN($E29-$G29)=SIGN(AE29-AG29),Auxiliar!$C$15,IF(AE29=AG29,Auxiliar!$C$16,0))))))) -> 15
C30: =C20+1 -> 2 | D30: AME | E30: 2 | F30: x | G30: 1 | H30: COR | K30: 0 | L30: x | M30: 5 | N30: =IF(OR($E30="",$G30=""),"",IF(AND(K30=$E30,M30=$G30),Auxiliar!$C$11,IF(AND(SIGN($E30-$G30)=SIGN(K30-M30),MAX($E30,$G30)=MAX(K30,M30)),Auxiliar!$C$12,IF(ABS($E30-$G30)=ABS(K30-M30),Auxiliar!$C$13,IF(AND(SIGN($E30-$G30)=SIGN(K30-M30),MIN($E30,$G30)=MIN(K30,M30)),Auxiliar!$C$14,IF(SIGN($E30-$G30)=SIGN(K30-M30),Auxiliar!$C$15,IF(K30=M30,Auxiliar!$C$16,0))))))) -> 0 | P30: 3 | Q30: x | R30: 5 | S30: =IF(OR($E30="",$G30=""),"",IF(AND(P30=$E30,R30=$G30),Auxiliar!$C$11,IF(AND(SIGN($E30-$G30)=SIGN(P30-R30),MAX($E30,$G30)=MAX(P30,R30)),Auxiliar!$C$12,IF(ABS($E30-$G30)=ABS(P30-R30),Auxiliar!$C$13,IF(AND(SIGN($E30-$G30)=SIGN(P30-R30),MIN($E30,$G30)=MIN(P30,R30)),Auxiliar!$C$14,IF(SIGN($E30-$G30)=SIGN(P30-R30),Auxiliar!$C$15,IF(P30=R30,Auxiliar!$C$16,0))))))) -> 0 | U30: 0 | V30: x | W30: 2 | X30: =IF(OR($E30="",$G30=""),"",IF(AND(U30=$E30,W30=$G30),Auxiliar!$C$11,IF(AND(SIGN($E30-$G30)=SIGN(U30-W30),MAX($E30,$G30)=MAX(U30,W30)),Auxiliar!$C$12,IF(ABS($E30-$G30)=ABS(U30-W30),Auxiliar!$C$13,IF(AND(SIGN($E30-$G30)=SIGN(U30-W30),MIN($E30,$G30)=MIN(U30,W30)),Auxiliar!$C$14,IF(SIGN($E30-$G30)=SIGN(U30-W30),Auxiliar!$C$15,IF(U30=W30,Auxiliar!$C$16,0))))))) -> 0 | Z30: 3 | AA30: x | AB30: 2 | AC30: =IF(OR($E30="",$G30=""),"",IF(AND(Z30=$E30,AB30=$G30),Auxiliar!$C$11,IF(AND(SIGN($E30-$G30)=SIGN(Z30-AB30),MAX($E30,$G30)=MAX(Z30,AB30)),Auxiliar!$C$12,IF(ABS($E30-$G30)=ABS(Z30-AB30),Auxiliar!$C$13,IF(AND(SIGN($E30-$G30)=SIGN(Z30-AB30),MIN($E30,$G30)=MIN(Z30,AB30)),Auxiliar!$C$14,IF(SIGN($E30-$G30)=SIGN(Z30-AB30),Auxiliar!$C$15,IF(Z30=AB30,Auxiliar!$C$16,0))))))) -> 15 | AE30: 2 | AF30: x | AG30: 4 | AH30: =IF(OR($E30="",$G30=""),"",IF(AND(AE30=$E30,AG30=$G30),Auxiliar!$C$11,IF(AND(SIGN($E30-$G30)=SIGN(AE30-AG30),MAX($E30,$G30)=MAX(AE30,AG30)),Auxiliar!$C$12,IF(ABS($E30-$G30)=ABS(AE30-AG30),Auxiliar!$C$13,IF(AND(SIGN($E30-$G30)=SIGN(AE30-AG30),MIN($E30,$G30)=MIN(AE30,AG30)),Auxiliar!$C$14,IF(SIGN($E30-$G30)=SIGN(AE30-AG30),Auxiliar!$C$15,IF(AE30=AG30,Auxiliar!$C$16,0))))))) -> 0
C31: =C21+1 -> 2 | D31: FLU | E31: 5 | F31: x | G31: 5 | H31: CUI | K31: 4 | L31: x | M31: 0 | N31: =IF(OR($E31="",$G31=""),"",IF(AND(K31=$E31,M31=$G31),Auxiliar!$C$11,IF(AND(SIGN($E31-$G31)=SIGN(K31-M31),MAX($E31,$G31)=MAX(K31,M31)),Auxiliar!$C$12,IF(ABS($E31-$G31)=ABS(K31-M31),Auxiliar!$C$13,IF(AND(SIGN($E31-$G31)=SIGN(K31-M31),MIN($E31,$G31)=MIN(K31,M31)),Auxiliar!$C$14,IF(SIGN($E31-$G31)=SIGN(K31-M31),Auxiliar!$C$15,IF(K31=M31,Auxiliar!$C$16,0))))))) -> 0 | P31: 5 | Q31: x | R31: 4 | S31: =IF(OR($E31="",$G31=""),"",IF(AND(P31=$E31,R31=$G31),Auxiliar!$C$11,IF(AND(SIGN($E31-$G31)=SIGN(P31-R31),MAX($E31,$G31)=MAX(P31,R31)),Auxiliar!$C$12,IF(ABS($E31-$G31)=ABS(P31-R31),Auxiliar!$C$13,IF(AND(SIGN($E31-$G31)=SIGN(P31-R31),MIN($E31,$G31)=MIN(P31,R31)),Auxiliar!$C$14,IF(SIGN($E31-$G31)=SIGN(P31-R31),Auxiliar!$C$15,IF(P31=R31,Auxiliar!$C$16,0))))))) -> 0 | U31: 3 | V31: x | W31: 4 | X31: =IF(OR($E31="",$G31=""),"",IF(AND(U31=$E31,W31=$G31),Auxiliar!$C$11,IF(AND(SIGN($E31-$G31)=SIGN(U31-W31),MAX($E31,$G31)=MAX(U31,W31)),Auxiliar!$C$12,IF(ABS($E31-$G31)=ABS(U31-W31),Auxiliar!$C$13,IF(AND(SIGN($E31-$G31)=SIGN(U31-W31),MIN($E31,$G31)=MIN(U31,W31)),Auxiliar!$C$14,IF(SIGN($E31-$G31)=SIGN(U31-W31),Auxiliar!$C$15,IF(U31=W31,Auxiliar!$C$16,0))))))) -> 0 | Z31: 5 | AA31: x | AB31: 0 | AC31: =IF(OR($E31="",$G31=""),"",IF(AND(Z31=$E31,AB31=$G31),Auxiliar!$C$11,IF(AND(SIGN($E31-$G31)=SIGN(Z31-AB31),MAX($E31,$G31)=MAX(Z31,AB31)),Auxiliar!$C$12,IF(ABS($E31-$G31)=ABS(Z31-AB31),Auxiliar!$C$13,IF(AND(SIGN($E31-$G31)=SIGN(Z31-AB31),MIN($E31,$G31)=MIN(Z31,AB31)),Auxiliar!$C$14,IF(SIGN($E31-$G31)=SIGN(Z31-AB31),Auxiliar!$C$15,IF(Z31=AB31,Auxiliar!$C$16,0))))))) -> 0 | AE31: 4 | AF31: x | AG31: 1 | AH31: =IF(OR($E31="",$G31=""),"",IF(AND(AE31=$E31,AG31=$G31),Auxiliar!$C$11,IF(AND(SIGN($E31-$G31)=SIGN(AE31-AG31),MAX($E31,$G31)=MAX(AE31,AG31)),Auxiliar!$C$12,IF(ABS($E31-$G31)=ABS(AE31-AG31),Auxiliar!$C$13,IF(AND(SIGN($E31-$G31)=SIGN(AE31-AG31),MIN($E31,$G31)=MIN(AE31,AG31)),Auxiliar!$C$14,IF(SIGN($E31-$G31)=SIGN(AE31-AG31),Auxiliar!$C$15,IF(AE31=AG31,Auxiliar!$C$16,0))))))) -> 0
C32: =C22+1 -> 2 | D32: PAL | E32: 4 | F32: x | G32: 1 | H32: CHA | K32: 5 | L32: x | M32: 3 | N32: =IF(OR($E32="",$G32=""),"",IF(AND(K32=$E32,M32=$G32),Auxiliar!$C$11,IF(AND(SIGN($E32-$G32)=SIGN(K32-M32),MAX($E32,$G32)=MAX(K32,M32)),Auxiliar!$C$12,IF(ABS($E32-$G32)=ABS(K32-M32),Auxiliar!$C$13,IF(AND(SIGN($E32-$G32)=SIGN(K32-M32),MIN($E32,$G32)=MIN(K32,M32)),Auxiliar!$C$14,IF(SIGN($E32-$G32)=SIGN(K32-M32),Auxiliar!$C$15,IF(K32=M32,Auxiliar!$C$16,0))))))) -> 10 | P32: 0 | Q32: x | R32: 5 | S32: =IF(OR($E32="",$G32=""),"",IF(AND(P32=$E32,R32=$G32),Auxiliar!$C$11,IF(AND(SIGN($E32-$G32)=SIGN(P32-R32),MAX($E32,$G32)=MAX(P32,R32)),Auxiliar!$C$12,IF(ABS($E32-$G32)=ABS(P32-R32),Auxiliar!$C$13,IF(AND(SIGN($E32-$G32)=SIGN(P32-R32),MIN($E32,$G32)=MIN(P32,R32)),Auxiliar!$C$14,IF(SIGN($E32-$G32)=SIGN(P32-R32),Auxiliar!$C$15,IF(P32=R32,Auxiliar!$C$16,0))))))) -> 0 | U32: 1 | V32: x | W32: 2 | X32: =IF(OR($E32="",$G32=""),"",IF(AND(U32=$E32,W32=$G32),Auxiliar!$C$11,IF(AND(SIGN($E32-$G32)=SIGN(U32-W32),MAX($E32,$G32)=MAX(U32,W32)),Auxiliar!$C$12,IF(ABS($E32-$G32)=ABS(U32-W32),Auxiliar!$C$13,IF(AND(SIGN($E32-$G32)=SIGN(U32-W32),MIN($E32,$G32)=MIN(U32,W32)),Auxiliar!$C$14,IF(SIGN($E32-$G32)=SIGN(U32-W32),Auxiliar!$C$15,IF(U32=W32,Auxiliar!$C$16,0))))))) -> 0 | Z32: 1 | AA32: x | AB32: 2 | AC32: =IF(OR($E32="",$G32=""),"",IF(AND(Z32=$E32,AB32=$G32),Auxiliar!$C$11,IF(AND(SIGN($E32-$G32)=SIGN(Z32-AB32),MAX($E32,$G32)=MAX(Z32,AB32)),Auxiliar!$C$12,IF(ABS($E32-$G32)=ABS(Z32-AB32),Auxiliar!$C$13,IF(AND(SIGN($E32-$G32)=SIGN(Z32-AB32),MIN($E32,$G32)=MIN(Z32,AB32)),Auxiliar!$C$14,IF(SIGN($E32-$G32)=SIGN(Z32-AB32),Auxiliar!$C$15,IF(Z32=AB32,Auxiliar!$C$16,0))))))) -> 0 | AE32: 2 | AF32: x | AG32: 0 | AH32: =IF(OR($E32="",$G32=""),"",IF(AND(AE32=$E32,AG32=$G32),Auxiliar!$C$11,IF(AND(SIGN($E32-$G32)=SIGN(AE32-AG32),MAX($E32,$G32)=MAX(AE32,AG32)),Auxiliar!$C$12,IF(ABS($E32-$G32)=ABS(AE32-AG32),Auxiliar!$C$13,IF(AND(SIGN($E32-$G32)=SIGN(AE32-AG32),MIN($E32,$G32)=MIN(AE32,AG32)),Auxiliar!$C$14,IF(SIGN($E32-$G32)=SIGN(AE32-AG32),Auxiliar!$C$15,IF(AE32=AG32,Auxiliar!$C$16,0))))))) -> 10
C33: =C23+1 -> 2 | D33: SAN | E33: 3 | F33: x | G33: 4 | H33: CEA | K33: 5 | L33: x | M33: 2 | N33: =IF(OR($E33="",$G33=""),"",IF(AND(K33=$E33,M33=$G33),Auxiliar!$C$11,IF(AND(SIGN($E33-$G33)=SIGN(K33-M33),MAX($E33,$G33)=MAX(K33,M33)),Auxiliar!$C$12,IF(ABS($E33-$G33)=ABS(K33-M33),Auxiliar!$C$13,IF(AND(SIGN($E33-$G33)=SIGN(K33-M33),MIN($E33,$G33)=MIN(K33,M33)),Auxiliar!$C$14,IF(SIGN($E33-$G33)=SIGN(K33-M33),Auxiliar!$C$15,IF(K33=M33,Auxiliar!$C$16,0))))))) -> 0 | P33: 0 | Q33: x | R33: 5 | S33: =IF(OR($E33="",$G33=""),"",IF(AND(P33=$E33,R33=$G33),Auxiliar!$C$11,IF(AND(SIGN($E33-$G33)=SIGN(P33-R33),MAX($E33,$G33)=MAX(P33,R33)),Auxiliar!$C$12,IF(ABS($E33-$G33)=ABS(P33-R33),Auxiliar!$C$13,IF(AND(SIGN($E33-$G33)=SIGN(P33-R33),MIN($E33,$G33)=MIN(P33,R33)),Auxiliar!$C$14,IF(SIGN($E33-$G33)=SIGN(P33-R33),Auxiliar!$C$15,IF(P33=R33,Auxiliar!$C$16,0))))))) -> 10 | U33: 4 | V33: x | W33: 3 | X33: =IF(OR($E33="",$G33=""),"",IF(AND(U33=$E33,W33=$G33),Auxiliar!$C$11,IF(AND(SIGN($E33-$G33)=SIGN(U33-W33),MAX($E33,$G33)=MAX(U33,W33)),Auxiliar!$C$12,IF(ABS($E33-$G33)=ABS(U33-W33),Auxiliar!$C$13,IF(AND(SIGN($E33-$G33)=SIGN(U33-W33),MIN($E33,$G33)=MIN(U33,W33)),Auxiliar!$C$14,IF(SIGN($E33-$G33)=SIGN(U33-W33),Auxiliar!$C$15,IF(U33=W33,Auxiliar!$C$16,0))))))) -> 15 | Z33: 3 | AA33: x | AB33: 2 | AC33: =IF(OR($E33="",$G33=""),"",IF(AND(Z33=$E33,AB33=$G33),Auxiliar!$C$11,IF(AND(SIGN($E33-$G33)=SIGN(Z33-AB33),MAX($E33,$G33)=MAX(Z33,AB33)),Auxiliar!$C$12,IF(ABS($E33-$G33)=ABS(Z33-AB33),Auxiliar!$C$13,IF(AND(SIGN($E33-$G33)=SIGN(Z33-AB33),MIN($E33,$G33)=MIN(Z33,AB33)),Auxiliar!$C$14,IF(SIGN($E33-$G33)=SIGN(Z33-AB33),Auxiliar!$C$15,IF(Z33=AB33,Auxiliar!$C$16,0))))))) -> 15 | AE33: 2 | AF33: x | AG33: 2 | AH33: =IF(OR($E33="",$G33=""),"",IF(AND(AE33=$E33,AG33=$G33),Auxiliar!$C$11,IF(AND(SIGN($E33-$G33)=SIGN(AE33-AG33),MAX($E33,$G33)=MAX(AE33,AG33)),Auxiliar!$C$12,IF(ABS($E33-$G33)=ABS(AE33-AG33),Auxiliar!$C$13,IF(AND(SIGN($E33-$G33)=SIGN(AE33-AG33),MIN($E33,$G33)=MIN(AE33,AG33)),Auxiliar!$C$14,IF(SIGN($E33-$G33)=SIGN(AE33-AG33),Auxiliar!$C$15,IF(AE33=AG33,Auxiliar!$C$16,0))))))) -> 5
C34: =C24+1 -> 2 | D34: FOR | E34: 3 | F34: x | G34: 2 | H34: INT | K34: 3 | L34: x | M34: 2 | N34: =IF(OR($E34="",$G34=""),"",IF(AND(K34=$E34,M34=$G34),Auxiliar!$C$11,IF(AND(SIGN($E34-$G34)=SIGN(K34-M34),MAX($E34,$G34)=MAX(K34,M34)),Auxiliar!$C$12,IF(ABS($E34-$G34)=ABS(K34-M34),Auxiliar!$C$13,IF(AND(SIGN($E34-$G34)=SIGN(K34-M34),MIN($E34,$G34)=MIN(K34,M34)),Auxiliar!$C$14,IF(SIGN($E34-$G34)=SIGN(K34-M34),Auxiliar!$C$15,IF(K34=M34,Auxiliar!$C$16,0))))))) -> 25 | P34: 4 | Q34: x | R34: 1 | S34: =IF(OR($E34="",$G34=""),"",IF(AND(P34=$E34,R34=$G34),Auxiliar!$C$11,IF(AND(SIGN($E34-$G34)=SIGN(P34-R34),MAX($E34,$G34)=MAX(P34,R34)),Auxiliar!$C$12,IF(ABS($E34-$G34)=ABS(P34-R34),Auxiliar!$C$13,IF(AND(SIGN($E34-$G34)=SIGN(P34-R34),MIN($E34,$G34)=MIN(P34,R34)),Auxiliar!$C$14,IF(SIGN($E34-$G34)=SIGN(P34-R34),Auxiliar!$C$15,IF(P34=R34,Auxiliar!$C$16,0))))))) -> 10 | U34: 3 | V34: x | W34: 4 | X34: =IF(OR($E34="",$G34=""),"",IF(AND(U34=$E34,W34=$G34),Auxiliar!$C$11,IF(AND(SIGN($E34-$G34)=SIGN(U34-W34),MAX($E34,$G34)=MAX(U34,W34)),Auxiliar!$C$12,IF(ABS($E34-$G34)=ABS(U34-W34),Auxiliar!$C$13,IF(AND(SIGN($E34-$G34)=SIGN(U34-W34),MIN($E34,$G34)=MIN(U34,W34)),Auxiliar!$C$14,IF(SIGN($E34-$G34)=SIGN(U34-W34),Auxiliar!$C$15,IF(U34=W34,Auxiliar!$C$16,0))))))) -> 15 | Z34: 4 | AA34: x | AB34: 5 | AC34: =IF(OR($E34="",$G34=""),"",IF(AND(Z34=$E34,AB34=$G34),Auxiliar!$C$11,IF(AND(SIGN($E34-$G34)=SIGN(Z34-AB34),MAX($E34,$G34)=MAX(Z34,AB34)),Auxiliar!$C$12,IF(ABS($E34-$G34)=ABS(Z34-AB34),Auxiliar!$C$13,IF(AND(SIGN($E34-$G34)=SIGN(Z34-AB34),MIN($E34,$G34)=MIN(Z34,AB34)),Auxiliar!$C$14,IF(SIGN($E34-$G34)=SIGN(Z34-AB34),Auxiliar!$C$15,IF(Z34=AB34,Auxiliar!$C$16,0))))))) -> 15 | AE34: 1 | AF34: x | AG34: 2 | AH34: =IF(OR($E34="",$G34=""),"",IF(AND(AE34=$E34,AG34=$G34),Auxiliar!$C$11,IF(AND(SIGN($E34-$G34)=SIGN(AE34-AG34),MAX($E34,$G34)=MAX(AE34,AG34)),Auxiliar!$C$12,IF(ABS($E34-$G34)=ABS(AE34-AG34),Auxiliar!$C$13,IF(AND(SIGN($E34-$G34)=SIGN(AE34-AG34),MIN($E34,$G34)=MIN(AE34,AG34)),Auxiliar!$C$14,IF(SIGN($E34-$G34)=SIGN(AE34-AG34),Auxiliar!$C$15,IF(AE34=AG34,Auxiliar!$C$16,0))))))) -> 15
C35: =C25+1 -> 2 | D35: SPT | E35: 0 | F35: x | G35: 5 | H35: CAM | K35: 3 | L35: x | M35: 4 | N35: =IF(OR($E35="",$G35=""),"",IF(AND(K35=$E35,M35=$G35),Auxiliar!$C$11,IF(AND(SIGN($E35-$G35)=SIGN(K35-M35),MAX($E35,$G35)=MAX(K35,M35)),Auxiliar!$C$12,IF(ABS($E35-$G35)=ABS(K35-M35),Auxiliar!$C$13,IF(AND(SIGN($E35-$G35)=SIGN(K35-M35),MIN($E35,$G35)=MIN(K35,M35)),Auxiliar!$C$14,IF(SIGN($E35-$G35)=SIGN(K35-M35),Auxiliar!$C$15,IF(K35=M35,Auxiliar!$C$16,0))))))) -> 10 | P35: 5 | Q35: x | R35: 4 | S35: =IF(OR($E35="",$G35=""),"",IF(AND(P35=$E35,R35=$G35),Auxiliar!$C$11,IF(AND(SIGN($E35-$G35)=SIGN(P35-R35),MAX($E35,$G35)=MAX(P35,R35)),Auxiliar!$C$12,IF(ABS($E35-$G35)=ABS(P35-R35),Auxiliar!$C$13,IF(AND(SIGN($E35-$G35)=SIGN(P35-R35),MIN($E35,$G35)=MIN(P35,R35)),Auxiliar!$C$14,IF(SIGN($E35-$G35)=SIGN(P35-R35),Auxiliar!$C$15,IF(P35=R35,Auxiliar!$C$16,0))))))) -> 0 | U35: 0 | V35: x | W35: 4 | X35: =IF(OR($E35="",$G35=""),"",IF(AND(U35=$E35,W35=$G35),Auxiliar!$C$11,IF(AND(SIGN($E35-$G35)=SIGN(U35-W35),MAX($E35,$G35)=MAX(U35,W35)),Auxiliar!$C$12,IF(ABS($E35-$G35)=ABS(U35-W35),Auxiliar!$C$13,IF(AND(SIGN($E35-$G35)=SIGN(U35-W35),MIN($E35,$G35)=MIN(U35,W35)),Auxiliar!$C$14,IF(SIGN($E35-$G35)=SIGN(U35-W35),Auxiliar!$C$15,IF(U35=W35,Auxiliar!$C$16,0))))))) -> 12 | Z35: 4 | AA35: x | AB35: 2 | AC35: =IF(OR($E35="",$G35=""),"",IF(AND(Z35=$E35,AB35=$G35),Auxiliar!$C$11,IF(AND(SIGN($E35-$G35)=SIGN(Z35-AB35),MAX($E35,$G35)=MAX(Z35,AB35)),Auxiliar!$C$12,IF(ABS($E35-$G35)=ABS(Z35-AB35),Auxiliar!$C$13,IF(AND(SIGN($E35-$G35)=SIGN(Z35-AB35),MIN($E35,$G35)=MIN(Z35,AB35)),Auxiliar!$C$14,IF(SIGN($E35-$G35)=SIGN(Z35-AB35),Auxiliar!$C$15,IF(Z35=AB35,Auxiliar!$C$16,0))))))) -> 0 | AE35: 5 | AF35: x | AG35: 1 | AH35: =IF(OR($E35="",$G35=""),"",IF(AND(AE35=$E35,AG35=$G35),Auxiliar!$C$11,IF(AND(SIGN($E35-$G35)=SIGN(AE35-AG35),MAX($E35,$G35)=MAX(AE35,AG35)),Auxiliar!$C$12,IF(ABS($E35-$G35)=ABS(AE35-AG35),Auxiliar!$C$13,IF(AND(SIGN($E35-$G35)=SIGN(AE35-AG35),MIN($E35,$G35)=MIN(AE35,AG35)),Auxiliar!$C$14,IF(SIGN($E35-$G35)=SIGN(AE35-AG35),Auxiliar!$C$15,IF(AE35=AG35,Auxiliar!$C$16,0))))))) -> 0
C36: =C26+1 -> 2 | D36: BGT | E36: 1 | F36: x | G36: 0 | H36: BAH | K36: 5 | L36: x | M36: 5 | N36: =IF(OR($E36="",$G36=""),"",IF(AND(K36=$E36,M36=$G36),Auxiliar!$C$11,IF(AND(SIGN($E36-$G36)=SIGN(K36-M36),MAX($E36,$G36)=MAX(K36,M36)),Auxiliar!$C$12,IF(ABS($E36-$G36)=ABS(K36-M36),Auxiliar!$C$13,IF(AND(SIGN($E36-$G36)=SIGN(K36-M36),MIN($E36,$G36)=MIN(K36,M36)),Auxiliar!$C$14,IF(SIGN($E36-$G36)=SIGN(K36-M36),Auxiliar!$C$15,IF(K36=M36,Auxiliar!$C$16,0))))))) -> 5 | P36: 4 | Q36: x | R36: 4 | S36: =IF(OR($E36="",$G36=""),"",IF(AND(P36=$E36,R36=$G36),Auxiliar!$C$11,IF(AND(SIGN($E36-$G36)=SIGN(P36-R36),MAX($E36,$G36)=MAX(P36,R36)),Auxiliar!$C$12,IF(ABS($E36-$G36)=ABS(P36-R36),Auxiliar!$C$13,IF(AND(SIGN($E36-$G36)=SIGN(P36-R36),MIN($E36,$G36)=MIN(P36,R36)),Auxiliar!$C$14,IF(SIGN($E36-$G36)=SIGN(P36-R36),Auxiliar!$C$15,IF(P36=R36,Auxiliar!$C$16,0))))))) -> 5 | U36: 4 | V36: x | W36: 5 | X36: =IF(OR($E36="",$G36=""),"",IF(AND(U36=$E36,W36=$G36),Auxiliar!$C$11,IF(AND(SIGN($E36-$G36)=SIGN(U36-W36),MAX($E36,$G36)=MAX(U36,W36)),Auxiliar!$C$12,IF(ABS($E36-$G36)=ABS(U36-W36),Auxiliar!$C$13,IF(AND(SIGN($E36-$G36)=SIGN(U36-W36),MIN($E36,$G36)=MIN(U36,W36)),Auxiliar!$C$14,IF(SIGN($E36-$G36)=SIGN(U36-W36),Auxiliar!$C$15,IF(U36=W36,Auxiliar!$C$16,0))))))) -> 15 | Z36: 3 | AA36: x | AB36: 3 | AC36: =IF(OR($E36="",$G36=""),"",IF(AND(Z36=$E36,AB36=$G36),Auxiliar!$C$11,IF(AND(SIGN($E36-$G36)=SIGN(Z36-AB36),MAX($E36,$G36)=MAX(Z36,AB36)),Auxiliar!$C$12,IF(ABS($E36-$G36)=ABS(Z36-AB36),Auxiliar!$C$13,IF(AND(SIGN($E36-$G36)=SIGN(Z36-AB36),MIN($E36,$G36)=MIN(Z36,AB36)),Auxiliar!$C$14,IF(SIGN($E36-$G36)=SIGN(Z36-AB36),Auxiliar!$C$15,IF(Z36=AB36,Auxiliar!$C$16,0))))))) -> 5 | AE36: 2 | AF36: x | AG36: 5 | AH36: =IF(OR($E36="",$G36=""),"",IF(AND(AE36=$E36,AG36=$G36),Auxiliar!$C$11,IF(AND(SIGN($E36-$G36)=SIGN(AE36-AG36),MAX($E36,$G36)=MAX(AE36,AG36)),Auxiliar!$C$12,IF(ABS($E36-$G36)=ABS(AE36-AG36),Auxiliar!$C$13,IF(AND(SIGN($E36-$G36)=SIGN(AE36-AG36),MIN($E36,$G36)=MIN(AE36,AG36)),Auxiliar!$C$14,IF(SIGN($E36-$G36)=SIGN(AE36-AG36),Auxiliar!$C$15,IF(AE36=AG36,Auxiliar!$C$16,0))))))) -> 0
C37: =C27+1 -> 2 | D37: ACG | E37: 5 | F37: x | G37: 5 | H37: SAO | K37: 1 | L37: x | M37: 2 | N37: =IF(OR($E37="",$G37=""),"",IF(AND(K37=$E37,M37=$G37),Auxiliar!$C$11,IF(AND(SIGN($E37-$G37)=SIGN(K37-M37),MAX($E37,$G37)=MAX(K37,M37)),Auxiliar!$C$12,IF(ABS($E37-$G37)=ABS(K37-M37),Auxiliar!$C$13,IF(AND(SIGN($E37-$G37)=SIGN(K37-M37),MIN($E37,$G37)=MIN(K37,M37)),Auxiliar!$C$14,IF(SIGN($E37-$G37)=SIGN(K37-M37),Auxiliar!$C$15,IF(K37=M37,Auxiliar!$C$16,0))))))) -> 0 | P37: 3 | Q37: x | R37: 2 | S37: =IF(OR($E37="",$G37=""),"",IF(AND(P37=$E37,R37=$G37),Auxiliar!$C$11,IF(AND(SIGN($E37-$G37)=SIGN(P37-R37),MAX($E37,$G37)=MAX(P37,R37)),Auxiliar!$C$12,IF(ABS($E37-$G37)=ABS(P37-R37),Auxiliar!$C$13,IF(AND(SIGN($E37-$G37)=SIGN(P37-R37),MIN($E37,$G37)=MIN(P37,R37)),Auxiliar!$C$14,IF(SIGN($E37-$G37)=SIGN(P37-R37),Auxiliar!$C$15,IF(P37=R37,Auxiliar!$C$16,0))))))) -> 0 | U37: 1 | V37: x | W37: 1 | X37: =IF(OR($E37="",$G37=""),"",IF(AND(U37=$E37,W37=$G37),Auxiliar!$C$11,IF(AND(SIGN($E37-$G37)=SIGN(U37-W37),MAX($E37,$G37)=MAX(U37,W37)),Auxiliar!$C$12,IF(ABS($E37-$G37)=ABS(U37-W37),Auxiliar!$C$13,IF(AND(SIGN($E37-$G37)=SIGN(U37-W37),MIN($E37,$G37)=MIN(U37,W37)),Auxiliar!$C$14,IF(SIGN($E37-$G37)=SIGN(U37-W37),Auxiliar!$C$15,IF(U37=W37,Auxiliar!$C$16,0))))))) -> 15 | Z37: 4 | AA37: x | AB37: 1 | AC37: =IF(OR($E37="",$G37=""),"",IF(AND(Z37=$E37,AB37=$G37),Auxiliar!$C$11,IF(AND(SIGN($E37-$G37)=SIGN(Z37-AB37),MAX($E37,$G37)=MAX(Z37,AB37)),Auxiliar!$C$12,IF(ABS($E37-$G37)=ABS(Z37-AB37),Auxiliar!$C$13,IF(AND(SIGN($E37-$G37)=SIGN(Z37-AB37),MIN($E37,$G37)=MIN(Z37,AB37)),Auxiliar!$C$14,IF(SIGN($E37-$G37)=SIGN(Z37-AB37),Auxiliar!$C$15,IF(Z37=AB37,Auxiliar!$C$16,0))))))) -> 0 | AE37: 3 | AF37: x | AG37: 3 | AH37: =IF(OR($E37="",$G37=""),"",IF(AND(AE37=$E37,AG37=$G37),Auxiliar!$C$11,IF(AND(SIGN($E37-$G37)=SIGN(AE37-AG37),MAX($E37,$G37)=MAX(AE37,AG37)),Auxiliar!$C$12,IF(ABS($E37-$G37)=ABS(AE37-AG37),Auxiliar!$C$13,IF(AND(SIGN($E37-$G37)=SIGN(AE37-AG37),MIN($E37,$G37)=MIN(AE37,AG37)),Auxiliar!$C$14,IF(SIGN($E37-$G37)=SIGN(AE37-AG37),Auxiliar!$C$15,IF(AE37=AG37,Auxiliar!$C$16,0))))))) -> 15
C38: =C28+1 -> 2 | D38: JUV | E38: 0 | F38: x | G38: 0 | H38: CAP | K38: 1 | L38: x | M38: 4 | N38: =IF(OR($E38="",$G38=""),"",IF(AND(K38=$E38,M38=$G38),Auxiliar!$C$11,IF(AND(SIGN($E38-$G38)=SIGN(K38-M38),MAX($E38,$G38)=MAX(K38,M38)),Auxiliar!$C$12,IF(ABS($E38-$G38)=ABS(K38-M38),Auxiliar!$C$13,IF(AND(SIGN($E38-$G38)=SIGN(K38-M38),MIN($E38,$G38)=MIN(K38,M38)),Auxiliar!$C$14,IF(SIGN($E38-$G38)=SIGN(K38-M38),Auxiliar!$C$15,IF(K38=M38,Auxiliar!$C$16,0))))))) -> 0 | P38: 0 | Q38: x | R38: 1 | S38: =IF(OR($E38="",$G38=""),"",IF(AND(P38=$E38,R38=$G38),Auxiliar!$C$11,IF(AND(SIGN($E38-$G38)=SIGN(P38-R38),MAX($E38,$G38)=MAX(P38,R38)),Auxiliar!$C$12,IF(ABS($E38-$G38)=ABS(P38-R38),Auxiliar!$C$13,IF(AND(SIGN($E38-$G38)=SIGN(P38-R38),MIN($E38,$G38)=MIN(P38,R38)),Auxiliar!$C$14,IF(SIGN($E38-$G38)=SIGN(P38-R38),Auxiliar!$C$15,IF(P38=R38,Auxiliar!$C$16,0))))))) -> 0 | U38: 3 | V38: x | W38: 3 | X38: =IF(OR($E38="",$G38=""),"",IF(AND(U38=$E38,W38=$G38),Auxiliar!$C$11,IF(AND(SIGN($E38-$G38)=SIGN(U38-W38),MAX($E38,$G38)=MAX(U38,W38)),Auxiliar!$C$12,IF(ABS($E38-$G38)=ABS(U38-W38),Auxiliar!$C$13,IF(AND(SIGN($E38-$G38)=SIGN(U38-W38),MIN($E38,$G38)=MIN(U38,W38)),Auxiliar!$C$14,IF(SIGN($E38-$G38)=SIGN(U38-W38),Auxiliar!$C$15,IF(U38=W38,Auxiliar!$C$16,0))))))) -> 15 | Z38: 3 | AA38: x | AB38: 3 | AC38: =IF(OR($E38="",$G38=""),"",IF(AND(Z38=$E38,AB38=$G38),Auxiliar!$C$11,IF(AND(SIGN($E38-$G38)=SIGN(Z38-AB38),MAX($E38,$G38)=MAX(Z38,AB38)),Auxiliar!$C$12,IF(ABS($E38-$G38)=ABS(Z38-AB38),Auxiliar!$C$13,IF(AND(SIGN($E38-$G38)=SIGN(Z38-AB38),MIN($E38,$G38)=MIN(Z38,AB38)),Auxiliar!$C$14,IF(SIGN($E38-$G38)=SIGN(Z38-AB38),Auxiliar!$C$15,IF(Z38=AB38,Auxiliar!$C$16,0))))))) -> 15 | AE38: 5 | AF38: x | AG38: 2 | AH38: =IF(OR($E38="",$G38=""),"",IF(AND(AE38=$E38,AG38=$G38),Auxiliar!$C$11,IF(AND(SIGN($E38-$G38)=SIGN(AE38-AG38),MAX($E38,$G38)=MAX(AE38,AG38)),Auxiliar!$C$12,IF(ABS($E38-$G38)=ABS(AE38-AG38),Auxiliar!$C$13,IF(AND(SIGN($E38-$G38)=SIGN(AE38-AG38),MIN($E38,$G38)=MIN(AE38,AG38)),Auxiliar!$C$14,IF(SIGN($E38-$G38)=SIGN(AE38-AG38),Auxiliar!$C$15,IF(AE38=AG38,Auxiliar!$C$16,0))))))) -> 0
C39: =C29+1 -> 3 | D39: FLA | E39: 1 | F39: x | G39: 1 | H39: AME | K39: 4 | L39: x | M39: 0 | N39: =IF(OR($E39="",$G39=""),"",IF(AND(K39=$E39,M39=$G39),Auxiliar!$C$11,IF(AND(SIGN($E39-$G39)=SIGN(K39-M39),MAX($E39,$G39)=MAX(K39,M39)),Auxiliar!$C$12,IF(ABS($E39-$G39)=ABS(K39-M39),Auxiliar!$C$13,IF(AND(SIGN($E39-$G39)=SIGN(K39-M39),MIN($E39,$G39)=MIN(K39,M39)),Auxiliar!$C$14,IF(SIGN($E39-$G39)=SIGN(K39-M39),Auxiliar!$C$15,IF(K39=M39,Auxiliar!$C$16,0))))))) -> 0 | P39: 0 | Q39: x | R39: 0 | S39: =IF(OR($E39="",$G39=""),"",IF(AND(P39=$E39,R39=$G39),Auxiliar!$C$11,IF(AND(SIGN($E39-$G39)=SIGN(P39-R39),MAX($E39,$G39)=MAX(P39,R39)),Auxiliar!$C$12,IF(ABS($E39-$G39)=ABS(P39-R39),Auxiliar!$C$13,IF(AND(SIGN($E39-$G39)=SIGN(P39-R39),MIN($E39,$G39)=MIN(P39,R39)),Auxiliar!$C$14,IF(SIGN($E39-$G39)=SIGN(P39-R39),Auxiliar!$C$15,IF(P39=R39,Auxiliar!$C$16,0))))))) -> 15 | U39: 2 | V39: x | W39: 3 | X39: =IF(OR($E39="",$G39=""),"",IF(AND(U39=$E39,W39=$G39),Auxiliar!$C$11,IF(AND(SIGN($E39-$G39)=SIGN(U39-W39),MAX($E39,$G39)=MAX(U39,W39)),Auxiliar!$C$12,IF(ABS($E39-$G39)=ABS(U39-W39),Auxiliar!$C$13,IF(AND(SIGN($E39-$G39)=SIGN(U39-W39),MIN($E39,$G39)=MIN(U39,W39)),Auxiliar!$C$14,IF(SIGN($E39-$G39)=SIGN(U39-W39),Auxiliar!$C$15,IF(U39=W39,Auxiliar!$C$16,0))))))) -> 0 | Z39: 5 | AA39: x | AB39: 4 | AC39: =IF(OR($E39="",$G39=""),"",IF(AND(Z39=$E39,AB39=$G39),Auxiliar!$C$11,IF(AND(SIGN($E39-$G39)=SIGN(Z39-AB39),MAX($E39,$G39)=MAX(Z39,AB39)),Auxiliar!$C$12,IF(ABS($E39-$G39)=ABS(Z39-AB39),Auxiliar!$C$13,IF(AND(SIGN($E39-$G39)=SIGN(Z39-AB39),MIN($E39,$G39)=MIN(Z39,AB39)),Auxiliar!$C$14,IF(SIGN($E39-$G39)=SIGN(Z39-AB39),Auxiliar!$C$15,IF(Z39=AB39,Auxiliar!$C$16,0))))))) -> 0 | AE39: 3 | AF39: x | AG39: 5 | AH39: =IF(OR($E39="",$G39=""),"",IF(AND(AE39=$E39,AG39=$G39),Auxiliar!$C$11,IF(AND(SIGN($E39-$G39)=SIGN(AE39-AG39),MAX($E39,$G39)=MAX(AE39,AG39)),Auxiliar!$C$12,IF(ABS($E39-$G39)=ABS(AE39-AG39),Auxiliar!$C$13,IF(AND(SIGN($E39-$G39)=SIGN(AE39-AG39),MIN($E39,$G39)=MIN(AE39,AG39)),Auxiliar!$C$14,IF(SIGN($E39-$G39)=SIGN(AE39-AG39),Auxiliar!$C$15,IF(AE39=AG39,Auxiliar!$C$16,0))))))) -> 0
C40: =C30+1 -> 3 | D40: PAL | E40: 2 | F40: x | G40: 1 | H40: COR | K40: 1 | L40: x | M40: 1 | N40: =IF(OR($E40="",$G40=""),"",IF(AND(K40=$E40,M40=$G40),Auxiliar!$C$11,IF(AND(SIGN($E40-$G40)=SIGN(K40-M40),MAX($E40,$G40)=MAX(K40,M40)),Auxiliar!$C$12,IF(ABS($E40-$G40)=ABS(K40-M40),Auxiliar!$C$13,IF(AND(SIGN($E40-$G40)=SIGN(K40-M40),MIN($E40,$G40)=MIN(K40,M40)),Auxiliar!$C$14,IF(SIGN($E40-$G40)=SIGN(K40-M40),Auxiliar!$C$15,IF(K40=M40,Auxiliar!$C$16,0))))))) -> 5 | P40: 4 | Q40: x | R40: 0 | S40: =IF(OR($E40="",$G40=""),"",IF(AND(P40=$E40,R40=$G40),Auxiliar!$C$11,IF(AND(SIGN($E40-$G40)=SIGN(P40-R40),MAX($E40,$G40)=MAX(P40,R40)),Auxiliar!$C$12,IF(ABS($E40-$G40)=ABS(P40-R40),Auxiliar!$C$13,IF(AND(SIGN($E40-$G40)=SIGN(P40-R40),MIN($E40,$G40)=MIN(P40,R40)),Auxiliar!$C$14,IF(SIGN($E40-$G40)=SIGN(P40-R40),Auxiliar!$C$15,IF(P40=R40,Auxiliar!$C$16,0))))))) -> 10 | U40: 3 | V40: x | W40: 2 | X40: =IF(OR($E40="",$G40=""),"",IF(AND(U40=$E40,W40=$G40),Auxiliar!$C$11,IF(AND(SIGN($E40-$G40)=SIGN(U40-W40),MAX($E40,$G40)=MAX(U40,W40)),Auxiliar!$C$12,IF(ABS($E40-$G40)=ABS(U40-W40),Auxiliar!$C$13,IF(AND(SIGN($E40-$G40)=SIGN(U40-W40),MIN($E40,$G40)=MIN(U40,W40)),Auxiliar!$C$14,IF(SIGN($E40-$G40)=SIGN(U40-W40),Auxiliar!$C$15,IF(U40=W40,Auxiliar!$C$16,0))))))) -> 15 | Z40: 0 | AA40: x | AB40: 5 | AC40: =IF(OR($E40="",$G40=""),"",IF(AND(Z40=$E40,AB40=$G40),Auxiliar!$C$11,IF(AND(SIGN($E40-$G40)=SIGN(Z40-AB40),MAX($E40,$G40)=MAX(Z40,AB40)),Auxiliar!$C$12,IF(ABS($E40-$G40)=ABS(Z40-AB40),Auxiliar!$C$13,IF(AND(SIGN($E40-$G40)=SIGN(Z40-AB40),MIN($E40,$G40)=MIN(Z40,AB40)),Auxiliar!$C$14,IF(SIGN($E40-$G40)=SIGN(Z40-AB40),Auxiliar!$C$15,IF(Z40=AB40,Auxiliar!$C$16,0))))))) -> 0 | AE40: 0 | AF40: x | AG40: 3 | AH40: =IF(OR($E40="",$G40=""),"",IF(AND(AE40=$E40,AG40=$G40),Auxiliar!$C$11,IF(AND(SIGN($E40-$G40)=SIGN(AE40-AG40),MAX($E40,$G40)=MAX(AE40,AG40)),Auxiliar!$C$12,IF(ABS($E40-$G40)=ABS(AE40-AG40),Auxiliar!$C$13,IF(AND(SIGN($E40-$G40)=SIGN(AE40-AG40),MIN($E40,$G40)=MIN(AE40,AG40)),Auxiliar!$C$14,IF(SIGN($E40-$G40)=SIGN(AE40-AG40),Auxiliar!$C$15,IF(AE40=AG40,Auxiliar!$C$16,0))))))) -> 0
... C108: =C98+1 -> 9 | D108: CHA | E108: 5 | F108: x | G108: 0 | H108: BAH | K108: 0 | L108: x | M108: 4 | N108: =IF(OR($E108="",$G108=""),"",IF(AND(K108=$E108,M108=$G108),Auxiliar!$C$11,IF(AND(SIGN($E108-$G108)=SIGN(K108-M108),MAX($E108,$G108)=MAX(K108,M108)),Auxiliar!$C$12,IF(ABS($E108-$G108)=ABS(K108-M108),Auxiliar!$C$13,IF(AND(SIGN($E108-$G108)=SIGN(K108-M108),MIN($E108,$G108)=MIN(K108,M108)),Auxiliar!$C$14,IF(SIGN($E108-$G108)=SIGN(K108-M108),Auxiliar!$C$15,IF(K108=M108,Auxiliar!$C$16,0))))))) -> 0 | P108: 2 | Q108: x | R108: 3 | S108: =IF(OR($E108="",$G108=""),"",IF(AND(P108=$E108,R108=$G108),Auxiliar!$C$11,IF(AND(SIGN($E108-$G108)=SIGN(P108-R108),MAX($E108,$G108)=MAX(P108,R108)),Auxiliar!$C$12,IF(ABS($E108-$G108)=ABS(P108-R108),Auxiliar!$C$13,IF(AND(SIGN($E108-$G108)=SIGN(P108-R108),MIN($E108,$G108)=MIN(P108,R108)),Auxiliar!$C$14,IF(SIGN($E108-$G108)=SIGN(P108-R108),Auxiliar!$C$15,IF(P108=R108,Auxiliar!$C$16,0))))))) -> 0 | U108: 4 | V108: x | W108: 4 | X108: =IF(OR($E108="",$G108=""),"",IF(AND(U108=$E108,W108=$G108),Auxiliar!$C$11,IF(AND(SIGN($E108-$G108)=SIGN(U108-W108),MAX($E108,$G108)=MAX(U108,W108)),Auxiliar!$C$12,IF(ABS($E108-$G108)=ABS(U108-W108),Auxiliar!$C$13,IF(AND(SIGN($E108-$G108)=SIGN(U108-W108),MIN($E108,$G108)=MIN(U108,W108)),Auxiliar!$C$14,IF(SIGN($E108-$G108)=SIGN(U108-W108),Auxiliar!$C$15,IF(U108=W108,Auxiliar!$C$16,0))))))) -> 5 | Z108: 3 | AA108: x | AB108: 5 | AC108: =IF(OR($E108="",$G108=""),"",IF(AND(Z108=$E108,AB108=$G108),Auxiliar!$C$11,IF(AND(SIGN($E108-$G108)=SIGN(Z108-AB108),MAX($E108,$G108)=MAX(Z108,AB108)),Auxiliar!$C$12,IF(ABS($E108-$G108)=ABS(Z108-AB108),Auxiliar!$C$13,IF(AND(SIGN($E108-$G108)=SIGN(Z108-AB108),MIN($E108,$G108)=MIN(Z108,AB108)),Auxiliar!$C$14,IF(SIGN($E108-$G108)=SIGN(Z108-AB108),Auxiliar!$C$15,IF(Z108=AB108,Auxiliar!$C$16,0))))))) -> 0 | AE108: 0 | AF108: x | AG108: 4 | AH108: =IF(OR($E108="",$G108=""),"",IF(AND(AE108=$E108,AG108=$G108),Auxiliar!$C$11,IF(AND(SIGN($E108-$G108)=SIGN(AE108-AG108),MAX($E108,$G108)=MAX(AE108,AG108)),Auxiliar!$C$12,IF(ABS($E108-$G108)=ABS(AE108-AG108),Auxiliar!$C$13,IF(AND(SIGN($E108-$G108)=SIGN(AE108-AG108),MIN($E108,$G108)=MIN(AE108,AG108)),Auxiliar!$C$14,IF(SIGN($E108-$G108)=SIGN(AE108-AG108),Auxiliar!$C$15,IF(AE108=AG108,Auxiliar!$C$16,0))))))) -> 0
C109: =C99+1 -> 10 | F109: x | K109: 4 | L109: x | M109: 3 | N109: =IF(OR($E109="",$G109=""),"",IF(AND(K109=$E109,M109=$G109),Auxiliar!$C$11,IF(AND(SIGN($E109-$G109)=SIGN(K109-M109),MAX($E109,$G109)=MAX(K109,M109)),Auxiliar!$C$12,IF(ABS($E109-$G109)=ABS(K109-M109),Auxiliar!$C$13,IF(AND(SIGN($E109-$G109)=SIGN(K109-M109),MIN($E109,$G109)=MIN(K109,M109)),Auxiliar!$C$14,IF(SIGN($E109-$G109)=SIGN(K109-M109),Auxiliar!$C$15,IF(K109=M109,Auxiliar!$C$16,0))))))) | P109: 4 | Q109: x | R109: 1 | S109: =IF(OR($E109="",$G109=""),"",IF(AND(P109=$E109,R109=$G109),Auxiliar!$C$11,IF(AND(SIGN($E109-$G109)=SIGN(P109-R109),MAX($E109,$G109)=MAX(P109,R109)),Auxiliar!$C$12,IF(ABS($E109-$G109)=ABS(P109-R109),Auxiliar!$C$13,IF(AND(SIGN($E109-$G109)=SIGN(P109-R109),MIN($E109,$G109)=MIN(P109,R109)),Auxiliar!$C$14,IF(SIGN($E109-$G109)=SIGN(P109-R109),Auxiliar!$C$15,IF(P109=R109,Auxiliar!$C$16,0))))))) | U109: 3 | V109: x | W109: 2 | X109: =IF(OR($E109="",$G109=""),"",IF(AND(U109=$E109,W109=$G109),Auxiliar!$C$11,IF(AND(SIGN($E109-$G109)=SIGN(U109-W109),MAX($E109,$G109)=MAX(U109,W109)),Auxiliar!$C$12,IF(ABS($E109-$G109)=ABS(U109-W109),Auxiliar!$C$13,IF(AND(SIGN($E109-$G109)=SIGN(U109-W109),MIN($E109,$G109)=MIN(U109,W109)),Auxiliar!$C$14,IF(SIGN($E109-$G109)=SIGN(U109-W109),Auxiliar!$C$15,IF(U109=W109,Auxiliar!$C$16,0))))))) | Z109: 5 | AA109: x | AB109: 5 | AC109: =IF(OR($E109="",$G109=""),"",IF(AND(Z109=$E109,AB109=$G109),Auxiliar!$C$11,IF(AND(SIGN($E109-$G109)=SIGN(Z109-AB109),MAX($E109,$G109)=MAX(Z109,AB109)),Auxiliar!$C$12,IF(ABS($E109-$G109)=ABS(Z109-AB109),Auxiliar!$C$13,IF(AND(SIGN($E109-$G109)=SIGN(Z109-AB109),MIN($E109,$G109)=MIN(Z109,AB109)),Auxiliar!$C$14,IF(SIGN($E109-$G109)=SIGN(Z109-AB109),Auxiliar!$C$15,IF(Z109=AB109,Auxiliar!$C$16,0))))))) | AE109: 5 | AF109: x | AG109: 3 | AH109: =IF(OR($E109="",$G109=""),"",IF(AND(AE109=$E109,AG109=$G109),Auxiliar!$C$11,IF(AND(SIGN($E109-$G109)=SIGN(AE109-AG109),MAX($E109,$G109)=MAX(AE109,AG109)),Auxiliar!$C$12,IF(ABS($E109-$G109)=ABS(AE109-AG109),Auxiliar!$C$13,IF(AND(SIGN($E109-$G109)=SIGN(AE109-AG109),MIN($E109,$G109)=MIN(AE109,AG109)),Auxiliar!$C$14,IF(SIGN($E109-$G109)=SIGN(AE109-AG109),Auxiliar!$C$15,IF(AE109=AG109,Auxiliar!$C$16,0)))))))
C110: =C100+1 -> 10 | F110: x | K110: 1 | L110: x | M110: 4 | N110: =IF(OR($E110="",$G110=""),"",IF(AND(K110=$E110,M110=$G110),Auxiliar!$C$11,IF(AND(SIGN($E110-$G110)=SIGN(K110-M110),MAX($E110,$G110)=MAX(K110,M110)),Auxiliar!$C$12,IF(ABS($E110-$G110)=ABS(K110-M110),Auxiliar!$C$13,IF(AND(SIGN($E110-$G110)=SIGN(K110-M110),MIN($E110,$G110)=MIN(K110,M110)),Auxiliar!$C$14,IF(SIGN($E110-$G110)=SIGN(K110-M110),Auxiliar!$C$15,IF(K110=M110,Auxiliar!$C$16,0))))))) | P110: 2 | Q110: x | R110: 2 | S110: =IF(OR($E110="",$G110=""),"",IF(AND(P110=$E110,R110=$G110),Auxiliar!$C$11,IF(AND(SIGN($E110-$G110)=SIGN(P110-R110),MAX($E110,$G110)=MAX(P110,R110)),Auxiliar!$C$12,IF(ABS($E110-$G110)=ABS(P110-R110),Auxiliar!$C$13,IF(AND(SIGN($E110-$G110)=SIGN(P110-R110),MIN($E110,$G110)=MIN(P110,R110)),Auxiliar!$C$14,IF(SIGN($E110-$G110)=SIGN(P110-R110),Auxiliar!$C$15,IF(P110=R110,Auxiliar!$C$16,0))))))) | U110: 2 | V110: x | W110: 4 | X110: =IF(OR($E110="",$G110=""),"",IF(AND(U110=$E110,W110=$G110),Auxiliar!$C$11,IF(AND(SIGN($E110-$G110)=SIGN(U110-W110),MAX($E110,$G110)=MAX(U110,W110)),Auxiliar!$C$12,IF(ABS($E110-$G110)=ABS(U110-W110),Auxiliar!$C$13,IF(AND(SIGN($E110-$G110)=SIGN(U110-W110),MIN($E110,$G110)=MIN(U110,W110)),Auxiliar!$C$14,IF(SIGN($E110-$G110)=SIGN(U110-W110),Auxiliar!$C$15,IF(U110=W110,Auxiliar!$C$16,0))))))) | Z110: 1 | AA110: x | AB110: 1 | AC110: =IF(OR($E110="",$G110=""),"",IF(AND(Z110=$E110,AB110=$G110),Auxiliar!$C$11,IF(AND(SIGN($E110-$G110)=SIGN(Z110-AB110),MAX($E110,$G110)=MAX(Z110,AB110)),Auxiliar!$C$12,IF(ABS($E110-$G110)=ABS(Z110-AB110),Auxiliar!$C$13,IF(AND(SIGN($E110-$G110)=SIGN(Z110-AB110),MIN($E110,$G110)=MIN(Z110,AB110)),Auxiliar!$C$14,IF(SIGN($E110-$G110)=SIGN(Z110-AB110),Auxiliar!$C$15,IF(Z110=AB110,Auxiliar!$C$16,0))))))) | AE110: 2 | AF110: x | AG110: 3 | AH110: =IF(OR($E110="",$G110=""),"",IF(AND(AE110=$E110,AG110=$G110),Auxiliar!$C$11,IF(AND(SIGN($E110-$G110)=SIGN(AE110-AG110),MAX($E110,$G110)=MAX(AE110,AG110)),Auxiliar!$C$12,IF(ABS($E110-$G110)=ABS(AE110-AG110),Auxiliar!$C$13,IF(AND(SIGN($E110-$G110)=SIGN(AE110-AG110),MIN($E110,$G110)=MIN(AE110,AG110)),Auxiliar!$C$14,IF(SIGN($E110-$G110)=SIGN(AE110-AG110),Auxiliar!$C$15,IF(AE110=AG110,Auxiliar!$C$16,0)))))))
C111: =C101+1 -> 10 | F111: x | K111: 0 | L111: x | M111: 0 | N111: =IF(OR($E111="",$G111=""),"",IF(AND(K111=$E111,M111=$G111),Auxiliar!$C$11,IF(AND(SIGN($E111-$G111)=SIGN(K111-M111),MAX($E111,$G111)=MAX(K111,M111)),Auxiliar!$C$12,IF(ABS($E111-$G111)=ABS(K111-M111),Auxiliar!$C$13,IF(AND(SIGN($E111-$G111)=SIGN(K111-M111),MIN($E111,$G111)=MIN(K111,M111)),Auxiliar!$C$14,IF(SIGN($E111-$G111)=SIGN(K111-M111),Auxiliar!$C$15,IF(K111=M111,Auxiliar!$C$16,0))))))) | P111: 1 | Q111: x | R111: 0 | S111: =IF(OR($E111="",$G111=""),"",IF(AND(P111=$E111,R111=$G111),Auxiliar!$C$11,IF(AND(SIGN($E111-$G111)=SIGN(P111-R111),MAX($E111,$G111)=MAX(P111,R111)),Auxiliar!$C$12,IF(ABS($E111-$G111)=ABS(P111-R111),Auxiliar!$C$13,IF(AND(SIGN($E111-$G111)=SIGN(P111-R111),MIN($E111,$G111)=MIN(P111,R111)),Auxiliar!$C$14,IF(SIGN($E111-$G111)=SIGN(P111-R111),Auxiliar!$C$15,IF(P111=R111,Auxiliar!$C$16,0))))))) | U111: 5 | V111: x | W111: 1 | X111: =IF(OR($E111="",$G111=""),"",IF(AND(U111=$E111,W111=$G111),Auxiliar!$C$11,IF(AND(SIGN($E111-$G111)=SIGN(U111-W111),MAX($E111,$G111)=MAX(U111,W111)),Auxiliar!$C$12,IF(ABS($E111-$G111)=ABS(U111-W111),Auxiliar!$C$13,IF(AND(SIGN($E111-$G111)=SIGN(U111-W111),MIN($E111,$G111)=MIN(U111,W111)),Auxiliar!$C$14,IF(SIGN($E111-$G111)=SIGN(U111-W111),Auxiliar!$C$15,IF(U111=W111,Auxiliar!$C$16,0))))))) | Z111: 2 | AA111: x | AB111: 2 | AC111: =IF(OR($E111="",$G111=""),"",IF(AND(Z111=$E111,AB111=$G111),Auxiliar!$C$11,IF(AND(SIGN($E111-$G111)=SIGN(Z111-AB111),MAX($E111,$G111)=MAX(Z111,AB111)),Auxiliar!$C$12,IF(ABS($E111-$G111)=ABS(Z111-AB111),Auxiliar!$C$13,IF(AND(SIGN($E111-$G111)=SIGN(Z111-AB111),MIN($E111,$G111)=MIN(Z111,AB111)),Auxiliar!$C$14,IF(SIGN($E111-$G111)=SIGN(Z111-AB111),Auxiliar!$C$15,IF(Z111=AB111,Auxiliar!$C$16,0))))))) | AE111: 1 | AF111: x | AG111: 0 | AH111: =IF(OR($E111="",$G111=""),"",IF(AND(AE111=$E111,AG111=$G111),Auxiliar!$C$11,IF(AND(SIGN($E111-$G111)=SIGN(AE111-AG111),MAX($E111,$G111)=MAX(AE111,AG111)),Auxiliar!$C$12,IF(ABS($E111-$G111)=ABS(AE111-AG111),Auxiliar!$C$13,IF(AND(SIGN($E111-$G111)=SIGN(AE111-AG111),MIN($E111,$G111)=MIN(AE111,AG111)),Auxiliar!$C$14,IF(SIGN($E111-$G111)=SIGN(AE111-AG111),Auxiliar!$C$15,IF(AE111=AG111,Auxiliar!$C$16,0)))))))
C112: =C102+1 -> 10 | F112: x | K112: 5 | L112: x | M112: 1 | N112: =IF(OR($E112="",$G112=""),"",IF(AND(K112=$E112,M112=$G112),Auxiliar!$C$11,IF(AND(SIGN($E112-$G112)=SIGN(K112-M112),MAX($E112,$G112)=MAX(K112,M112)),Auxiliar!$C$12,IF(ABS($E112-$G112)=ABS(K112-M112),Auxiliar!$C$13,IF(AND(SIGN($E112-$G112)=SIGN(K112-M112),MIN($E112,$G112)=MIN(K112,M112)),Auxiliar!$C$14,IF(SIGN($E112-$G112)=SIGN(K112-M112),Auxiliar!$C$15,IF(K112=M112,Auxiliar!$C$16,0))))))) | P112: 1 | Q112: x | R112: 3 | S112: =IF(OR($E112="",$G112=""),"",IF(AND(P112=$E112,R112=$G112),Auxiliar!$C$11,IF(AND(SIGN($E112-$G112)=SIGN(P112-R112),MAX($E112,$G112)=MAX(P112,R112)),Auxiliar!$C$12,IF(ABS($E112-$G112)=ABS(P112-R112),Auxiliar!$C$13,IF(AND(SIGN($E112-$G112)=SIGN(P112-R112),MIN($E112,$G112)=MIN(P112,R112)),Auxiliar!$C$14,IF(SIGN($E112-$G112)=SIGN(P112-R112),Auxiliar!$C$15,IF(P112=R112,Auxiliar!$C$16,0))))))) | U112: 5 | V112: x | W112: 2 | X112: =IF(OR($E112="",$G112=""),"",IF(AND(U112=$E112,W112=$G112),Auxiliar!$C$11,IF(AND(SIGN($E112-$G112)=SIGN(U112-W112),MAX($E112,$G112)=MAX(U112,W112)),Auxiliar!$C$12,IF(ABS($E112-$G112)=ABS(U112-W112),Auxiliar!$C$13,IF(AND(SIGN($E112-$G112)=SIGN(U112-W112),MIN($E112,$G112)=MIN(U112,W112)),Auxiliar!$C$14,IF(SIGN($E112-$G112)=SIGN(U112-W112),Auxiliar!$C$15,IF(U112=W112,Auxiliar!$C$16,0))))))) | Z112: 0 | AA112: x | AB112: 1 | AC112: =IF(OR($E112="",$G112=""),"",IF(AND(Z112=$E112,AB112=$G112),Auxiliar!$C$11,IF(AND(SIGN($E112-$G112)=SIGN(Z112-AB112),MAX($E112,$G112)=MAX(Z112,AB112)),Auxiliar!$C$12,IF(ABS($E112-$G112)=ABS(Z112-AB112),Auxiliar!$C$13,IF(AND(SIGN($E112-$G112)=SIGN(Z112-AB112),MIN($E112,$G112)=MIN(Z112,AB112)),Auxiliar!$C$14,IF(SIGN($E112-$G112)=SIGN(Z112-AB112),Auxiliar!$C$15,IF(Z112=AB112,Auxiliar!$C$16,0))))))) | AE112: 2 | AF112: x | AG112: 4 | AH112: =IF(OR($E112="",$G112=""),"",IF(AND(AE112=$E112,AG112=$G112),Auxiliar!$C$11,IF(AND(SIGN($E112-$G112)=SIGN(AE112-AG112),MAX($E112,$G112)=MAX(AE112,AG112)),Auxiliar!$C$12,IF(ABS($E112-$G112)=ABS(AE112-AG112),Auxiliar!$C$13,IF(AND(SIGN($E112-$G112)=SIGN(AE112-AG112),MIN($E112,$G112)=MIN(AE112,AG112)),Auxiliar!$C$14,IF(SIGN($E112-$G112)=SIGN(AE112-AG112),Auxiliar!$C$15,IF(AE112=AG112,Auxiliar!$C$16,0)))))))
C113: =C103+1 -> 10 | F113: x | K113: 5 | L113: x | M113: 4 | N113: =IF(OR($E113="",$G113=""),"",IF(AND(K113=$E113,M113=$G113),Auxiliar!$C$11,IF(AND(SIGN($E113-$G113)=SIGN(K113-M113),MAX($E113,$G113)=MAX(K113,M113)),Auxiliar!$C$12,IF(ABS($E113-$G113)=ABS(K113-M113),Auxiliar!$C$13,IF(AND(SIGN($E113-$G113)=SIGN(K113-M113),MIN($E113,$G113)=MIN(K113,M113)),Auxiliar!$C$14,IF(SIGN($E113-$G113)=SIGN(K113-M113),Auxiliar!$C$15,IF(K113=M113,Auxiliar!$C$16,0))))))) | P113: 3 | Q113: x | R113: 4 | S113: =IF(OR($E113="",$G113=""),"",IF(AND(P113=$E113,R113=$G113),Auxiliar!$C$11,IF(AND(SIGN($E113-$G113)=SIGN(P113-R113),MAX($E113,$G113)=MAX(P113,R113)),Auxiliar!$C$12,IF(ABS($E113-$G113)=ABS(P113-R113),Auxiliar!$C$13,IF(AND(SIGN($E113-$G113)=SIGN(P113-R113),MIN($E113,$G113)=MIN(P113,R113)),Auxiliar!$C$14,IF(SIGN($E113-$G113)=SIGN(P113-R113),Auxiliar!$C$15,IF(P113=R113,Auxiliar!$C$16,0))))))) | U113: 4 | V113: x | W113: 2 | X113: =IF(OR($E113="",$G113=""),"",IF(AND(U113=$E113,W113=$G113),Auxiliar!$C$11,IF(AND(SIGN($E113-$G113)=SIGN(U113-W113),MAX($E113,$G113)=MAX(U113,W113)),Auxiliar!$C$12,IF(ABS($E113-$G113)=ABS(U113-W113),Auxiliar!$C$13,IF(AND(SIGN($E113-$G113)=SIGN(U113-W113),MIN($E113,$G113)=MIN(U113,W113)),Auxiliar!$C$14,IF(SIGN($E113-$G113)=SIGN(U113-W113),Auxiliar!$C$15,IF(U113=W113,Auxiliar!$C$16,0))))))) | Z113: 2 | AA113: x | AB113: 4 | AC113: =IF(OR($E113="",$G113=""),"",IF(AND(Z113=$E113,AB113=$G113),Auxiliar!$C$11,IF(AND(SIGN($E113-$G113)=SIGN(Z113-AB113),MAX($E113,$G113)=MAX(Z113,AB113)),Auxiliar!$C$12,IF(ABS($E113-$G113)=ABS(Z113-AB113),Auxiliar!$C$13,IF(AND(SIGN($E113-$G113)=SIGN(Z113-AB113),MIN($E113,$G113)=MIN(Z113,AB113)),Auxiliar!$C$14,IF(SIGN($E113-$G113)=SIGN(Z113-AB113),Auxiliar!$C$15,IF(Z113=AB113,Auxiliar!$C$16,0))))))) | AE113: 4 | AF113: x | AG113: 0 | AH113: =IF(OR($E113="",$G113=""),"",IF(AND(AE113=$E113,AG113=$G113),Auxiliar!$C$11,IF(AND(SIGN($E113-$G113)=SIGN(AE113-AG113),MAX($E113,$G113)=MAX(AE113,AG113)),Auxiliar!$C$12,IF(ABS($E113-$G113)=ABS(AE113-AG113),Auxiliar!$C$13,IF(AND(SIGN($E113-$G113)=SIGN(AE113-AG113),MIN($E113,$G113)=MIN(AE113,AG113)),Auxiliar!$C$14,IF(SIGN($E113-$G113)=SIGN(AE113-AG113),Auxiliar!$C$15,IF(AE113=AG113,Auxiliar!$C$16,0)))))))
